Workbook
Name _Rt12: #REF!
Name _Rt12: #REF!
Name AJUSTES: #REF!
Name AJUSTES: #REF!
Name Assumptions: #N/A
Name Assumptions: #REF!
Name Base: #REF!
Name BN_CY: #REF!
Name BN_LY: #REF!
Name BN_PY: #REF!
Name BuiltIn_Print_Area: #REF!
Name BuiltIn_Print_Area: #REF!
Name BuiltIn_Print_Area___0: #REF!
Name BuiltIn_Print_Area___0: #REF!
Name BuiltIn_Print_Titles: #REF!
Name BuiltIn_Print_Titles___0: #REF!
Name CASH_FLOW: #N/A
Name CASH_FLOW: #REF!
Name Costo: #REF!
Name Costo: #REF!
Name DAYS_CY: #REF!
Name DeltaLodgeTabla: 'Real 2024'!$C$15:$P$139
Name Depreciation_Investment: #N/A
Name Depreciation_Investment: #REF!
Name EVOLUCION___0: #N/A
Name FC_CY: #REF!
Name FC_LY: #REF!
Name FC_PY: #REF!
Name FI_CY: #REF!
Name FI_LY: #REF!
Name FI_PY: #REF!
Name IBrutos: #REF!
Name IBrutos: #REF!
Name INCOME_STATEMENT: #N/A
Name INCOME_STATEMENT: #REF!
Name Intang: #REF!
Name Intang: #REF!
Name LCR_Real: #REF!
Name Macro1: #N/A
Name Monext: #REF!
Name Monext: #REF!
Name PAX_CY: #REF!
Name PAX_LY: #REF!
Name PAX_PY: #REF!
Name PERSONNEL: #N/A
Name PERSONNEL: #REF!
Name Real22: #REF!
Name Real23: #REF!
Name RealVM23: #REF!
Name Revenues_Expenses: #N/A
Name Revenues_Expenses: #REF!
Name Total_Sales__quantity: #N/A
Name Total_Sales__quantity: #REF!
Name Uniona: #REF!
Name Uniona: #REF!

Sheet Real 2024
B1: ok | C1: DELTA DAY TRIPS | D1: 2024 | E1: Budget | F1: REAL 2024 | K1: REAL 2023
B2: =IF(ROUND($D$72,0)=0,"ok","Check") -> #REF! | C2: BN | E2: 240 | F2: 220 | G2: =IF(F2=0,0,+F2/E2) -> 0.91666667 | K2: 270
B3: =IF(ROUND($E$72,0)=0,"ok","Check") -> #REF! | C3: FD | E3: =+E2*0.85 -> 204 | F3: 129 | G3: =IF(F3=0,0,+F3/E3) -> 0.63235294 | K3: 97
B4: =IF(ROUND($F$72,0)=0,"ok","Check") -> #REF! | C4: Pax | E4: =ROUND(+E2/2,0) -> 120 | F4: 126 | G4: =IF(F4=0,0,+F4/E4) -> 1.05 | K4: 138
B5: =IF(ROUND(#REF!,0)=0,"ok","Check") -> #REF! | C5: Inicio: | E5: 45170 | F5: =+E5 -> 45170 | G5: =IF(F2=0,0,ROUND(+F2/F4,1)) -> 1.7 | K5: 42248 | P5: =IF(K2=0,0,ROUND(+K2/K4,1)) -> 2
B6: =IF(ROUND(#REF!,0)=0,"ok","Check") -> #REF! | C6: Cierre: | E6: 45535 | F6: 45443 | K6: 42613
B7: =IF(ROUND($K$72,0)=0,"ok","Check") -> #REF! | C7: Días: | E7: =+E6-E5+1 -> 366 | F7: =+F6-F5+1 -> 274 | G7: =+F7/E7 -> 0.74863388 | K7: =+K6-K5 -> 365
C8: Semanas: | E8: =+E7/7 -> 52.285714 | F8: =+F7/7 -> 39.142857 | G8: =+F8/E8 -> 0.74863388 | K8: =+K7/7 -> 52.142857
C10: Comparativo Presupuestado/Real | D10: Budget Total | E10: Budget s/BN devengadas | F10: Real Acumulado | G10: Desvío | H10: Vs. Budget Total | K10: Real Acumulado | M10: Variable Budget Total | N10: Variable Real | O10: Variable Desvío | P10: Variable Real | S10: Gastos Estimados Cierre Temporada
C11: Rubro/Ítem | D11: =+$D$1 -> 2024 | E11: =+$D$1 -> 2024 | F11: =+$D$1 -> 2024 | G11: Budget a hoy vs Real | I11: Observaciones | K11: 2023 | M11: =+$D$1 -> 2024 | N11: =+$D$1 -> 2024 | O11: Budget a hoy vs Real | P11: =+K11 -> 2023 | S11: =+SUM(S12:S51) -> 3475.4167
C13: Otros Ingresos
C14: Shop | D14: =+$E$2*8 -> 1920 | E14: =IF($F$2=0,0,+D14/$E$2*$F$2) -> 1760 | F14: 430 | G14: =(F14-E14)+(F15-E15) -> -180 | H14: FD | K14: 887 | M14: =IF($E$2=0,0,+D14/$E$2) -> 8 | N14: =IF($F$2=0,0,+F14/$F$2) -> 1.9545455 | O14: =+N14-M14 -> -6.0454545 | P14: =+K14/$K$2 -> 3.2851852
C15: (CMV) Shop | D15: =-D14*0.6 -> -1152 | E15: =-E14*0.8 -> -1408 | F15: -258 | H15: =IF(F14=0,0,-F15/F14) -> 0.6 | K15: -487.85
C16: (Comisiones ventas shop) | D16: =-(D14+D15)*0.1 -> -76.8 | E16: 0 | F16: 0 | G16: =F16-E16 -> 0 | K16: 0
C17: Extras (Net) | D17: 200 | E17: =IF($F$2=0,0,+D17/$E$2*$F$2) -> 183.33333 | F17: 0 | G17: =F17-E17 -> -183.33333 | H17: FD | K17: 150 | M17: =IF($E$2=0,0,+D17/$E$2) -> 0.83333333 | N17: =IF($F$2=0,0,+F17/$F$2) -> 0 | O17: =+N17-M17 -> -0.83333333 | P17: =+K17/$K$2 -> 0.55555556
C18: Ingresos por Tips | D18: 0 | E18: =IF($F$2=0,0,+D18/$E$2*$F$2) -> 0 | F18: 0 | G18: =F18-E18 -> 0 | H18: FD | K18: 0 | M18: =IF($E$2=0,0,+D18/$E$2) -> 0 | N18: =IF($F$2=0,0,+F18/$F$2) -> 0 | O18: =+N18-M18 -> 0 | P18: =+K18/$K$2 -> 0
C19: Insert
C20: Total Otros Ingresos | D20: =SUM(D13:D19) -> 891.2 | E20: =SUM(E13:E19) -> 535.33333 | F20: =SUM(F13:F19) -> 172 | G20: =SUM(G13:G19) -> -363.33333 | H20: =+F20-E20-G20 -> 0 | K20: =SUM(K13:K19) -> 549.15
C22: Gastos Operativos
C23: Canon Lodge | D23: 1800 | E23: =+D23*$G$7 -> 1347.541 | F23: 1453.2 | G23: =E23-F23 -> -105.65902 | H23: FD | I23: Apenas Pasados | K23: 1763.97 | M23: =IF($E$2=0,0,+D23/$E$2) -> 7.5 | N23: =IF($F$2=0,0,+F23/$F$2) -> 6.6054545 | O23: =+M23-N23 -> 0.89454545 | P23: =+K23/$K$2 -> 6.5332222 | S23: =200000/480 -> 416.66667 | T23: =+F23+S23 -> 1869.8667 | U23: =+D23-T23 -> -69.866667
C24: Sueldos | D24: =SUM(D25:D28) -> 42570 | E24: =SUM(E25:E28) -> 37848.82 | F24: =SUM(F25:F28) -> 41738.82 | G24: =SUM(G25:G28) -> -3890 | K24: =SUM(K25:K28) -> 47755.6
C25: Managers | D25: 9540 | E25: =IF($G$2>1,D25,IF($F$2=0,0,+D25/$E$2*$F$2)) -> 8745 | F25: 11360 | G25: =E25-F25 -> -2615 | I25: Real pasados | K25: 7850
C26: Guias | D26: 22950 | E26: =IF(F26>D26,D26,IF($G$2>1,+D26*$G$2,IF(G7=1,D26,IF(D26>F26,F26,IF($F$3=0,0,+D26/$E$3*$F$3))))) -> 22950 | F26: 24225 | G26: =E26-F26 -> -1275 | H26: FD | I26: Ver Fees Noel como queda | K26: 28545 | M26: =IF($E$2=0,0,+D26/$E$2) -> 95.625 | N26: =IF($F$2=0,0,+F26/$F$2) -> 110.11364 | O26: =+M26-N26 -> -14.488636 | P26: =+K26/$K$2 -> 105.72222 | R26: =+O26/M26 -> -0.15151515 | S26: =670*2 -> 1340 | T26: =+F26+S26 -> 25565 | U26: =+D26-T26 -> -2615
C27: Servicio | D27: =10080-D28 -> 10080 | E27: =IF($G$7=1,+D27,IF(F27>D27,D27,+F27)) -> 6153.82 | F27: 6153.82 | G27: =E27-F27 -> 0 | K27: 11360.6 | S27: =(235000+100000)/480 -> 697.91667 | T27: =+F27+S27 -> 6851.7367 | U27: =+D27-T27 -> 3228.2633 | V27: Resta Mantenimiento y Limpieza dos meses
C28: Cargas Sociales | D28: =+F28 -> 0 | E28: =IF($G$7=1,+D28,IF(F28>D28,D28,+F28)) -> 0 | F28: 0 | G28: =E28-F28 -> 0 | K28: 0 | T28: =+F28+S28 -> 0 | U28: =+D28-T28 -> 0
C29: Comida / Vinos | D29: =ROUND(+$E$2*65,0) -> 15600 | E29: =+F2*M29 -> 14300 | F29: 13355.87 | G29: =E29-F29 -> 944.13 | H29: BN | K29: 17226.4 | M29: =IF($E$2=0,0,+D29/$E$2) -> 65 | N29: =IF($F$2=0,0,+F29/$F$2) -> 60.7085 | O29: =+M29-N29 -> 4.2915 | P29: =+K29/$K$2 -> 63.801481 | R29: =+O29/M29 -> 0.066023077
C30: Combustible | D30: =SUM(D31:D33) -> 5800 | E30: =SUM(E31:E33) -> 5055.06 | F30: =SUM(F31:F33) -> 5842.89 | G30: =SUM(G31:G33) -> -787.83 | K30: =SUM(K31:K33) -> 5532.71 | M30: =IF($E$2=0,0,+D30/$E$2) -> 24.166667 | N30: =IF($F$2=0,0,+F30/$F$2) -> 26.558591 | O30: =+M30-N30 -> -2.3919242 | P30: =+K30/$K$2 -> 20.491519
C31: Electricidad | D31: =500+500-D33 -> 602.39 | E31: =IF($G$7=1,+D31,IF(F31<D31,F31,(+D31/$E$2*$F$2))) -> 257.45 | F31: 257.45 | G31: =E31-F31 -> 0 | H31: BN | K31: 81.29 | M31: =IF($E$2=0,0,+D31/$E$2) -> 2.5099583 | N31: =IF($F$2=0,0,+F31/$F$2) -> 1.1702273 | O31: =+M31-N31 -> 1.3397311 | P31: =+K31/$K$2 -> 0.30107407 | S31: =80000/480 -> 166.66667 | T31: =+F31+S31 -> 424.11667 | U31: =+E31-T31 -> -166.66667
C32: Vehiculos/Botes | D32: =ROUND((+$E$2*20),0) -> 4800 | E32: =IF($G$7=1,+D32,IF(F32<D32,F32,(+D32/$E$2*$F$2))) -> 4400 | F32: 5187.83 | G32: =E32-F32 -> -787.83 | H32: BN | K32: 5114.47 | M32: =IF($E$2=0,0,+D32/$E$2) -> 20 | N32: =IF($F$2=0,0,+F32/$F$2) -> 23.581045 | O32: =+M32-N32 -> -3.5810455 | P32: =+K32/$K$2 -> 18.942481 | S32: =100000/480 -> 208.33333 | T32: =+F32+S32 -> 5396.1633 | U32: =+D32-T32 -> -596.16333
C33: Gas | D33: =+F33 -> 397.61 | E33: =+F33 -> 397.61 | F33: 397.61 | G33: =E33-F33 -> 0 | H33: BN | K33: 336.95 | M33: =IF($E$2=0,0,+D33/$E$2) -> 1.6567083 | N33: =IF($F$2=0,0,+F33/$F$2) -> 1.8073182 | O33: =+M33-N33 -> -0.15060985 | P33: =+K33/$K$2 -> 1.247963 | T33: =+F33+S33 -> 397.61 | U33: =+D33-T33 -> 0
C34: Traslado Aerop/Lodge/Alq Vehiculos | D34: =+$E$2*23 -> 5520 | E34: =IF(G2>1,+D34*G2,IF($G$7=1,D34,IF(F34<D34,F34,D34))) -> 5520 | F34: 5525 | G34: =E34-F34 -> -5 | H34: =IF(F34=0,0,+F34/D34) -> 1.0009058 | I34: Pasados hay que ver cuanto mas se pasará | K34: 6200 | M34: =IF($E$2=0,0,+D34/$E$2) -> 23 | N34: =IF($F$2=0,0,+F34/$F$2) -> 25.113636 | O34: =+M34-N34 -> -2.1136364 | P34: =+K34/$K$2 -> 22.962963
C35: Viaticos y Movilidad Personal | D35: 2500 | E35: =IF($G$7=1,D35,IF(F35<D35,F35,D35)) -> 1953.7 | F35: 1953.7 | G35: =E35-F35 -> 0 | K35: 2632.04 | M35: =IF($E$2=0,0,+D35/$E$2) -> 10.416667 | N35: =IF($F$2=0,0,+F35/$F$2) -> 8.8804545 | O35: =+M35-N35 -> 1.5362121 | P35: =+K35/$K$2 -> 9.7482963 | T35: =+F35+S35 -> 1953.7 | U35: =+D35-T35 -> 546.3
C36: Uniformes | D36: 1500 | E36: =IF($G$7=1,D36,IF(F36<D36,F36,D36)) -> 1138.1 | F36: 1138.1 | G36: =E36-F36 -> 0 | K36: 1723.61
C37: Permisos de Caza/Pesca | D37: 0 | E37: =IF($F$2=0,0,+D37/$E$2*$F$2) -> 0 | F37: 0 | G37: =E37-F37 -> 0 | H37: Pax | K37: 0 | M37: =IF($E$4=0,0,+D37/$E$4) -> 0 | N37: =IF($F$4=0,0,+F37/$F$4) -> 0 | O37: =+M37-N37 -> 0 | P37: =+K37/$K$4 -> 0
C38: Mantenimiento/Reposiciones | D38: =SUM(D39:D41) -> 15000 | E38: =SUM(E39:E41) -> 15000 | F38: =SUM(F39:F41) -> 15817.23 | G38: =SUM(G39:G41) -> -817.23 | H38: =+F38/D38 -> 1.054482 | K38: =SUM(K39:K41) -> 10601.67
C39: Lodge | D39: =8000+5500+1500-D41-D40 -> 6633.12 | E39: =IF(G7=1,D39,IF($G$2<1,IF(F39<D39,F39,D39),D39)) -> 6633.12 | F39: 7450.35 | G39: =E39-F39 -> -817.23 | I39: Pasados Real mínimos | K39: 4133.57 | S39: =250000/480 -> 520.83333 | T39: =+F39+S39 -> 7971.1833 | U39: =+D39-T39 -> -1338.0633
C40: Vehiculos | D40: =+F40 -> 2890.32 | E40: =IF(G7=1,D40,IF($G$2<1,IF(F40<D40,F40,D40),D40)) -> 2890.32 | F40: 2890.32 | G40: =E40-F40 -> 0 | K40: 5626.03 | M40: =IF($E$2=0,0,+D40/$E$2) -> 12.043 | N40: =IF($F$2=0,0,+F40/$F$2) -> 13.137818 | O40: =+M40-N40 -> -1.0948182 | T40: =+F40+S40 -> 2890.32 | U40: =+D40-T40 -> 0
C41: Equipos | D41: =+F41 -> 5476.56 | E41: =IF($G$2<1,IF(F41<D41,F41,D41),D41) -> 5476.56 | F41: 5476.56 | G41: =E41-F41 -> 0 | K41: 842.07
C42: Comunicaciones | D42: 150 | E42: =IF($G$7=1,D42,IF(F42<D42,F42,D42)) -> 105.06 | F42: 105.06 | G42: =E42-F42 -> 0 | H42: FD | K42: 121.46 | M42: =IF($E$2=0,0,+D42/$E$2) -> 0.625 | N42: =IF($F$2=0,0,+F42/$F$2) -> 0.47754545 | O42: =+M42-N42 -> 0.14745455 | P42: =+K42/$K$2 -> 0.44985185 | S42: 25 | T42: =+F42+S42 -> 130.06 | U42: =+D42-T42 -> 19.94
C43: Seguros | D43: 500 | E43: =IF($G$7=1,D43,IF(F43<D43,F43,D43)) -> 500 | F43: 1300 | G43: =E43-F43 -> -800 | H43: =+F43/D43 -> 2.6 | I43: pasados Real se logro asegurar el Lodge. | K43: 407.57 | S43: =50*2 -> 100 | T43: =+F43+S43 -> 1400 | U43: =+D43-T43 -> -900
...

Sheet Budget Del 25-26
C1: Total Gastos Operativos | D1: Por Diego | F1: =VLOOKUP($C1,INDIRECT(#REF!),#REF!,FALSE) -> #REF! | G1: =VLOOKUP($C1,INDIRECT(#REF!),#REF!,FALSE) -> #REF!
F2: =IF(F1=E26,"OK","ERROR") -> #REF! | G2: =IF(G1=F26,"OK","ERROR") -> #REF!
G3: TC | H3: 1450
D5: Budget Delta Lodge
D6: Temporada 2025-26
C8: Total Gastos Operativos | F8: =VLOOKUP($C8,INDIRECT(#REF!),#REF!,FALSE) -> #REF! | G8: =VLOOKUP($C8,INDIRECT(#REF!),#REF!,FALSE) -> #REF!
C9: Total | F9: =VLOOKUP($C9,INDIRECT(#REF!),#REF!,FALSE) -> #REF! | G9: =VLOOKUP($C9,INDIRECT(#REF!),#REF!,FALSE) -> #REF!
D10: En Dolares x temporada | G10: En Dolares x bednight | J10: Varianzas | L10: Observaciones
D11: Budget 25-26 | E11: Real 24-25 | F11: Real 23-24 | G11: Budget 25-26 | H11: Real 24-25 | I11: Real 23-24 | J11: Vs 23-24 | K11: Vs 22-23
C12: Parametros
C13: BN | D13: 375 | E13: 328 | F13: 220
C14: FD | D14: =D13*0.85 -> 318.75 | E14: 279
C15: Pax | D15: =D13/2 -> 187.5 | E15: 184 | F15: 120
C16: Fecha Inicio | D16: 45901 | E16: 44805 | F16: 44805
C17: Fecha Cierre | D17: 46265 | E17: 45169 | F17: 45169
C18: Dias | D18: =D17-D16 -> 364 | E18: 364 | F18: 364
C20: Otros Ingresos | D20: =SUBTOTAL(9,D21:D24) -> 675 | E20: =SUM(E21:E24) -> 537.97 | F20: 172 | G20: =D20/D$13 -> 1.8 | H20: =E20/E$20 -> 1 | I20: 1 | J20: =IF(E20=0,0,D20/E20) -> 1.2547168 | K20: =IF(F20=0,0,D20/F20) -> 3.9244186
C21: Shop | D21: =4*D13 -> 1500 | E21: 1097 | F21: 430 | G21: =D21/D$13 -> 4 | H21: =E21/E$13 -> 3.3445122 | I21: 1.9545455 | J21: =IF(E21=0,0,D21/E21) -> 1.3673655 | K21: =IF(F21=0,0,D21/F21) -> 3.4883721
C22: (CMV) Shop | D22: =D21*-0.5 -> -750 | E22: -559.03 | F22: -258 | G22: =D22/D$13 -> -2 | H22: =E22/E$13 -> -1.7043598 | I22: -1.1727273 | J22: =IF(E22=0,0,D22/E22) -> 1.3416096 | K22: =IF(F22=0,0,D22/F22) -> 2.9069767
C23: (Comisiones Ventas Shop) | D23: =(D21+D22)*-0.1 -> -75 | E23: 0 | F23: 0 | G23: =D23/D$13 -> -0.2 | H23: =E23/E$13 -> 0 | I23: 0 | J23: =IF(E23=0,0,D23/E23) -> 0 | K23: =IF(F23=0,0,D23/F23) -> 0
C24: Extras (NET) | D24: 0 | E24: 0 | F24: 0 | G24: =D24/D$13 -> 0 | H24: =E24/E$13 -> 0 | I24: 0 | J24: =IF(E24=0,0,D24/E24) -> 0 | K24: =IF(F24=0,0,D24/F24) -> 0
C26: Gastos Operativos | D26: =SUM(D27:D49)-D28-D34-D42 -> 186500.7 | E26: =SUM(E27:E49)-E28-E34-E42 -> 172506.19 | F26: 89308.51 | G26: =D26/D$13 -> 497.3352 | H26: =E26/E$13 -> 525.93351 | I26: 405.94777 | J26: =IF(E26=0,0,D26/E26) -> 1.0811247 | K26: =IF(F26=0,0,D26/F26) -> 2.0882747
B27: Se vende la lancha de Alan por ende es un año de Labaie y solo dos meses de guarderia extra (Septiembre y lo que tarden en retirar la lancha de octubre) | C27: Canon Lodge | D27: 2200 | E27: 4021 | F27: 1453.2 | G27: =D27/D$13 -> 5.8666667 | H27: =E27/E$13 -> 12.259146 | I27: 6.6054545 | J27: =IF(E27=0,0,D27/E27) -> 0.54712758 | K27: =IF(F27=0,0,D27/F27) -> 1.5139004
C28: Sueldos | D28: =SUM(D29:D32) -> 106217.24 | E28: 94044.26 | F28: 41738.82 | G28: =D28/D$13 -> 283.24598 | H28: =E28/E$13 -> 286.7203 | I28: 189.72191 | J28: =IF(E28=0,0,D28/E28) -> 1.1294389 | K28: =IF(F28=0,0,D28/F28) -> 2.544807
C29: Managers | D29: =Sueldos!H6 -> 17637.931 | E29: 14186.94 | F29: 11360 | G29: =D29/D$13 -> 47.034483 | H29: =E29/E$13 -> 43.252866 | I29: 51.636364 | J29: =IF(E29=0,0,D29/E29) -> 1.2432513 | K29: =IF(F29=0,0,D29/F29) -> 1.5526348
C30: Guias | D30: =Sueldos!D23 -> 47600 | E30: 45154.98 | F30: 24225 | G30: =D30/D$13 -> 126.93333 | H30: =E30/E$13 -> 137.66762 | I30: 110.11364 | J30: =IF(E30=0,0,D30/E30) -> 1.0541473 | K30: =IF(F30=0,0,D30/F30) -> 1.9649123
C31: Servicio | D31: =Sueldos!H14 -> 34151.724 | E31: 30778.14 | F31: 6153.82 | G31: =D31/D$13 -> 91.071264 | H31: =E31/E$13 -> 93.835793 | I31: 27.971909 | J31: =IF(E31=0,0,D31/E31) -> 1.1096097 | K31: =IF(F31=0,0,D31/F31) -> 5.5496788
C32: Cargas Sociales | D32: =Sueldos!B29 -> 6827.5862 | E32: 3924.2 | F32: 0 | G32: =D32/D$13 -> 18.206897 | H32: =E32/E$13 -> 11.964024 | I32: 0 | J32: =IF(E32=0,0,D32/E32) -> 1.739867 | K32: =IF(F32=0,0,D32/F32) -> 0
B33: Vamos a trabajar en mejorar los costos a traves de compras en mayoristas. Tomando un escenario estable, y haciendo el esfuerzo de comprar mejor lo dejo en usd 100 x BN | C33: Comida / Vinos | D33: =100*D13 -> 37500 | E33: 34990.73 | F33: 13355.87 | G33: =D33/D$13 -> 100 | H33: =E33/E$13 -> 106.67905 | I33: 60.7085 | J33: =IF(E33=0,0,D33/E33) -> 1.0717124 | K33: =IF(F33=0,0,D33/F33) -> 2.8077542
C34: Combustible | D34: =SUM(D35:D37) -> 13800.888 | E34: 10635.61 | F34: 5842.89 | G34: =D34/D$13 -> 36.802368 | H34: =E34/E$13 -> 32.42564 | I34: 26.558591 | J34: =IF(E34=0,0,D34/E34) -> 1.2976113 | K34: =IF(F34=0,0,D34/F34) -> 2.3619969
C35: Electricidad | D35: 3000 | E35: 3025.91 | F35: 257.45 | G35: =D35/D$13 -> 8 | H35: =E35/E$13 -> 9.2253354 | I35: 1.1702273 | J35: =IF(E35=0,0,D35/E35) -> 0.99143729 | K35: =IF(F35=0,0,D35/F35) -> 11.652748
B36: Tomando unos 192 botes (La mitad de los FD mas un 15% que suponemos va solo en el bote) temporada, son 40 litros combustible promedio por dia completo guiada, da un total de combustible guias de unos usd 8400. A esto se le suman las cargas de combustible para ir y venir a La Baie. Estimo un total de 10K. Da bastante mas que año pasado porque quedaron en sueldos guias, las guiadas de pablo que incluyen tambien el combustible. Este año vamos a dejar bien imputado sueldo guias y combustible aparte | C36: Vehiculos/Botes | D36: =(((((D14/2)*1.15)*40)*1622)/H3)+1600 -> 9800.8879 | E36: 6652 | F36: 5187.83 | G36: =D36/D$13 -> 26.135701 | H36: =E36/E$13 -> 20.280488 | I36: 23.581045 | J36: =IF(E36=0,0,D36/E36) -> 1.4733746 | K36: =IF(F36=0,0,D36/F36) -> 1.8892076
C37: Gas | D37: 1000 | E37: 957.7 | F37: 397.61 | G37: =D37/D$13 -> 2.6666667 | H37: =E37/E$13 -> 2.9198171 | I37: 1.8073182 | J37: =IF(E37=0,0,D37/E37) -> 1.0441683 | K37: =IF(F37=0,0,D37/F37) -> 2.5150273
C38: Traslado Aerop/Lodge/Alq Vehiculos | D38: 0 | E38: 0 | F38: 5525 | G38: =D38/D$13 -> 0 | H38: =E38/E$13 -> 0 | I38: 25.113636 | J38: =IF(E38=0,0,D38/E38) -> 0 | K38: =IF(F38=0,0,D38/F38) -> 0
B39: Este numero debe bajar considerablemente respecto al real 2025, teniendo en cuenta que se dejen de usar | C39: Viaticos y Movilidad Personal | D39: 4000 | E39: 8898.43 | F39: 1953.7 | G39: =D39/D$13 -> 10.666667 | H39: =E39/E$13 -> 27.12936 | I39: 8.8804545 | J39: =IF(E39=0,0,D39/E39) -> 0.4495175 | K39: =IF(F39=0,0,D39/F39) -> 2.0473972
C40: Uniformes | D40: 2500 | E40: 2761.02 | F40: 1138.1 | G40: =D40/D$13 -> 6.6666667 | H40: =E40/E$13 -> 8.4177439 | I40: 5.1731818 | J40: =IF(E40=0,0,D40/E40) -> 0.90546247 | K40: =IF(F40=0,0,D40/F40) -> 2.1966435
C41: Permisos de Caza | D41: 0 | E41: 125.24 | F41: 0 | G41: =D41/D$13 -> 0 | H41: =E41/E$13 -> 0.38182927 | I41: 0 | J41: =IF(E41=0,0,D41/E41) -> 0 | K41: =IF(F41=0,0,D41/F41) -> 0
C42: Mantenimiento/Reposiciones | D42: =SUM(D43:D45) -> 15000 | E42: 12674.94 | F42: 15817.23 | G42: =D42/D$13 -> 40 | H42: =E42/E$13 -> 38.64311 | I42: 71.8965 | J42: =IF(E42=0,0,D42/E42) -> 1.1834376 | K42: =IF(F42=0,0,D42/F42) -> 0.94833293
B43: Info ya revisada con FDC | C43: Lodge | D43: 8000 | E43: 7633.74 | F43: 7450.35 | G43: =D43/D$13 -> 21.333333 | H43: =E43/E$13 -> 23.273598 | I43: 33.865227 | J43: =IF(E43=0,0,D43/E43) -> 1.0479791 | K43: =IF(F43=0,0,D43/F43) -> 1.0737751
C44: Vehiculos | D44: 6000 | E44: 1430.26 | F44: 2890.32 | G44: =D44/D$13 -> 16 | H44: =E44/E$13 -> 4.3605488 | I44: 13.137818 | J44: =IF(E44=0,0,D44/E44) -> 4.1950415 | K44: =IF(F44=0,0,D44/F44) -> 2.0758947
...

Sheet Sueldos
B1: TC | C1: ='Budget Del 25-26'!H3 -> 1450
A3: Manager | B3: Pago Diario Meses Low Season | C3: Pago Mensual Ene-Feb-Mar | D3: Dias estimados con clientes apertura y cierre | E3: Total sueldo estimado | F3: Sueldo Nomina | G3: Costo Nomina 25% | H3: Costo total
A4: Alejandro | B4: 75 | C4: 2000 | D4: 80 | E4: =(B4*D4)+(C4*3) -> 12000 | F4: =550000/$C$1 -> 379.31034 | G4: =F4*0.25*12 -> 1137.931 | H4: =G4+E4 -> 13137.931
A5: Dias Noel Apertura y Cierre grupos | B5: 30 | D5: 150 | E5: =D5*B5 -> 4500 | H5: =E5+G5 -> 4500
H6: =SUM(H4:H5) -> 17637.931
A9: Servicio | B9: Pago Diario Meses Low Season | C9: Pago Mensual Ene-Feb-Mar | D9: Dias estimados con clientes apertura y cierre | E9: Total sueldo estimado | F9: Sueldo Nomina | G9: Costo Nomina 25% | H9: Costo total
A10: Andres Cocinero | B10: 65 | C10: 1500 | D10: 80 | E10: =(B10*D10)+(C10*3) -> 9700 | F10: =550000/$C$1 -> 379.31034 | G10: =F10*0.25*12 -> 1137.931 | H10: =G10+E10 -> 10837.931
A11: Alexis Mantenimiento | C11: 600 | E11: =C11*12 -> 7200 | F11: =550000/$C$1 -> 379.31034 | G11: =F11*0.25*12 -> 1137.931 | H11: =G11+E11 -> 8337.931
A12: Karina Mucama | B12: 65 | C12: 1500 | D12: 80 | E12: =(B12*D12)+(C12*3) -> 9700 | F12: =550000/$C$1 -> 379.31034 | G12: =F12*0.25*12 -> 1137.931 | H12: =G12+E12 -> 10837.931
A13: Dias Noel francos Casero | B13: 50 | D13: 60 | E13: =D13*B13 -> 3000 | F13: =550000/$C$1 -> 379.31034 | G13: =F13*0.25*12 -> 1137.931 | H13: =G13+E13 -> 4137.931
H14: =SUM(H10:H13) -> 34151.724
A18: Guías | B18: Pago Diario | C18: Dias estimados de guiada | D18: Total
A19: Noel | B19: 200 | C19: 100 | D19: =C19*B19 -> 20000
A20: Pablo | B20: 280 | C20: 70 | D20: =C20*B20 -> 19600
A21: Matías | B21: 200 | C21: 35 | D21: =C21*B21 -> 7000
A22: guiadas Ale | B22: 50 | C22: 20 | D22: =C22*B22 -> 1000
D23: =SUM(D19:D22) -> 47600
A25: Cargas Sociales
A26: Manager | B26: =F10*0.3*12 -> 1365.5172
A27: Servicio | B27: =SUM(F10:F13)*0.3*12 -> 5462.069
A28: Guías | B28: 0
A29: Total Cargas | B29: =SUM(B26:B28) -> 6827.5862
