Workbook
Name _Rt12: #REF!
Name AJUSTES: #REF!
Name Assumptions: #REF!
Name BN_CY: #REF!
Name BN_LY: #REF!
Name BN_PY: #REF!
Name BuiltIn_Print_Area: #REF!
Name BuiltIn_Print_Area___0: #REF!
Name BuiltIn_Print_Titles: #REF!
Name BuiltIn_Print_Titles___0: #REF!
Name CASH_FLOW: #REF!
Name Costo: #REF!
Name DAYS_CY: #REF!
Name Depreciation_Investment: #REF!
Name EVOLUCION___0: #N/A
Name FC_CY: #REF!
Name FC_LY: #REF!
Name FC_PY: #REF!
Name FI_CY: #REF!
Name FI_LY: #REF!
Name FI_PY: #REF!
Name IBrutos: #REF!
Name INCOME_STATEMENT: #REF!
Name Intang: #REF!
Name LCR_Real: #REF!
Name Macro1: #N/A
Name Monext: #REF!
Name PAX_CY: #REF!
Name PAX_LY: #REF!
Name PAX_PY: #REF!
Name PERSONNEL: #REF!
Name Real22: #REF!
Name Real23: #REF!
Name RealVM23: #REF!
Name Revenues_Expenses: #REF!
Name Total_Sales__quantity: #REF!
Name Uniona: #REF!

Sheet Real al 31-7-24
B2: Control BUDGET
B3: TEMPORADA 2023-2024 | D3: =IF(ROUND(D61,2)=0,"ok","Check") -> #VALUE! | F3: =IF(ROUND(F61,2)=0,"ok","Check") -> #VALUE! | K3: =IF(ROUND(K61,2)=0,"ok","Check") -> #VALUE! | M3: =IF(ROUND(M61,2)=0,"ok","Check") -> #VALUE! | R3: =IF(ROUND(R61,2)=0,"ok","Check") -> #VALUE! | T3: =IF(ROUND(T61,2)=0,"ok","Check") -> #VALUE!
B5: OK | D5: TUC LODGE | K5: ET LODGE | R5: TUC + ET LODGE | Y5: TUC LODGE | AF5: ET LODGE
A7: Criterio | B7: Ítem /LODGES | D7: TUC LODGE BUDGET TOTAL | E7: TUC LODGE BUDGET Comparable | F7: TUC LODGE REAL | G7: TUC LODGE Diferencia Desvío | H7: TUC LODGE Observación | K7: ET LODGE BUDGET TOTAL | L7: ET LODGE BUDGET Comparable | M7: ET LODGE REAL | N7: ET LODGE Diferencia Desvío | O7: ET LODGE Observación | R7: TUC + ET LODGE BUDGET TOTAL | S7: TUC + ET LODGE BUDGET Comparable | T7: TUC + ET LODGE REAL | U7: TUC + ET LODGE Diferencia Desvío | V7: TUC + ET LODGE Observación | Y7: TUC LODGE BUDGET TOTAL | Z7: TUC LODGE REAL | AA7: TUC LODGE % | AF7: ET LODGE BUDGET TOTAL | AG7: ET LODGE REAL | AH7: ET LODGE %
B8: Total BN | D8: 1200 | E8: =+F8 -> 1039 | F8: 1039 | G8: =+F8/D8 -> 0.86583333 | K8: 160 | L8: =+M8 -> 79 | M8: 79 | N8: =+M8/K8 -> 0.49375 | R8: =+D8+K8 -> 1360 | S8: =+E8+L8 -> 1118 | T8: =+F8+M8 -> 1118 | U8: =+T8/R8 -> 0.82205882 | Y8: =+'[1]Budget Comparativo'!D8 -> 1200 | Z8: =+'[1]Budget Comparativo'!F8 -> 1039 | AA8: =+Z8/Y8 -> 0.86583333 | AF8: =+'[1]Budget Comparativo'!K8 -> 160 | AG8: =+'[1]Budget Comparativo'!M8 -> 79 | AH8: =+AG8/AF8 -> 0.49375
B9: Total pax | D9: =ROUND(D8/3,0) -> 400 | E9: =+F9 -> 338 | F9: 338 | G9: =+F9/D9 -> 0.845 | K9: =ROUND(K8/2,0) -> 80 | L9: =+M9 -> 55 | M9: 55 | N9: =+M9/K9 -> 0.6875 | R9: =+D9+K9 -> 480 | S9: =+E9+L9 -> 393 | T9: =+F9+M9 -> 393 | U9: =+T9/R9 -> 0.81875 | Y9: =+'[1]Budget Comparativo'!D9 -> 400 | Z9: =+'[1]Budget Comparativo'!F9 -> 338 | AA9: =+Z9/Y9 -> 0.845 | AF9: =+'[1]Budget Comparativo'!K9 -> 80 | AG9: =+'[1]Budget Comparativo'!M9 -> 55 | AH9: =+AG9/AF9 -> 0.6875
B10: Meses Transcurridos | D10: 12 | E10: =+F10 -> 11 | F10: 11 | G10: =+F10/D10 -> 0.91666667 | I10: =IF(ROUND(F10,0)=0,0,IF(D10=0,0,+F10/D10)) -> 0.91666667 | K10: 12 | L10: =+M10 -> 11 | M10: =+F10 -> 11 | N10: =+M10/K10 -> 0.91666667 | P10: =IF(ROUND(M10,0)=0,0,IF(K10=0,0,+M10/K10)) -> 0.91666667 | R10: 12 | S10: =+T10 -> 11 | T10: =+M10 -> 11 | U10: =+T10/R10 -> 0.91666667 | W10: =IF(ROUND(T10,0)=0,0,IF(R10=0,0,+T10/R10)) -> 0.91666667 | Y10: =+'[1]Budget Comparativo'!D10 -> 12 | Z10: =+'[1]Budget Comparativo'!F10 -> 11 | AA10: =+Z10/Y10 -> 0.91666667 | AF10: =+'[1]Budget Comparativo'!K10 -> 12 | AG10: =+'[1]Budget Comparativo'!M10 -> 11 | AH10: =+AG10/AF10 -> 0.91666667 | AJ10: Ctas
B11: INCOMES
B13: Other Income
A14: BN | B14: Shop | D14: =ROUND($D$8*25,0) -> 30000 | E14: =IF(A14="Acumulado",IF(F14>D14,D14,F14),IF(A14="BN",+(D14/$D$8*$E$8),"VER")) -> 25975 | F14: =-SUMIF([1]Resumen_Base!$A$7:$A$91,'[1]Budget Comparativo'!B14,[1]Resumen_Base!$Y$7:$Y$91) -> #VALUE! | G14: =+F14-E14 -> #VALUE! | H14: Bajo se compensa con las excelentes ventas de Libros | K14: =ROUND($K$8*5,0) -> 800 | L14: =IF(A14="Acumulado",IF(M14>K14,K14,M14),IF(A14="BN",+(K14/$K$8*$L$8),"VER")) -> 395 | M14: =-SUMIF([1]Resumen_Base!$A$94:$A$160,'[1]Budget Comparativo'!B14,[1]Resumen_Base!$Y$94:$Y$160) -> #VALUE! | N14: =+M14-L14 -> #VALUE! | R14: =+D14+K14 -> 30800 | S14: =+E14+L14 -> 26370 | T14: =+F14+M14 -> #VALUE! | U14: =+T14-S14 -> #VALUE! | Y14: =+'[1]Budget Comparativo'!D14/'[1]Budget Comparativo'!$Y$8 -> 25 | Z14: =+'[1]Budget Comparativo'!F14/'[1]Budget Comparativo'!$Z$8 -> 14.361883 | AA14: =+Z14-Y14 -> -10.638117 | AF14: =+'[1]Budget Comparativo'!K14/'[1]Budget Comparativo'!$AF$8 -> 5 | AG14: =+'[1]Budget Comparativo'!M14/'[1]Budget Comparativo'!$AG$8 -> 2.7848101 | AH14: =+AG14-AF14 -> -2.2151899 | AJ14: 4104
A15: BN | B15: Extras | D15: =ROUND($D$8*24,0) -> 28800 | E15: =IF(A15="Acumulado",IF(F15>D15,D15,F15),IF(A15="BN",+(D15/$D$8*$E$8),"VER")) -> 24936 | F15: =-SUMIF([1]Resumen_Base!$A$7:$A$91,'[1]Budget Comparativo'!B15,[1]Resumen_Base!$Y$7:$Y$91)-'[1]Stock - Deudas'!$F$14 -> #VALUE! | G15: =+F15-E15 -> #VALUE! | H15: Muy Buenas Ventas | K15: =ROUND($K$8*10,0) -> 1600 | L15: =IF(A15="Acumulado",IF(M15>K15,K15,M15),IF(A15="BN",+(K15/$K$8*$L$8),"VER")) -> 790 | M15: =-SUMIF([1]Resumen_Base!$A$94:$A$160,'[1]Budget Comparativo'!B15,[1]Resumen_Base!$Y$94:$Y$160) -> #VALUE! | N15: =+M15-L15 -> #VALUE! | R15: =+D15+K15 -> 30400 | S15: =+E15+L15 -> 25726 | T15: =+F15+M15 -> #VALUE! | U15: =+T15-S15 -> #VALUE! | Y15: =+'[1]Budget Comparativo'!D15/'[1]Budget Comparativo'!$Y$8 -> 24 | Z15: =+'[1]Budget Comparativo'!F15/'[1]Budget Comparativo'!$Z$8 -> 39.152796 | AA15: =+Z15-Y15 -> 15.152796 | AF15: =+'[1]Budget Comparativo'!K15/'[1]Budget Comparativo'!$AF$8 -> 10 | AG15: =+'[1]Budget Comparativo'!M15/'[1]Budget Comparativo'!$AG$8 -> 0.75949367 | AH15: =+AG15-AF15 -> -9.2405063 | AJ15: 4103 | AK15: 4110 | AL15: 4112 | AM15: 4114 | AN15: 5285 | AO15: 5104 | AP15: 4118 | AQ15: 4129 | AR15: 5290 | AS15: 5103
A16: BN | B16: Gun Rental | D16: =+D8*130*0.65 -> 101400 | E16: =IF(A16="Acumulado",IF(F16>D16,D16,F16),IF(A16="BN",+(D16/$D$8*$E$8),"VER")) -> 87795.5 | F16: =-SUMIF([1]Resumen_Base!$A$7:$A$91,'[1]Budget Comparativo'!B16,[1]Resumen_Base!$Y$7:$Y$91)-'[1]Stock - Deudas'!$F$12 -> #VALUE! | G16: =+F16-E16 -> #VALUE! | H16: Sigue con buena tendencia | K16: =+$K$8*130*0.65 -> 13520 | L16: =IF(A16="Acumulado",IF(M16>K16,K16,M16),IF(A16="BN",+(K16/$K$8*$L$8),"VER")) -> 6675.5 | M16: =-SUMIF([1]Resumen_Base!$A$94:$A$160,'[1]Budget Comparativo'!B16,[1]Resumen_Base!$Y$94:$Y$160) -> #VALUE! | N16: =+M16-L16 -> #VALUE! | R16: =+D16+K16 -> 114920 | S16: =+E16+L16 -> 94471 | T16: =+F16+M16 -> #VALUE! | U16: =+T16-S16 -> #VALUE! | Y16: =+'[1]Budget Comparativo'!D16/'[1]Budget Comparativo'!$Y$8 -> 84.5 | Z16: =+'[1]Budget Comparativo'!F16/'[1]Budget Comparativo'!$Z$8 -> 90.127383 | AA16: =+Z16-Y16 -> 5.6273826 | AF16: =+'[1]Budget Comparativo'!K16/'[1]Budget Comparativo'!$AF$8 -> 84.5 | AG16: =+'[1]Budget Comparativo'!M16/'[1]Budget Comparativo'!$AG$8 -> 105.94937 | AH16: =+AG16-AF16 -> 21.449367 | AJ16: 4120 | AK16: 5286 | AL16: 5229
B17: Insert
B18: Total Other Income | D18: =SUM(D13:D17) -> 160200 | E18: =SUM(E13:E17) -> 138706.5 | F18: =SUM(F13:F17) -> #VALUE! | G18: =SUM(G13:G17) -> #VALUE! | K18: =SUM(K13:K17) -> 15920 | L18: =SUM(L13:L17) -> 7860.5 | M18: =SUM(M13:M17) -> #VALUE! | N18: =SUM(N13:N17) -> #VALUE! | R18: =SUM(R13:R17) -> 176120 | S18: =SUM(S13:S17) -> 146567 | T18: =SUM(T13:T17) -> #VALUE! | U18: =SUM(U13:U17) -> #VALUE! | Y18: =SUM(Y13:Y17) -> 133.5 | Z18: =SUM(Z13:Z17) -> 143.64206 | AA18: =+Z18-Y18 -> 10.142062 | AF18: =SUM(AF13:AF17) -> 99.5 | AG18: =SUM(AG13:AG17) -> 109.49367 | AH18: =+AG18-AF18 -> 9.9936709
B20: EXPENSES
B22: Operative Expenses
B23: Canon & Labour Permits + Filed - Baiting/Maize | D23: =+SUM(D24:D26) -> 36800 | E23: =+SUM(E24:E26) -> #VALUE! | F23: =+SUM(F24:F26) -> #VALUE! | G23: =+SUM(G24:G26) -> #VALUE! | K23: =+SUM(K24:K26) -> 3000 | L23: =+SUM(L24:L26) -> #VALUE! | M23: =+SUM(M24:M26) -> #VALUE! | N23: =+SUM(N24:N26) -> #VALUE! | R23: =+SUM(R24:R26) -> 39800 | S23: =+SUM(S24:S26) -> #VALUE! | T23: =+SUM(T24:T26) -> #VALUE! | U23: =+SUM(U24:U26) -> #VALUE! | Y23: =+'[1]Budget Comparativo'!D23/'[1]Budget Comparativo'!$Y$8 -> 30.666667 | Z23: =+'[1]Budget Comparativo'!F23/'[1]Budget Comparativo'!$Z$8 -> 21.208518 | AA23: =+Y23-Z23 -> 9.4581485 | AF23: =+'[1]Budget Comparativo'!K23/'[1]Budget Comparativo'!$AF$8 -> 18.75 | AG23: =+'[1]Budget Comparativo'!M23/'[1]Budget Comparativo'!$AG$8 -> 0.51144355 | AH23: =+AF23-AG23 -> 18.238556
A24: Acumulado | B24: Canon Lodge/Labor Permits: | D24: 14200 | E24: =IF(A24="Acumulado",IF(F24>D24,D24,F24),IF(A24="BN",+(D24/$D$8*$E$8),"VER")) -> #VALUE! | F24: =+SUMIF([1]Resumen_Base!$A$7:$A$91,'[1]Budget Comparativo'!B24,[1]Resumen_Base!$Y$7:$Y$91) -> #VALUE! | G24: =+E24-F24 -> #VALUE! | I24: =IF(ROUND(F24,0)=0,0,IF(D24=0,0,+F24/D24)) -> #VALUE! | K24: 0 | L24: =IF(A24="Acumulado",IF(M24>K24,K24,M24),IF(A24="BN",+(K24/$K$8*$L$8),"VER")) -> #VALUE! | M24: =SUMIF([1]Resumen_Base!$A$94:$A$160,'[1]Budget Comparativo'!B24,[1]Resumen_Base!$Y$94:$Y$160) -> #VALUE! | N24: =+L24-M24 -> #VALUE! | P24: =IF(ROUND(M24,0)=0,0,IF(K24=0,0,+M24/K24)) -> #VALUE! | R24: =+D24+K24 -> 14200 | S24: =+E24+L24 -> #VALUE! | T24: =+F24+M24 -> #VALUE! | U24: =+S24-T24 -> #VALUE! | W24: =IF(ROUND(T24,0)=0,0,IF(R24=0,0,+T24/R24)) -> #VALUE! | Y24: =+'[1]Budget Comparativo'!D24/'[1]Budget Comparativo'!$Y$8 -> 11.833333 | Z24: =+'[1]Budget Comparativo'!F24/'[1]Budget Comparativo'!$Z$8 -> 12.704524 | AA24: =+Y24-Z24 -> -0.87119025 | AF24: =+'[1]Budget Comparativo'!K24/'[1]Budget Comparativo'!$AF$8 -> 0 | AG24: =+'[1]Budget Comparativo'!M24/'[1]Budget Comparativo'!$AG$8 -> 0 | AH24: =+AF24-AG24 -> 0 | AJ24: 5208
A25: Acumulado | B25: Field: | D25: =+$D$8*18 -> 21600 | E25: =IF(A25="Acumulado",IF(F25>D25,D25,F25),IF(A25="BN",+(D25/$D$8*$E$8),"VER")) -> #VALUE! | F25: =+SUMIF([1]Resumen_Base!$A$7:$A$91,'[1]Budget Comparativo'!B25,[1]Resumen_Base!$Y$7:$Y$91) -> #VALUE! | G25: =+E25-F25 -> #VALUE! | H25: ok seguro acá haya un gran ahorro | I25: =IF(ROUND(F25,0)=0,0,+F25/D25) -> #VALUE! | K25: 0 | L25: =IF(A25="Acumulado",IF(M25>K25,K25,M25),IF(A25="BN",+(K25/$K$8*$L$8),"VER")) -> #VALUE! | M25: =SUMIF([1]Resumen_Base!$A$94:$A$160,'[1]Budget Comparativo'!B25,[1]Resumen_Base!$Y$94:$Y$160) -> #VALUE! | N25: =+L25-M25 -> #VALUE! | P25: =IF(ROUND(M25,0)=0,0,+M25/K25) -> #VALUE! | R25: =+D25+K25 -> 21600 | S25: =+E25+L25 -> #VALUE! | T25: =+F25+M25 -> #VALUE! | U25: =+S25-T25 -> #VALUE! | W25: =IF(ROUND(T25,0)=0,0,+T25/R25) -> #VALUE! | Y25: =+'[1]Budget Comparativo'!D25/'[1]Budget Comparativo'!$Y$8 -> 18 | Z25: =+'[1]Budget Comparativo'!F25/'[1]Budget Comparativo'!$Z$8 -> 8.5039946 | AA25: =+Y25-Z25 -> 9.4960054 | AF25: =+'[1]Budget Comparativo'!K25/'[1]Budget Comparativo'!$AF$8 -> 0 | AG25: =+'[1]Budget Comparativo'!M25/'[1]Budget Comparativo'!$AG$8 -> 0 | AH25: =+AF25-AG25 -> 0 | AJ25: 5207 | AK25: 5283
A26: Acumulado | B26: Baiting/Maize: | D26: 1000 | E26: =IF(A26="Acumulado",IF(F26>D26,D26,F26),IF(A26="BN",+(D26/$D$8*$E$8),"VER")) -> #VALUE! | F26: =+SUMIF([1]Resumen_Base!$A$7:$A$91,'[1]Budget Comparativo'!B26,[1]Resumen_Base!$Y$7:$Y$91) -> #VALUE! | G26: =+E26-F26 -> #VALUE! | I26: =IF(ROUND(F26,0)=0,0,IF(D26=0,0,+F26/D26)) -> #VALUE! | K26: 3000 | L26: =IF(A26="Acumulado",IF(M26>K26,K26,M26),IF(A26="BN",+(K26/$K$8*$L$8),"VER")) -> #VALUE! | M26: =SUMIF([1]Resumen_Base!$A$94:$A$160,'[1]Budget Comparativo'!B26,[1]Resumen_Base!$Y$94:$Y$160) -> #VALUE! | N26: =+L26-M26 -> #VALUE! | P26: =IF(ROUND(M26,0)=0,0,IF(K26=0,0,+M26/K26)) -> #VALUE! | R26: =+D26+K26 -> 4000 | S26: =+E26+L26 -> #VALUE! | T26: =+F26+M26 -> #VALUE! | U26: =+S26-T26 -> #VALUE! | W26: =IF(ROUND(T26,0)=0,0,IF(R26=0,0,+T26/R26)) -> #VALUE! | Y26: =+'[1]Budget Comparativo'!D26/'[1]Budget Comparativo'!$Y$8 -> 0.83333333 | Z26: =+'[1]Budget Comparativo'!F26/'[1]Budget Comparativo'!$Z$8 -> 0 | AA26: =+Y26-Z26 -> 0.83333333 | AF26: =+'[1]Budget Comparativo'!K26/'[1]Budget Comparativo'!$AF$8 -> 18.75 | AG26: =+'[1]Budget Comparativo'!M26/'[1]Budget Comparativo'!$AG$8 -> 0.51144355 | AH26: =+AF26-AG26 -> 18.238556 | AJ26: 5284 | AK26: 5258
B27: Salaries | D27: =+SUM(D28:D31) -> 102000 | E27: =+SUM(E28:E31) -> #VALUE! | F27: =+SUM(F28:F31) -> #VALUE! | G27: =+SUM(G28:G31) -> #VALUE! | H27: Estimamos vamos a pasarnos unos 10 y 15k a fin año en total General Sueldos y Cargas Sociales. | I27: =IF(ROUND(F27,0)=0,0,IF(D27=0,0,+F27/D27)) -> #VALUE! | K27: =+SUM(K28:K31) -> 33192 | L27: =+SUM(L28:L31) -> #VALUE! | M27: =+SUM(M28:M31) -> #VALUE! | N27: =+SUM(N28:N31) -> #VALUE! | P27: =IF(ROUND(M27,0)=0,0,IF(K27=0,0,+M27/K27)) -> #VALUE! | R27: =+SUM(R28:R31) -> 135192 | S27: =+SUM(S28:S31) -> #VALUE! | T27: =+SUM(T28:T31) -> #VALUE! | U27: =+SUM(U28:U31) -> #VALUE! | W27: =IF(ROUND(T27,0)=0,0,IF(R27=0,0,+T27/R27)) -> #VALUE! | Y27: =+'[1]Budget Comparativo'!D27/'[1]Budget Comparativo'!$Y$8 -> 85 | Z27: =+'[1]Budget Comparativo'!F27/'[1]Budget Comparativo'!$Z$8 -> 96.388462 | AA27: =+Y27-Z27 -> -11.388462 | AF27: =+'[1]Budget Comparativo'!K27/'[1]Budget Comparativo'!$AF$8 -> 207.45 | AG27: =+'[1]Budget Comparativo'!M27/'[1]Budget Comparativo'!$AG$8 -> 152.19206 | AH27: =+AF27-AG27 -> 55.257937
A28: Acumulado | B28: Manager | D28: 30000 | E28: =IF(A28="Acumulado",IF(F28>D28,D28,F28),IF(A28="BN",+(D28/$D$8*$E$8),"VER")) -> #VALUE! | F28: =+SUMIF([1]Resumen_Base!$A$7:$A$91,'[1]Budget Comparativo'!B28,[1]Resumen_Base!$Y$7:$Y$91)+'[1]Stock - Deudas'!F16 -> #VALUE! | G28: =+E28-F28 -> #VALUE! | H28: Vamos a pasarnos 5k | I28: =IF(ROUND(F28,0)=0,0,IF(D28=0,0,+F28/D28)) -> #VALUE! | K28: 3692 | L28: =IF(A28="Acumulado",IF(M28>K28,K28,M28),IF(A28="BN",+(K28/$K$8*$L$8),"VER")) -> #VALUE! | M28: =SUMIF([1]Resumen_Base!$A$94:$A$160,'[1]Budget Comparativo'!B28,[1]Resumen_Base!$Y$94:$Y$160) -> #VALUE! | N28: =+L28-M28 -> #VALUE! | P28: =IF(ROUND(M28,0)=0,0,IF(K28=0,0,+M28/K28)) -> #VALUE! | R28: =+D28+K28 -> 33692 | S28: =+E28+L28 -> #VALUE! | T28: =+F28+M28 -> #VALUE! | U28: =+S28-T28 -> #VALUE! | W28: =IF(ROUND(T28,0)=0,0,IF(R28=0,0,+T28/R28)) -> #VALUE! | Y28: =+'[1]Budget Comparativo'!D28/'[1]Budget Comparativo'!$Y$8 -> 25 | Z28: =+'[1]Budget Comparativo'!F28/'[1]Budget Comparativo'!$Z$8 -> 30.514206 | AA28: =+Y28-Z28 -> -5.514206 | AF28: =+'[1]Budget Comparativo'!K28/'[1]Budget Comparativo'!$AF$8 -> 23.075 | AG28: =+'[1]Budget Comparativo'!M28/'[1]Budget Comparativo'!$AG$8 -> 36.184557 | AH28: =+AF28-AG28 -> -13.109557 | AJ28: 5228
A29: Acumulado | B29: Guides | D29: 26000 | E29: =IF(A29="Acumulado",IF(F29>D29,D29,F29),IF(A29="BN",+(D29/$D$8*$E$8),"VER")) -> #VALUE! | F29: =+SUMIF([1]Resumen_Base!$A$7:$A$91,'[1]Budget Comparativo'!B29,[1]Resumen_Base!$Y$7:$Y$91)+'[1]Stock - Deudas'!F20 -> #VALUE! | G29: =+E29-F29 -> #VALUE! | H29: justos quiza algo nos pasemos mínimo | I29: =IF(ROUND(F29,0)=0,0,IF(D29=0,0,+F29/D29)) -> #VALUE! | K29: 17500 | L29: =IF(A29="Acumulado",IF(M29>K29,K29,M29),IF(A29="BN",+(K29/$K$8*$L$8),"VER")) -> #VALUE! | M29: =SUMIF([1]Resumen_Base!$A$94:$A$160,'[1]Budget Comparativo'!B29,[1]Resumen_Base!$Y$94:$Y$160) -> #VALUE! | N29: =+L29-M29 -> #VALUE! | P29: =IF(ROUND(M29,0)=0,0,IF(K29=0,0,+M29/K29)) -> #VALUE! | R29: =+D29+K29 -> 43500 | S29: =+E29+L29 -> #VALUE! | T29: =+F29+M29 -> #VALUE! | U29: =+S29-T29 -> #VALUE! | W29: =IF(ROUND(T29,0)=0,0,IF(R29=0,0,+T29/R29)) -> #VALUE! | Y29: =+'[1]Budget Comparativo'!D29/'[1]Budget Comparativo'!$Y$8 -> 21.666667 | Z29: =+'[1]Budget Comparativo'!F29/'[1]Budget Comparativo'!$Z$8 -> 24.816297 | AA29: =+Y29-Z29 -> -3.1496306 | AF29: =+'[1]Budget Comparativo'!K29/'[1]Budget Comparativo'!$AF$8 -> 109.375 | AG29: =+'[1]Budget Comparativo'!M29/'[1]Budget Comparativo'!$AG$8 -> 19.963527 | AH29: =+AF29-AG29 -> 89.411473 | AJ29: 5227 | AK29: 5280
A30: Acumulado | B30: Services/House | D30: 35000 | E30: =IF(A30="Acumulado",IF(F30>D30,D30,F30),IF(A30="BN",+(D30/$D$8*$E$8),"VER")) -> #VALUE! | F30: =+SUMIF([1]Resumen_Base!$A$7:$A$91,'[1]Budget Comparativo'!B30,[1]Resumen_Base!$Y$7:$Y$91)+'[1]Stock - Deudas'!F18 -> #VALUE! | G30: =+E30-F30 -> #VALUE! | H30: vamos a terminar pasados 5k aprox. | I30: =IF(ROUND(F30,0)=0,0,IF(D30=0,0,+F30/D30)) -> #VALUE! | K30: 8000 | L30: =IF(A30="Acumulado",IF(M30>K30,K30,M30),IF(A30="BN",+(K30/$K$8*$L$8),"VER")) -> #VALUE! | M30: =SUMIF([1]Resumen_Base!$A$94:$A$160,'[1]Budget Comparativo'!B30,[1]Resumen_Base!$Y$94:$Y$160) -> #VALUE! | N30: =+L30-M30 -> #VALUE! | P30: =IF(ROUND(M30,0)=0,0,IF(K30=0,0,+M30/K30)) -> #VALUE! | R30: =+D30+K30 -> 43000 | S30: =+E30+L30 -> #VALUE! | T30: =+F30+M30 -> #VALUE! | U30: =+S30-T30 -> #VALUE! | W30: =IF(ROUND(T30,0)=0,0,IF(R30=0,0,+T30/R30)) -> #VALUE! | Y30: =+'[1]Budget Comparativo'!D30/'[1]Budget Comparativo'!$Y$8 -> 29.166667 | Z30: =+'[1]Budget Comparativo'!F30/'[1]Budget Comparativo'!$Z$8 -> 28.118968 | AA30: =+Y30-Z30 -> 1.0476982 | AF30: =+'[1]Budget Comparativo'!K30/'[1]Budget Comparativo'!$AF$8 -> 50 | AG30: =+'[1]Budget Comparativo'!M30/'[1]Budget Comparativo'!$AG$8 -> 71.329422 | AH30: =+AF30-AG30 -> -21.329422 | AJ30: 5226 | AK30: 5281
A31: Acumulado | B31: Social Security Contributions | D31: 11000 | E31: =IF(A31="Acumulado",IF(F31>D31,D31,F31),IF(A31="BN",+(D31/$D$8*$E$8),"VER")) -> #VALUE! | F31: =+SUMIF([1]Resumen_Base!$A$7:$A$91,'[1]Budget Comparativo'!B31,[1]Resumen_Base!$Y$7:$Y$91) -> #VALUE! | G31: =+E31-F31 -> #VALUE! | H31: Vamos a pasarnos por 3/4k | I31: =IF(ROUND(F31,0)=0,0,IF(D31=0,0,+F31/D31)) -> #VALUE! | K31: 4000 | L31: =IF(A31="Acumulado",IF(M31>K31,K31,M31),IF(A31="BN",+(K31/$K$8*$L$8),"VER")) -> #VALUE! | M31: =SUMIF([1]Resumen_Base!$A$94:$A$160,'[1]Budget Comparativo'!B31,[1]Resumen_Base!$Y$94:$Y$160) -> #VALUE! | N31: =+L31-M31 -> #VALUE! | P31: =IF(ROUND(M31,0)=0,0,IF(K31=0,0,+M31/K31)) -> #VALUE! | R31: =+D31+K31 -> 15000 | S31: =+E31+L31 -> #VALUE! | T31: =+F31+M31 -> #VALUE! | U31: =+S31-T31 -> #VALUE! | W31: =IF(ROUND(T31,0)=0,0,IF(R31=0,0,+T31/R31)) -> #VALUE! | Y31: =+'[1]Budget Comparativo'!D31/'[1]Budget Comparativo'!$Y$8 -> 9.1666667 | Z31: =+'[1]Budget Comparativo'!F31/'[1]Budget Comparativo'!$Z$8 -> 12.93899 | AA31: =+Y31-Z31 -> -3.7723233 | AF31: =+'[1]Budget Comparativo'!K31/'[1]Budget Comparativo'!$AF$8 -> 25 | AG31: =+'[1]Budget Comparativo'!M31/'[1]Budget Comparativo'!$AG$8 -> 24.714557 | AH31: =+AF31-AG31 -> 0.28544304 | AJ31: 5235 | AK31: 5236 | AL31: 5237
A32: BN | B32: Tips | D32: 0 | E32: =IF(A32="Acumulado",IF(F32>D32,D32,F32),IF(A32="BN",+(D32/$D$8*$E$8),"VER")) -> 0 | G32: =+E32-F32 -> 0 | K32: 0 | L32: =IF(A32="Acumulado",IF(M32>K32,K32,M32),IF(A32="BN",+(K32/$K$8*$L$8),"VER")) -> 0 | M32: =SUMIF([1]Resumen_Base!$A$94:$A$160,'[1]Budget Comparativo'!B32,[1]Resumen_Base!$Y$94:$Y$160) -> 0 | N32: =+L32-M32 -> 0 | R32: =+D32+K32 -> 0 | S32: =+E32+L32 -> 0 | T32: =+F32+M32 -> 0 | U32: =+S32-T32 -> 0 | Y32: =+'[1]Budget Comparativo'!D32/'[1]Budget Comparativo'!$Y$8 -> 0 | Z32: =+'[1]Budget Comparativo'!F32/'[1]Budget Comparativo'!$Z$8 -> 0 | AA32: =+Y32-Z32 -> 0 | AF32: =+'[1]Budget Comparativo'!K32/'[1]Budget Comparativo'!$AF$8 -> 0 | AG32: =+'[1]Budget Comparativo'!M32/'[1]Budget Comparativo'!$AG$8 -> 0 | AH32: =+AF32-AG32 -> 0
A33: BN | B33: Food & Wine | D33: =+$D$8*55 -> 66000 | E33: =IF(A33="Acumulado",IF(F33>D33,D33,F33),IF(A33="BN",+(D33/$D$8*$E$8),"VER")) -> 57145 | F33: =+SUMIF([1]Resumen_Base!$A$7:$A$91,'[1]Budget Comparativo'!B33,[1]Resumen_Base!$Y$7:$Y$91)+'[1]Stock - Deudas'!$F$6 -> #VALUE! | G33: =+E33-F33 -> #VALUE! | H33: Pasados Real - Sigue tendencia negativa real por mayor costo que aumento de Tipo de cambio | K33: =ROUND($K$8*60,0) -> 9600 | L33: =IF(A33="Acumulado",IF(M33>K33,K33,M33),IF(A33="BN",+(K33/$K$8*$L$8),"VER")) -> 4740 | M33: =SUMIF([1]Resumen_Base!$A$94:$A$160,'[1]Budget Comparativo'!B33,[1]Resumen_Base!$Y$94:$Y$160)+'[1]Stock - Deudas'!$F$34 -> #VALUE! | N33: =+L33-M33 -> #VALUE! | O33: Real Pasados primera temporada - veremos meses siguientes | R33: =+D33+K33 -> 75600 | S33: =+E33+L33 -> 61885 | T33: =+F33+M33 -> #VALUE! | U33: =+S33-T33 -> #VALUE! | V33: Sigue tendencia negativa real por mayor costo que aumento de Tipo de cambio | Y33: =+'[1]Budget Comparativo'!D33/'[1]Budget Comparativo'!$Y$8 -> 55 | Z33: =+'[1]Budget Comparativo'!F33/'[1]Budget Comparativo'!$Z$8 -> 62.180293 | AA33: =+Y33-Z33 -> -7.180293 | AF33: =+'[1]Budget Comparativo'!K33/'[1]Budget Comparativo'!$AF$8 -> 60 | AG33: =+'[1]Budget Comparativo'!M33/'[1]Budget Comparativo'!$AG$8 -> 86.968729 | AH33: =+AF33-AG33 -> -26.968729 | AJ33: 5250 | AK33: 5251 | AL33: 5213 | AM33: 5291 | AN33: 5289
B34: Electricity - Gas for Boats & Vehicles - Propane | D34: =+SUM(D35:D37) -> 25000 | E34: =+SUM(E35:E37) -> 21645.833 | F34: =+SUM(F35:F37) -> #VALUE! | G34: =+SUM(G35:G37) -> #VALUE! | K34: =+SUM(K35:K37) -> 12200 | L34: =+SUM(L35:L37) -> 6023.75 | M34: =+SUM(M35:M37) -> #VALUE! | N34: =+SUM(N35:N37) -> #VALUE! | R34: =+SUM(R35:R37) -> 37200 | S34: =+SUM(S35:S37) -> 27669.583 | T34: =+SUM(T35:T37) -> #VALUE! | U34: =+SUM(U35:U37) -> #VALUE! | Y34: =+'[1]Budget Comparativo'!D34/'[1]Budget Comparativo'!$Y$8 -> 20.833333 | Z34: =+'[1]Budget Comparativo'!F34/'[1]Budget Comparativo'!$Z$8 -> 23.565077 | AA34: =+Y34-Z34 -> -2.731744 | AF34: =+'[1]Budget Comparativo'!K34/'[1]Budget Comparativo'!$AF$8 -> 76.25 | AG34: =+'[1]Budget Comparativo'!M34/'[1]Budget Comparativo'!$AG$8 -> 37.674536 | AH34: =+AF34-AG34 -> 38.575464
A35: BN | B35: Electricity | D35: 500 | E35: =IF(A35="Acumulado",IF(F35>D35,D35,F35),IF(A35="BN",+(D35/$D$8*$E$8),"VER")) -> 432.91667 | F35: =+SUMIF([1]Resumen_Base!$A$7:$A$91,'[1]Budget Comparativo'!B35,[1]Resumen_Base!$Y$7:$Y$91)+'[1]Stock - Deudas'!$F$8 -> #VALUE! | G35: =+E35-F35 -> #VALUE! | H35: Real Pasados - Combustible Generador y Electricidad Casa Operativa | K35: 6000 | L35: =IF(A35="Acumulado",IF(M35>K35,K35,M35),IF(A35="BN",+(K35/$K$8*$L$8),"VER")) -> 2962.5 | M35: =SUMIF([1]Resumen_Base!$A$94:$A$160,'[1]Budget Comparativo'!B35,[1]Resumen_Base!$Y$94:$Y$160) -> #VALUE! | N35: =+L35-M35 -> #VALUE! | R35: =+D35+K35 -> 6500 | S35: =+E35+L35 -> 3395.4167 | T35: =+F35+M35 -> #VALUE! | U35: =+S35-T35 -> #VALUE! | Y35: =+'[1]Budget Comparativo'!D35/'[1]Budget Comparativo'!$Y$8 -> 0.41666667 | Z35: =+'[1]Budget Comparativo'!F35/'[1]Budget Comparativo'!$Z$8 -> 1.0398772 | AA35: =+Y35-Z35 -> -0.62321056 | AF35: =+'[1]Budget Comparativo'!K35/'[1]Budget Comparativo'!$AF$8 -> 37.5 | AG35: =+'[1]Budget Comparativo'!M35/'[1]Budget Comparativo'!$AG$8 -> 14.905458 | AH35: =+AF35-AG35 -> 22.594542 | AJ35: 5247 | AK35: 5259
A36: BN | B36: Electricity - Gas for Boats & Vehicles | D36: =+$D$8*20 -> 24000 | E36: =IF(A36="Acumulado",IF(F36>D36,D36,F36),IF(A36="BN",+(D36/$D$8*$E$8),"VER")) -> 20780 | F36: =+SUMIF([1]Resumen_Base!$A$7:$A$91,'[1]Budget Comparativo'!B36,[1]Resumen_Base!$Y$7:$Y$91)+'[1]Stock - Deudas'!$F$10 -> #VALUE! | G36: =+E36-F36 -> #VALUE! | H36: Mejora en 2 USD x BN respecto acumulado mes anterior | K36: =ROUND($K$8*20,0) -> 3200 | L36: =IF(A36="Acumulado",IF(M36>K36,K36,M36),IF(A36="BN",+(K36/$K$8*$L$8),"VER")) -> 1580 | M36: =SUMIF([1]Resumen_Base!$A$94:$A$160,'[1]Budget Comparativo'!B36,[1]Resumen_Base!$Y$94:$Y$160) -> #VALUE! | N36: =+L36-M36 -> #VALUE! | R36: =+D36+K36 -> 27200 | S36: =+E36+L36 -> 22360 | T36: =+F36+M36 -> #VALUE! | U36: =+S36-T36 -> #VALUE! | Y36: =+'[1]Budget Comparativo'!D36/'[1]Budget Comparativo'!$Y$8 -> 20 | Z36: =+'[1]Budget Comparativo'!F36/'[1]Budget Comparativo'!$Z$8 -> 22.063032 | AA36: =+Y36-Z36 -> -2.0630323 | AF36: =+'[1]Budget Comparativo'!K36/'[1]Budget Comparativo'!$AF$8 -> 20 | AG36: =+'[1]Budget Comparativo'!M36/'[1]Budget Comparativo'!$AG$8 -> 15.916065 | AH36: =+AF36-AG36 -> 4.0839348 | AJ36: 5248 | AK36: 5288
A37: BN | B37: Propane | D37: 500 | E37: =IF(A37="Acumulado",IF(F37>D37,D37,F37),IF(A37="BN",+(D37/$D$8*$E$8),"VER")) -> 432.91667 | F37: =+SUMIF([1]Resumen_Base!$A$7:$A$91,'[1]Budget Comparativo'!B37,[1]Resumen_Base!$Y$7:$Y$91) -> #VALUE! | G37: =+E37-F37 -> #VALUE! | K37: 3000 | L37: =IF(A37="Acumulado",IF(M37>K37,K37,M37),IF(A37="BN",+(K37/$K$8*$L$8),"VER")) -> 1481.25 | M37: =SUMIF([1]Resumen_Base!$A$94:$A$160,'[1]Budget Comparativo'!B37,[1]Resumen_Base!$Y$94:$Y$160) -> #VALUE! | N37: =+L37-M37 -> #VALUE! | R37: =+D37+K37 -> 3500 | S37: =+E37+L37 -> 1914.1667 | T37: =+F37+M37 -> #VALUE! | U37: =+S37-T37 -> #VALUE! | Y37: =+'[1]Budget Comparativo'!D37/'[1]Budget Comparativo'!$Y$8 -> 0.41666667 | Z37: =+'[1]Budget Comparativo'!F37/'[1]Budget Comparativo'!$Z$8 -> 0.4621678 | AA37: =+Y37-Z37 -> -0.045501138 | AF37: =+'[1]Budget Comparativo'!K37/'[1]Budget Comparativo'!$AF$8 -> 18.75 | AG37: =+'[1]Budget Comparativo'!M37/'[1]Budget Comparativo'!$AG$8 -> 6.8530133 | AH37: =+AF37-AG37 -> 11.896987 | AJ37: 5249
A38: Acumulado | B38: Transfer to and from the airport (local taxi) - Vehicle Rental | D38: 14400 | E38: =IF(A38="Acumulado",IF(F38>D38,D38,F38),IF(A38="BN",+(D38/$D$8*$E$8),"VER")) -> #VALUE! | F38: =+SUMIF([1]Resumen_Base!$A$7:$A$91,'[1]Budget Comparativo'!B38,[1]Resumen_Base!$Y$7:$Y$91) -> #VALUE! | G38: =+E38-F38 -> #VALUE! | I38: =IF(ROUND(F38,0)=0,0,IF(D38=0,0,+F38/D38)) -> #VALUE! | K38: 2000 | L38: =IF(A38="Acumulado",IF(M38>K38,K38,M38),IF(A38="BN",+(K38/$K$8*$L$8),"VER")) -> #VALUE! | M38: =SUMIF([1]Resumen_Base!$A$94:$A$160,'[1]Budget Comparativo'!B38,[1]Resumen_Base!$Y$94:$Y$160) -> #VALUE! | N38: =+L38-M38 -> #VALUE! | P38: =IF(ROUND(M38,0)=0,0,IF(K38=0,0,+M38/K38)) -> #VALUE! | R38: =+D38+K38 -> 16400 | S38: =+E38+L38 -> #VALUE! | T38: =+F38+M38 -> #VALUE! | U38: =+S38-T38 -> #VALUE! | W38: =IF(ROUND(T38,0)=0,0,IF(R38=0,0,+T38/R38)) -> #VALUE! | Y38: =+'[1]Budget Comparativo'!D38/'[1]Budget Comparativo'!$Y$8 -> 12 | Z38: =+'[1]Budget Comparativo'!F38/'[1]Budget Comparativo'!$Z$8 -> 15.327865 | AA38: =+Y38-Z38 -> -3.327865 | AF38: =+'[1]Budget Comparativo'!K38/'[1]Budget Comparativo'!$AF$8 -> 12.5 | AG38: =+'[1]Budget Comparativo'!M38/'[1]Budget Comparativo'!$AG$8 -> 7.6859751 | AH38: =+AF38-AG38 -> 4.8140249 | AJ38: 5210 | AK38: 5225
A39: Acumulado | B39: Travel for personnel (employees) | D39: 4000 | E39: =IF(A39="Acumulado",IF(F39>D39,D39,F39),IF(A39="BN",+(D39/$D$8*$E$8),"VER")) -> #VALUE! | F39: =+SUMIF([1]Resumen_Base!$A$7:$A$91,'[1]Budget Comparativo'!B39,[1]Resumen_Base!$Y$7:$Y$91) -> #VALUE! | G39: =+E39-F39 -> #VALUE! | I39: =IF(ROUND(F39,0)=0,0,IF(D39=0,0,+F39/D39)) -> #VALUE! | K39: 1000 | L39: =IF(A39="Acumulado",IF(M39>K39,K39,M39),IF(A39="BN",+(K39/$K$8*$L$8),"VER")) -> #VALUE! | M39: =SUMIF([1]Resumen_Base!$A$94:$A$160,'[1]Budget Comparativo'!B39,[1]Resumen_Base!$Y$94:$Y$160) -> #VALUE! | N39: =+L39-M39 -> #VALUE! | P39: =IF(ROUND(M39,0)=0,0,IF(K39=0,0,+M39/K39)) -> #VALUE! | R39: =+D39+K39 -> 5000 | S39: =+E39+L39 -> #VALUE! | T39: =+F39+M39 -> #VALUE! | U39: =+S39-T39 -> #VALUE! | W39: =IF(ROUND(T39,0)=0,0,IF(R39=0,0,+T39/R39)) -> #VALUE! | Y39: =+'[1]Budget Comparativo'!D39/'[1]Budget Comparativo'!$Y$8 -> 3.3333333 | Z39: =+'[1]Budget Comparativo'!F39/'[1]Budget Comparativo'!$Z$8 -> 1.5174209 | AA39: =+Y39-Z39 -> 1.8159124 | AF39: =+'[1]Budget Comparativo'!K39/'[1]Budget Comparativo'!$AF$8 -> 6.25 | AG39: =+'[1]Budget Comparativo'!M39/'[1]Budget Comparativo'!$AG$8 -> 11.081152 | AH39: =+AF39-AG39 -> -4.8311523 | AJ39: 5255 | AK39: 5310 | AL39: 5222 | AM39: 5256
A40: Acumulado | B40: Work uniforms for personnel (employees) | D40: 12000 | E40: =IF(A40="Acumulado",IF(F40>D40,D40,F40),IF(A40="BN",+(D40/$D$8*$E$8),"VER")) -> #VALUE! | F40: =+SUMIF([1]Resumen_Base!$A$7:$A$91,'[1]Budget Comparativo'!B40,[1]Resumen_Base!$Y$7:$Y$91) -> #VALUE! | G40: =+E40-F40 -> #VALUE! | I40: =IF(ROUND(F40,0)=0,0,IF(D40=0,0,+F40/D40)) -> #VALUE! | K40: 1000 | L40: =IF(A40="Acumulado",IF(M40>K40,K40,M40),IF(A40="BN",+(K40/$K$8*$L$8),"VER")) -> #VALUE! | M40: =SUMIF([1]Resumen_Base!$A$94:$A$160,'[1]Budget Comparativo'!B40,[1]Resumen_Base!$Y$94:$Y$160) -> #VALUE! | N40: =+L40-M40 -> #VALUE! | P40: =IF(ROUND(M40,0)=0,0,IF(K40=0,0,+M40/K40)) -> #VALUE! | R40: =+D40+K40 -> 13000 | S40: =+E40+L40 -> #VALUE! | T40: =+F40+M40 -> #VALUE! | U40: =+S40-T40 -> #VALUE! | W40: =IF(ROUND(T40,0)=0,0,IF(R40=0,0,+T40/R40)) -> #VALUE! | Y40: =+'[1]Budget Comparativo'!D40/'[1]Budget Comparativo'!$Y$8 -> 10 | Z40: =+'[1]Budget Comparativo'!F40/'[1]Budget Comparativo'!$Z$8 -> 4.3455411 | AA40: =+Y40-Z40 -> 5.6544589 | AF40: =+'[1]Budget Comparativo'!K40/'[1]Budget Comparativo'!$AF$8 -> 6.25 | AG40: =+'[1]Budget Comparativo'!M40/'[1]Budget Comparativo'!$AG$8 -> 3.4915708 | AH40: =+AF40-AG40 -> 2.7584292 | AJ40: 5220
A41: Acumulado | B41: Licenses / Permits (Fishing and Shooting) | D41: 1200 | E41: =IF(A41="Acumulado",IF(F41>D41,D41,F41),IF(A41="BN",+(D41/$D$8*$E$8),"VER")) -> #VALUE! | F41: =+SUMIF([1]Resumen_Base!$A$7:$A$91,'[1]Budget Comparativo'!B41,[1]Resumen_Base!$Y$7:$Y$91) -> #VALUE! | G41: =+E41-F41 -> #VALUE! | I41: =IF(ROUND(F41,0)=0,0,IF(D41=0,0,+F41/D41)) -> #VALUE! | K41: 1000 | L41: =IF(A41="Acumulado",IF(M41>K41,K41,M41),IF(A41="BN",+(K41/$K$8*$L$8),"VER")) -> #VALUE! | M41: =SUMIF([1]Resumen_Base!$A$94:$A$160,'[1]Budget Comparativo'!B41,[1]Resumen_Base!$Y$94:$Y$160) -> #VALUE! | N41: =+L41-M41 -> #VALUE! | P41: =IF(ROUND(M41,0)=0,0,IF(K41=0,0,+M41/K41)) -> #VALUE! | R41: =+D41+K41 -> 2200 | S41: =+E41+L41 -> #VALUE! | T41: =+F41+M41 -> #VALUE! | U41: =+S41-T41 -> #VALUE! | W41: =IF(ROUND(T41,0)=0,0,IF(R41=0,0,+T41/R41)) -> #VALUE! | Y41: =+'[1]Budget Comparativo'!D41/'[1]Budget Comparativo'!$Y$8 -> 1 | Z41: =+'[1]Budget Comparativo'!F41/'[1]Budget Comparativo'!$Z$8 -> 1.8060448 | AA41: =+Y41-Z41 -> -0.80604481 | AF41: =+'[1]Budget Comparativo'!K41/'[1]Budget Comparativo'!$AF$8 -> 6.25 | AG41: =+'[1]Budget Comparativo'!M41/'[1]Budget Comparativo'!$AG$8 -> 0.269324 | AH41: =+AF41-AG41 -> 5.980676 | AJ41: 5221 | AK41: 5261
B42: Maintenance (Lodge / Boats / Vehicles / Equipment) | D42: =+SUM(D43:D45) -> 20000 | E42: =+SUM(E43:E45) -> #VALUE! | F42: =+SUM(F43:F45) -> #VALUE! | G42: =+SUM(G43:G45) -> #VALUE! | K42: =+SUM(K43:K45) -> 9000 | L42: =+SUM(L43:L45) -> #VALUE! | M42: =+SUM(M43:M45) -> #VALUE! | N42: =+SUM(N43:N45) -> #VALUE! | R42: =+SUM(R43:R45) -> 29000 | S42: =+SUM(S43:S45) -> #VALUE! | T42: =+SUM(T43:T45) -> #VALUE! | U42: =+SUM(U43:U45) -> #VALUE! | Y42: =+'[1]Budget Comparativo'!D42/'[1]Budget Comparativo'!$Y$8 -> 16.666667 | Z42: =+'[1]Budget Comparativo'!F42/'[1]Budget Comparativo'!$Z$8 -> 22.401642 | AA42: =+Y42-Z42 -> -5.734975 | AF42: =+'[1]Budget Comparativo'!K42/'[1]Budget Comparativo'!$AF$8 -> 56.25 | AG42: =+'[1]Budget Comparativo'!M42/'[1]Budget Comparativo'!$AG$8 -> 40.473683 | AH42: =+AF42-AG42 -> 15.776317
A43: Acumulado | B43: Maintenance Lodge | D43: 7000 | E43: =IF(A43="Acumulado",IF(F43>D43,D43,F43),IF(A43="BN",+(D43/$D$8*$E$8),"VER")) -> #VALUE! | F43: =+SUMIF([1]Resumen_Base!$A$7:$A$91,'[1]Budget Comparativo'!B43,[1]Resumen_Base!$Y$7:$Y$91) -> #VALUE! | G43: =+E43-F43 -> #VALUE! | H43: 0,7k Service Generador + 0,4k Arreglos Aires + 0,3k Arreglo Camas, 0,3k Plomería + 0,5k Amenities + 0,3k Cintas + 0,7k Ferretería e Insumos Pileta + 0,7k Desagote Pozos Ciegos + 0,4k Velones velas, etc + 1,4k Mucho Chiquitaje | I43: =IF(ROUND(F43,0)=0,0,+F43/D43) -> #VALUE! | K43: 4000 | L43: =IF(A43="Acumulado",IF(M43>K43,K43,M43),IF(A43="BN",+(K43/$K$8*$L$8),"VER")) -> #VALUE! | M43: =SUMIF([1]Resumen_Base!$A$94:$A$160,'[1]Budget Comparativo'!B43,[1]Resumen_Base!$Y$94:$Y$160) -> #VALUE! | N43: =+L43-M43 -> #VALUE! | P43: =IF(ROUND(M43,0)=0,0,+M43/K43) -> #VALUE! | Q43: =0.7+0.4+0.3+0.3+0.5+0.3+0.4+0.7+0.7+0.4+(1.4) -> 6.1 | R43: =+D43+K43 -> 11000 | S43: =+E43+L43 -> #VALUE! | T43: =+F43+M43 -> #VALUE! | U43: =+S43-T43 -> #VALUE! | W43: =IF(ROUND(T43,0)=0,0,+T43/R43) -> #VALUE! | Y43: =+'[1]Budget Comparativo'!D43/'[1]Budget Comparativo'!$Y$8 -> 5.8333333 | Z43: =+'[1]Budget Comparativo'!F43/'[1]Budget Comparativo'!$Z$8 -> 7.2552707 | AA43: =+Y43-Z43 -> -1.4219374 | AF43: =+'[1]Budget Comparativo'!K43/'[1]Budget Comparativo'!$AF$8 -> 25 | AG43: =+'[1]Budget Comparativo'!M43/'[1]Budget Comparativo'!$AG$8 -> 23.76704 | AH43: =+AF43-AG43 -> 1.2329604 | AJ43: 5252
A44: Acumulado | B44: Maintenance Boats / Vehicles | D44: 8000 | E44: =IF(A44="Acumulado",IF(F44>D44,D44,F44),IF(A44="BN",+(D44/$D$8*$E$8),"VER")) -> #VALUE! | F44: =+SUMIF([1]Resumen_Base!$A$7:$A$91,'[1]Budget Comparativo'!B44,[1]Resumen_Base!$Y$7:$Y$91) -> #VALUE! | G44: =+E44-F44 -> #VALUE! | H44: 2,1k Cubiertas Camionetas + 3,8k Services y Bateria, etc + 0,8k Chapista Toyota + 0,9k Frenos y Repuestos Vs | I44: =IF(ROUND(F44,0)=0,0,IF(D44=0,0,+F44/D44)) -> #VALUE! | K44: 3000 | L44: =IF(A44="Acumulado",IF(M44>K44,K44,M44),IF(A44="BN",+(K44/$K$8*$L$8),"VER")) -> #VALUE! | M44: =SUMIF([1]Resumen_Base!$A$94:$A$160,'[1]Budget Comparativo'!B44,[1]Resumen_Base!$Y$94:$Y$160) -> #VALUE! | N44: =+L44-M44 -> #VALUE! | P44: =IF(ROUND(M44,0)=0,0,IF(K44=0,0,+M44/K44)) -> #VALUE! | Q44: =2.1+3.8+0.8+0.9 -> 7.6 | R44: =+D44+K44 -> 11000 | S44: =+E44+L44 -> #VALUE! | T44: =+F44+M44 -> #VALUE! | U44: =+S44-T44 -> #VALUE! | W44: =IF(ROUND(T44,0)=0,0,IF(R44=0,0,+T44/R44)) -> #VALUE! | Y44: =+'[1]Budget Comparativo'!D44/'[1]Budget Comparativo'!$Y$8 -> 6.6666667 | Z44: =+'[1]Budget Comparativo'!F44/'[1]Budget Comparativo'!$Z$8 -> 8.9517821 | AA44: =+Y44-Z44 -> -2.2851154 | AF44: =+'[1]Budget Comparativo'!K44/'[1]Budget Comparativo'!$AF$8 -> 18.75 | AG44: =+'[1]Budget Comparativo'!M44/'[1]Budget Comparativo'!$AG$8 -> 15.404489 | AH44: =+AF44-AG44 -> 3.345511 | AJ44: 5253
A45: Acumulado | B45: Maintenance Equipment | D45: 5000 | E45: =IF(A45="Acumulado",IF(F45>D45,D45,F45),IF(A45="BN",+(D45/$D$8*$E$8),"VER")) -> #VALUE! | F45: =+SUMIF([1]Resumen_Base!$A$7:$A$91,'[1]Budget Comparativo'!B45,[1]Resumen_Base!$Y$7:$Y$91) -> #VALUE! | G45: =+E45-F45 -> #VALUE! | H45: Repuestos Escopetas y Armeros limpieza armas, cajas,etc | I45: =IF(ROUND(F45,0)=0,0,IF(D45=0,0,+F45/D45)) -> #VALUE! | K45: 2000 | L45: =IF(A45="Acumulado",IF(M45>K45,K45,M45),IF(A45="BN",+(K45/$K$8*$L$8),"VER")) -> #VALUE! | M45: =SUMIF([1]Resumen_Base!$A$94:$A$160,'[1]Budget Comparativo'!B45,[1]Resumen_Base!$Y$94:$Y$160) -> #VALUE! | N45: =+L45-M45 -> #VALUE! | P45: =IF(ROUND(M45,0)=0,0,IF(K45=0,0,+M45/K45)) -> #VALUE! | R45: =+D45+K45 -> 7000 | S45: =+E45+L45 -> #VALUE! | T45: =+F45+M45 -> #VALUE! | U45: =+S45-T45 -> #VALUE! | W45: =IF(ROUND(T45,0)=0,0,IF(R45=0,0,+T45/R45)) -> #VALUE! | Y45: =+'[1]Budget Comparativo'!D45/'[1]Budget Comparativo'!$Y$8 -> 4.1666667 | Z45: =+'[1]Budget Comparativo'!F45/'[1]Budget Comparativo'!$Z$8 -> 6.1945889 | AA45: =+Y45-Z45 -> -2.0279222 | AF45: =+'[1]Budget Comparativo'!K45/'[1]Budget Comparativo'!$AF$8 -> 12.5 | AG45: =+'[1]Budget Comparativo'!M45/'[1]Budget Comparativo'!$AG$8 -> 1.3021548 | AH45: =+AF45-AG45 -> 11.197845 | AJ45: 5254
A46: Acumulado | B46: Communications - Phone, internet and satellite TV | D46: 1000 | E46: =IF(A46="Acumulado",IF(F46>D46,D46,F46),IF(A46="BN",+(D46/$D$8*$E$8),"VER")) -> #VALUE! | F46: =+SUMIF([1]Resumen_Base!$A$7:$A$91,'[1]Budget Comparativo'!B46,[1]Resumen_Base!$Y$7:$Y$91) -> #VALUE! | G46: =+E46-F46 -> #VALUE! | I46: =IF(ROUND(F46,0)=0,0,+F46/D46) -> #VALUE! | K46: 0 | L46: =IF(A46="Acumulado",IF(M46>K46,K46,M46),IF(A46="BN",+(K46/$K$8*$L$8),"VER")) -> #VALUE! | M46: =SUMIF([1]Resumen_Base!$A$94:$A$160,'[1]Budget Comparativo'!B46,[1]Resumen_Base!$Y$94:$Y$160) -> #VALUE! | N46: =+L46-M46 -> #VALUE! | P46: =IF(ROUND(M46,0)=0,0,+M46/K46) -> #VALUE! | R46: =+D46+K46 -> 1000 | S46: =+E46+L46 -> #VALUE! | T46: =+F46+M46 -> #VALUE! | U46: =+S46-T46 -> #VALUE! | W46: =IF(ROUND(T46,0)=0,0,+T46/R46) -> #VALUE! | Y46: =+'[1]Budget Comparativo'!D46/'[1]Budget Comparativo'!$Y$8 -> 0.83333333 | Z46: =+'[1]Budget Comparativo'!F46/'[1]Budget Comparativo'!$Z$8 -> 0.68870348 | AA46: =+Y46-Z46 -> 0.14462986 | AF46: =+'[1]Budget Comparativo'!K46/'[1]Budget Comparativo'!$AF$8 -> 0 | AG46: =+'[1]Budget Comparativo'!M46/'[1]Budget Comparativo'!$AG$8 -> 1.7813651 | AH46: =+AF46-AG46 -> -1.7813651 | AJ46: 5209 | AK46: 5266 | AL46: 5324 | AM46: 5325 | AN46: 5326
...

Sheet Budget 2026
D4: Budget El Tobar Camp
D5: Temporada 2025-26
B10: Total Gastos Operativos | G10: =VLOOKUP($B10,INDIRECT(#REF!),#REF!,FALSE) -> #REF! | I10: =VLOOKUP($B10,INDIRECT(#REF!),#REF!,FALSE) -> #REF!
B11: Total | G11: =VLOOKUP($B11,INDIRECT(#REF!),#REF!,FALSE) -> #REF! | I11: =VLOOKUP($B11,INDIRECT(#REF!),#REF!,FALSE) -> #REF!
A12: Observaciones | D12: En Dolares x temporada | G12: En Dolares x bednight | J12: Observaciones
D13: Budget 25-26 | E13: Real 24-25 | F13: Real 23-24 | G13: Budget 24-25 | H13: Real 25-25 | I13: Real 23-24
B14: Parametros
B15: BN | D15: 260 | E15: 154 | F15: 79
B16: Pax | D16: =D15/1.5 -> 173.33333 | E16: 98 | F16: 55
B17: Fecha Inicio | D17: 46162 | E17: 45797 | F17: 45432
B18: Fecha Cierre | D18: 46275 | E18: 45910 | F18: 45545
B19: Dias | D19: =D18-D17 -> 113 | E19: =E18-E17 -> 113 | F19: =F18-F17 -> 113
B21: Otros Ingresos | D21: =SUM(D22:D29) -> 37242.4 | E21: =SUM(E22:E29) -> 21668.97 | F21: =SUM(F22:F29) -> 13635.866 | G21: =D21/$D$15 -> 143.24 | H21: =E21/$E$15 -> 140.7076 | I21: =F21/$F$15 -> 172.60589
B22: Shop | D22: =9*D15 -> 2340 | E22: 935 | F22: 220 | G22: =D22/$D$15 -> 9 | H22: =E22/$E$15 -> 6.0714286 | I22: =F22/$F$15 -> 2.7848101
B23: (CMV) Shop | D23: =D22*-0.6 -> -1404 | E23: -527.28 | F23: =F22*-0.6 -> -132 | G23: =D23/$D$15 -> -5.4 | H23: =E23/$E$15 -> -3.4238961 | I23: =F23/$F$15 -> -1.6708861
B24: (Comisiones Ventas Shop) | D24: =(D22+D23)*-0.1 -> -93.6 | E24: 0 | F24: =(F22+F23)*-0.1 -> -8.8 | G24: =D24/$D$15 -> -0.36 | H24: =E24/$E$15 -> 0 | I24: =F24/$F$15 -> -0.11139241
B25: Extras (NET) | D25: 0 | E25: 0 | F25: 60 | G25: =D25/$D$15 -> 0 | H25: =E25/$E$15 -> 0 | I25: =F25/$F$15 -> 0.75949367
B26: Ingresos por tips | D26: 0 | E26: 0 | F26: 0 | G26: =D26/$D$15 -> 0 | H26: =E26/$E$15 -> 0 | I26: =F26/$F$15 -> 0
B27: Gun Rental (NET) | D27: =80*D15 -> 20800 | E27: 12090 | F27: 8370 | G27: =D27/$D$15 -> 80 | H27: =E27/$E$15 -> 78.506494 | I27: =F27/$F$15 -> 105.94937
B28: Shells | D28: =5*26*D15 -> 33800 | E28: 18698 | F28: =4.95*24.34*F15 -> 9518.157 | G28: =D28/$D$15 -> 130 | H28: =E28/$E$15 -> 121.41558 | I28: =F28/$E$15 -> 61.806214
B29: Costo Shells | D29: =-14*D15*5 -> -18200 | E29: -9526.75 | F29: =-11.23*F15*4.95 -> -4391.4915 | G29: =D29/$D$15 -> -70 | H29: =E29/$E$15 -> -61.862013 | I29: =F29/$E$15 -> -28.516179
G30: =D30/$D$15 -> 0 | H30: =E30/$E$15 -> 0 | I30: =F30/$F$15 -> 0
B31: Gastos Operativos | D31: =SUM(D32:D58)-D51-D43-D40-D33 -> 113550.85 | E31: =SUM(E32:E58)-E51-E43-E40-E33 -> 107227.63 | F31: =SUM(F32:F58)-F51-F43-F40-F33 -> 41720.639 | G31: =D31/$D$15 -> 436.73404 | H31: =E31/$E$15 -> 696.28328 | I31: =F31/$F$15 -> 528.10935
B32: Canon Lodge | D32: 0 | E32: 0 | F32: 0 | G32: =D32/$D$15 -> 0 | H32: =E32/$E$15 -> 0 | I32: =F32/$F$15 -> 0
B33: Sueldos | D33: =SUBTOTAL(9,D34:D38) -> 48715.517 | E33: 47607.82 | F33: =SUM(F35:F38) -> 25452.45 | G33: =D33/$D$15 -> 187.36737 | H33: =E33/$E$15 -> 309.14169 | I33: =F33/$F$15 -> 322.18291
B34: Tips | D34: 0 | E34: 8758.96 | G34: =D34/$D$15 -> 0 | H34: =E34/$E$15 -> 56.876364 | I34: =F34/$F$15 -> 0
B35: Managers | D35: =Sueldos!G20 -> 8158.6207 | E35: 8759 | F35: 6900 | G35: =D35/$D$15 -> 31.37931 | H35: =E36/$E$15 -> 126.78571 | I35: =F35/$F$15 -> 87.341772
B36: Guias | D36: =Sueldos!F15 -> 14544.828 | E36: 19525 | F36: 4000 | G36: =D36/$D$15 -> 55.941645 | H36: =E37/$E$15 -> 101.85656 | I36: =F36/$F$15 -> 50.632911
B37: Servicio | D37: =Sueldos!G33 -> 19881.034 | E37: 15685.91 | F37: 12600 | G37: =D37/$D$15 -> 76.465517 | H37: =E38/$E$15 -> 23.623377 | I37: =F37/$F$15 -> 159.49367
B38: Cargas Sociales | D38: =Sueldos!B41 -> 6131.0345 | E38: 3638 | F38: 1952.45 | G38: =D38/$D$15 -> 23.580902 | H38: =E38/$E$15 -> 23.623377 | I38: =F38/$F$15 -> 24.714557
B39: Comida / Vinos | D39: =85*D15 -> 22100 | E39: 13937.67 | F39: 6871 | G39: =D39/$D$15 -> 85 | H39: =E39/$E$15 -> 90.504351 | I39: =F39/$F$15 -> 86.974684
B40: Costo de la caceria | D40: =SUBTOTAL(9,D41:D42) -> 4500 | E40: =E42+E41 -> 3101.64 | F40: =F42+F41 -> 40 | G40: =D40/$D$15 -> 17.307692 | H40: =E40/$E$15 -> 20.140519 | I40: =F40/$F$15 -> 0.50632911
B41: Canon Campos | D41: 0 | E41: 0 | F41: 0 | G41: =D41/$D$15 -> 0 | H41: =E41/$E$15 -> 0 | I41: =F41/$F$15 -> 0
B42: Maíz y Cebada | D42: 4500 | E42: 3101.64 | F42: 40 | G42: =D42/$D$15 -> 17.307692 | H42: =E42/$E$15 -> 20.140519 | I42: =F42/$F$15 -> 0.50632911
B43: Combustible | D43: =SUBTOTAL(9,D44:D46) -> 10900 | E43: 8904.99 | F43: 2976.2884 | G43: =D43/$D$15 -> 41.923077 | H43: =E43/$E$15 -> 57.82461 | I43: =F43/$F$15 -> 37.674536
A44: Esto lo revise con Maria, con cambio de Baterias deberiamos ser mas eficientes, dejo mismo nro año pasado y mejora el nro por BN. | B44: Electricidad | D44: 4500 | E44: 4473.83 | F44: 1177.5312 | G44: =D44/$D$15 -> 17.307692 | H44: =E44/$E$15 -> 29.050844 | I44: =F44/$F$15 -> 14.905458
A45: Pendiente Martin envio planilla combustible para calculo diario | B45: Vehiculos/Botes | D45: =20*D15 -> 5200 | E45: 3276.53 | F45: 1257.3692 | G45: =D45/$D$15 -> 20 | H45: =E45/$E$15 -> 21.276169 | I45: =F45/$F$15 -> 15.916065
B46: Gas | D46: 1200 | E46: 1154.63 | F46: 541.38805 | G46: =D46/$D$15 -> 4.6153846 | H46: =E46/$E$15 -> 7.4975974 | I46: =F46/$F$15 -> 6.8530133
B47: Traslado Aerop/Lodge/Alq Vehiculos | D47: 0 | E47: 400 | F47: 607.19203 | G47: =D47/$D$15 -> 0 | H47: =E47/$E$15 -> 2.5974026 | I47: =F47/$F$15 -> 7.6859751
B48: Viaticos y Movilidad Personal | D48: 2500 | E48: 2336.14 | F48: 875.41103 | G48: =D48/$D$15 -> 9.6153846 | H48: =E48/$E$15 -> 15.16974 | I48: =F48/$F$15 -> 11.081152
...

Sheet Sueldos
B1: TC | C1: 1450
A3: Calculo recupero Tips
A4: BN | B4: ='Budget 2026'!D15 -> 260
A5: Estimado tips x BN | B5: 75
A6: Total tips estimados | B6: =B5*B4 -> 19500
A7: Recupero 70% tips servicio | B7: =B6*0.7 -> 13650
A9: Guias | B9: Sueldo Nomina | C9: Costo Sueldo Nomina | D9: Sueldo extra | E9: Meses | F9: Total
A10: Guia 1 | B10: =500000/C1 -> 344.82759 | C10: =B10*0.25 -> 86.206897 | D10: =1100-B10 -> 755.17241 | E10: 4 | F10: =(B10+C10+D10)*E10 -> 4744.8276
A11: Cebador 1 | B11: 0 | C11: 0 | D11: 500 | E11: 5 | F11: =E11*D11 -> 2500
A12: Cebador 2 | B12: 0 | C12: 0 | D12: 500 | E12: 5 | F12: =E12*D12 -> 2500
A13: Scouting | F13: 2000 | G13: Total temporada
A14: Julian Logistica | F14: 2800 | G14: Total temporada
A15: Total guías | F15: =SUM(F10:F14) -> 14544.828
A18: Manager
A19: Guias | B19: Sueldo Nomina | C19: Costo Sueldo Nomina | D19: Sueldo extra | E19: Meses | F19: Bono | G19: Total
A20: Manager | B20: =1100000/C1 -> 758.62069 | C20: =B20*0.25 -> 189.65517 | D20: =1600-B20 -> 841.37931 | E20: 4 | F20: 1000 | G20: =(B20+C20+D20)*E20+F20 -> 8158.6207
A24: Servicio | B24: Sueldo Nomina | C24: Costo Sueldo Nomina | D24: Sueldo extra | E24: Meses | F24: Bono | G24: Total
A25: Mucama 1 | B25: =500000/C1 -> 344.82759 | C25: =B25*0.25 -> 86.206897 | D25: =(1100000/C1)-B25 -> 413.7931 | E25: 4 | F25: 700 | G25: =(B25+C25+D25)*E25+F25 -> 4079.3103
A26: Mucama 2 | B26: =500000/C1 -> 344.82759 | C26: =B26*0.25 -> 86.206897 | D26: =(1100000/C1)-B26 -> 413.7931 | E26: 4 | F26: 700 | G26: =(B26+C26+D26)*E26+F26 -> 4079.3103
A27: Mucama 3 y cocinera Staff | B27: =500000/C1 -> 344.82759 | C27: =B27*0.25 -> 86.206897 | D27: =(800000/C1)-B27 -> 206.89655 | E27: 4 | F27: 200 | G27: =(B27+C27+D27)*E27+F27 -> 2751.7241
A28: Lavandera | B28: 0 | C28: 0 | D28: =550000/C1 -> 379.31034 | E28: 4 | F28: 300 | G28: =D28*E28+F28 -> 1817.2414
A29: Cocinero | B29: =500000/C1 -> 344.82759 | C29: =B29*0.25 -> 86.206897 | D29: 1500 | E29: 4 | F29: 500 | G29: =(B29+C29+D29)*E29+F29 -> 8224.1379
A30: Mantenimiento 1 | B30: =500000/C1 -> 344.82759 | C30: =B30*0.25 -> 86.206897 | D30: =(900000/C1)-B30 -> 275.86207 | E30: 5 | F30: 700 | G30: =(B30+C30+D30)*E30+F30 -> 4234.4828
A31: Mantenimiento 2 | B31: =500000/C1 -> 344.82759 | C31: =B31*0.25 -> 86.206897 | D31: =(750000/C1)-B31 -> 172.41379 | E31: 13 | F31: 500 | G31: =(B31+C31+D31)*E31+F31 -> 8344.8276
A32: Menos Recupero de tips | G32: =-B7 -> -13650
A33: Total costo servicio | G33: =SUM(G32:G32)+SUM(G25:G31) -> 19881.034
A36: Cargas Sociales
A37: Total Sueldo Nomina Guias | B37: =B10*E10 -> 1379.3103
A38: Total Sueldos nomina Manager | B38: =B20*E20 -> 3034.4828
A39: Total Sueldo nomina Servicio | B39: =SUM(B25*38) -> 13103.448
A40: Total | B40: =SUM(B37:B39) -> 17517.241
A41: Cargas 35% | B41: =B40*0.35 -> 6131.0345
