Workbook
Name _Rt12: #REF!
Name AJUSTES: #REF!
Name Assumptions: #REF!
Name BN_CY: #REF!
Name BN_LY: #REF!
Name BN_PY: #REF!
Name BuiltIn_Print_Area: #REF!
Name BuiltIn_Print_Area___0: #REF!
Name BuiltIn_Print_Titles: #REF!
Name BuiltIn_Print_Titles___0: #REF!
Name CASH_FLOW: #REF!
Name Costo: #REF!
Name DAYS_CY: #REF!
Name Depreciation_Investment: #REF!
Name EVOLUCION___0: #N/A
Name FC_CY: #REF!
Name FC_LY: #REF!
Name FC_PY: #REF!
Name FI_CY: #REF!
Name FI_LY: #REF!
Name FI_PY: #REF!
Name IBrutos: #REF!
Name INCOME_STATEMENT: #REF!
Name Intang: #REF!
Name LCR_Real: #REF!
Name Macro1: #N/A
Name Monext: #REF!
Name PAX_CY: #REF!
Name PAX_LY: #REF!
Name PAX_PY: #REF!
Name PERSONNEL: #REF!
Name Real22: #REF!
Name Real23: #REF!
Name RealVM23: #REF!
Name Revenues_Expenses: #REF!
Name Total_Sales__quantity: #REF!
Name Uniona: #REF!

Sheet Budget 2025-26
F4: Budget Jacana Lodge
F5: Temporada 2025-26
E10: En Dolares x temporada | H10: En Dolares x bednight | K10: Observaciones
E11: Budget 25-26 | F11: Real 24-25 | G11: Real 23-24 | H11: Budget 25-26 | I11: Real 24-25 | J11: Real 23-24
B12: Parametros
B13: BN | E13: 425 | F13: 437 | G13: 367
B14: Pax | E14: 106 | F14: 124 | G14: 92
B15: Fecha Inicio | E15: 46127 | F15: 45762 | G15: 45397
B16: Fecha Cierre | F16: =FC_CY -> #REF! | G16: =FC_LY -> #REF! | I16: 44788
B17: Dias | F17: =F16-F15 -> #REF! | G17: =G16-G15 -> #REF! | I17: 122
B19: Fecha Finalizacion | E19: 46244 | F19: 45879 | G19: 45514
B20: Total días | E20: =E19-E15 -> 117 | F20: =F19-F15 -> 117 | G20: =G19-G15 -> 117
B21: Otros Ingresos | E21: =SUM(E22:E29) -> 155142 | F21: =SUM(F22:F27) -> 132389 | G21: =SUM(G22:G27) -> 103183 | H21: =E21/$E$13 -> 365.04 | I21: =F21/$F$13 -> 302.94966 | J21: =G21/$G$13 -> 281.15259
B22: Shop | E22: =14*E13 -> 5950 | F22: 6136 | G22: 4386 | H22: =E22/$E$13 -> 14 | I22: =F22/$F$13 -> 14.04119 | J22: =G22/$G$13 -> 11.950954
B23: (CMV) Shop | E23: =E22*-0.6 -> -3570 | F23: -3471 | G23: -2895 | H23: =E23/$E$13 -> -8.4 | I23: =F23/$F$13 -> -7.9427918 | J23: =G23/$G$13 -> -7.8882834
B24: (Comisiones Ventas Shop) | E24: =(E22+E23)*-0.1 -> -238 | F24: 0 | G24: 0 | H24: =E24/$E$13 -> -0.56 | I24: =F24/$F$13 -> 0 | J24: =G24/$G$13 -> 0
B25: Extras | E25: =5*E13 -> 2125 | F25: 1977 | G25: 2257 | H25: =E25/$E$13 -> 5 | I25: =F25/$F$13 -> 4.5240275 | J25: =G25/$G$13 -> 6.1498638
B26: Tips | E26: =180*E13 -> 76500 | F26: 80277 | G26: 64560 | H26: =E26/$E$13 -> 180 | I26: =F26/$F$13 -> 183.70023 | J26: =G26/$G$13 -> 175.91281
B27: Gun Rental | E27: =109*E13 -> 46325 | F27: 47470 | G27: 34875 | H27: =E27/$E$13 -> 109 | I27: =F27/$F$13 -> 108.627 | J27: =G27/$G$13 -> 95.027248
B28: Shells | E28: =6*26.5*E13 -> 67575 | F28: 63674 | G28: 49245 | H28: =E28/$E$13 -> 159 | I28: =F28/$F$13 -> 145.70709 | J28: =G28/$G$13 -> 134.18256 | K28: 6 caja x BN a $26,50
B29: Costo Shells | E29: =-6*E13*15.5 -> -39525 | F29: -37592 | G29: -31038 | H29: =E29/$E$13 -> -93 | I29: =F29/$F$13 -> -86.022883 | J29: =G29/$G$13 -> -84.572207 | K29: 6 caja x BN a $15,50 | M29: REVISAR PRECIO DE VENTA CON FDC
H30: =E30/$E$13 -> 0
B31: Gastos Operativos | E31: =SUM(E32:E57)-E50-E42-E39-E33 -> 294112.24 | F31: =SUM(F32:F57)-F50-F42-F39-F33 -> 305070 | G31: =SUM(G32:G57)-G50-G42-G39-G33 -> 251639.61 | H31: =E31/$E$13 -> 692.0288 | I31: =F31/$F$13 -> 698.10069 | J31: =G31/$G$13 -> 685.66651
B32: Canon | E32: 29500 | F32: 29500 | G32: 29511 | H32: =E32/$E$13 -> 69.411765 | I32: =F32/$F$13 -> 67.505721 | J32: =G32/$G$13 -> 80.411444
B33: Sueldos | E33: =SUM(E34:E37) -> 130287.24 | F33: =SUM(F34:F37) -> 134946 | G33: =SUM(G34:G37) -> 109151 | H33: =E33/$E$13 -> 306.55822 | I33: =F33/$F$13 -> 308.80092 | J33: =G33/$G$13 -> 297.41417
B34: Manager | E34: =Sueldos!G26 -> 15263.793 | F34: 15298 | G34: 13582 | H34: =E34/$E$13 -> 35.914807 | I34: =F34/$F$13 -> 35.006865 | J34: =G34/$G$13 -> 37.008174
B35: Guías | E35: =Sueldos!F19 -> 62121.724 | F35: 59687 | G35: 47592 | H35: =E35/$E$13 -> 146.16876 | I35: =F35/$F$13 -> 136.58352 | J35: =G35/$G$13 -> 129.67847
B36: Servicio | E36: =Sueldos!G35 -> 39901.724 | F36: 47677 | G36: 40345 | H36: =E36/$E$13 -> 93.88641 | I36: =F36/$F$13 -> 109.10069 | J36: =G36/$G$13 -> 109.93188
B37: Cargas Sociales | E37: 13000 | F37: 12284 | G37: 7632 | H37: =E37/$E$13 -> 30.588235 | I37: =F37/$F$13 -> 28.10984 | J37: =G37/$G$13 -> 20.79564
B38: Comida | E38: =85*E13 -> 36125 | F38: 41244 | G38: 24603 | H38: =E38/$E$13 -> 85 | I38: =F38/$F$13 -> 94.379863 | J38: =G38/$G$13 -> 67.038147
B39: Costo de la caceria | E39: =SUM(E40:E41) -> 36600 | F39: =SUM(F40:F41) -> 38211 | G39: =SUM(G40:G41) -> 33256.641 | H39: =E39/$E$13 -> 86.117647 | I39: =F39/$F$13 -> 87.439359 | J39: =G39/$G$13 -> 90.61755
B40: campos | E40: =72*E13 -> 30600 | F40: 31880 | G40: 27040 | H40: =E40/$E$13 -> 72 | I40: =F40/$F$13 -> 72.951945 | J40: =G40/$G$13 -> 73.678474
B41: Baiting | E41: 6000 | F41: 6331 | G41: 6216.6407 | H41: =E41/$E$13 -> 14.117647 | I41: =F41/$F$13 -> 14.487414 | J41: =G41/$G$13 -> 16.939075
B42: Combustible | E42: 10503.513 | F42: 10503.513 | G42: 10503.513 | H42: =E42/$E$13 -> 24.714149 | I42: =F42/$F$13 -> 24.0355 | J42: =G42/$G$13 -> 28.619927
B43: Electricidad | E43: 3500 | F43: 3459 | G43: 2260 | H43: =E43/$E$13 -> 8.2352941 | I43: =F43/$F$13 -> 7.9153318 | J43: =G43/$G$13 -> 6.1580381
B44: Vehículos | E44: 10500 | F44: 10898 | G44: 8050 | H44: =E44/$E$13 -> 24.705882 | I44: =F44/$F$13 -> 24.938215 | J44: =G44/$G$13 -> 21.934605
B45: Gas | E45: 3500 | F45: 3783 | G45: 2768 | H45: =E45/$E$13 -> 8.2352941 | I45: =F45/$F$13 -> 8.6567506 | J45: =G45/$G$13 -> 7.5422343
B46: Alquiler vehículos | E46: 11500 | F46: 11500 | G46: 11500 | H46: =E46/$E$13 -> 27.058824 | I46: =F46/$F$13 -> 26.315789 | J46: =G46/$G$13 -> 31.33515
B47: Viaticos staff | E47: 2500 | F47: 2879 | G47: 1243 | H47: =E47/$E$13 -> 5.8823529 | I47: =F47/$F$13 -> 6.5881007 | J47: =G47/$G$13 -> 3.386921
B48: Uniformes | E48: 3000 | F48: 2631 | G48: 3893.9688 | H48: =E48/$E$13 -> 7.0588235 | I48: =F48/$F$13 -> 6.020595 | J48: =G48/$G$13 -> 10.610269
...

Sheet Sueldos
B1: TC | C1: 1450
A3: Calculo recupero Tips House | D3: Calculo recupero Tips Field
A4: BN | B4: ='Budget 2025-26'!E13 -> 425 | D4: BN | E4: ='Budget 2025-26'!H13 -> 0
A5: Estimado tips x BN House | B5: 90 | D5: Estimado tips x BN Field | E5: 90
A6: Total tips estimados | B6: =B5*B4 -> 38250 | D6: Total tips estimados | E6: =E5*B4 -> 38250
A7: Recupero 75% tips servicio | B7: =B6*0.75 -> 28687.5 | D7: Recupero 100% | E7: =E6 -> 38250
A9: Guias | B9: Sueldo Nomina | C9: Costo Sueldo Nomina | D9: Sueldo extra | E9: Meses | F9: Total
A10: Head Guide - Diego Loyola Fijo anual | B10: =600000/$C$1 -> 413.7931 | C10: =B10*0.25 -> 103.44828 | D10: 0 | E10: 8 | F10: =(B10+C10+D10)*E10 -> 4137.931
A11: Head Guide - Diego Loyola Temporada | B11: =1100000/$C$1 -> 758.62069 | C11: =B11*0.25 -> 189.65517 | D11: 1500 | E11: 4 | F11: =(B11+C11+D11)*E11 -> 9793.1034
A12: Fernando Leiva | B12: =1100000/$C$1 -> 758.62069 | C12: =B12*0.25 -> 189.65517 | D12: 1100 | E12: 3.7 | F12: =(B12+C12+D12)*E12 -> 7578.6207
A13: Julio Arguello | B13: =1100000/$C$1 -> 758.62069 | C13: =B13*0.25 -> 189.65517 | D13: 1100 | E13: 3.7 | F13: =(B13+C13+D13)*E13 -> 7578.6207
A14: Guia 3 | B14: =1100000/$C$1 -> 758.62069 | C14: =B14*0.25 -> 189.65517 | D14: 1100 | E14: 3.7 | F14: =(B14+C14+D14)*E14 -> 7578.6207
A15: Field Assistant | B15: =1100000/$C$1 -> 758.62069 | C15: =B15*0.25 -> 189.65517 | D15: 800 | E15: 3.7 | F15: =(B15+C15+D15)*E15 -> 6468.6207
A16: Cebador - Ezequiel Loyola | B16: =1100000/$C$1 -> 758.62069 | C16: =B16*0.25 -> 189.65517 | D16: 800 | E16: 4 | F16: =(B16+C16+D16)*E16 -> 6993.1034
A17: Cebador 2 - Luca Querejeta | B17: =1100000/$C$1 -> 758.62069 | C17: =B17*0.25 -> 189.65517 | D17: 800 | E17: 4 | F17: =(B17+C17+D17)*E17 -> 6993.1034
A18: Charlie Lanusse (Tips) | F18: 5000
A19: Total guías | F19: =SUM(F10:F18) -> 62121.724
A23: Manager | B23: Sueldo Nomina | C23: Costo Sueldo Nomina | D23: Sueldo extra | E23: Meses | F23: Bono | G23: Total
A24: Celeste | B24: =1100000/C1 -> 758.62069 | C24: =B24*0.25 -> 189.65517 | D24: =1700-B24 -> 941.37931 | E24: 3.5 | F24: 1000 | G24: =(B24+C24+D24)*E24+F24 -> 7613.7931
A25: Tips Celeste 20% de House Tips | G25: =0.2*B6 -> 7650
A26: Total Manager | G26: =SUM(G24:G25) -> 15263.793
A28: Servicio | B28: Sueldo Nomina | C28: Costo Sueldo Nomina | D28: Sueldo extra | E28: Meses | F28: Bono | G28: Total
A29: Mucama 1 | B29: =1100000/$C$1 -> 758.62069 | C29: =B29*0.25 -> 189.65517 | D29: 500 | E29: 4 | F29: 300 | G29: =(B29+C29+D29)*E29+F29 -> 6093.1034
A30: Mucama 2 | B30: =1100000/$C$1 -> 758.62069 | C30: =B30*0.25 -> 189.65517 | D30: 400 | E30: 4 | F30: 300 | G30: =(B30+C30+D30)*E30+F30 -> 5693.1034
A31: Lavandera | B31: =1100000/$C$1 -> 758.62069 | C31: =B31*0.25 -> 189.65517 | D31: 400 | E31: 3.5 | F31: 300 | G31: =(B31+C31+D31)*E31+F31 -> 5018.9655
A32: Cocinero | B32: =1100000/$C$1 -> 758.62069 | C32: =B32*0.25 -> 189.65517 | D32: =2400-B32 -> 1641.3793 | E32: 3.5 | F32: 500 | G32: =(B32+C32+D32)*E32+F32 -> 9563.7931
A33: Ayudante de cocina | B33: =1100000/$C$1 -> 758.62069 | C33: =B33*0.25 -> 189.65517 | D33: =2000-B33 -> 1241.3793 | E33: 3.5 | F33: 500 | G33: =(B33+C33+D33)*E33+F33 -> 8163.7931
A34: Mantenimiento | B34: =1100000/$C$1 -> 758.62069 | C34: =B34*0.25 -> 189.65517 | D34: 500 | E34: 3.5 | F34: 300 | G34: =(B34+C34+D34)*E34+F34 -> 5368.9655
A35: Total costo servicio | G35: =SUM(G29:G34) -> 39901.724
