Workbook
Name _____Rt12: #REF!
Name _____Rt12: #REF!
Name _____Rt12: #REF!
Name _____Rt12: #REF!
Name _____Rt12: #REF!
Name _____Rt12: #REF!
Name ____Rt12: #REF!
Name ____Rt12: #REF!
Name ____Rt12: #REF!
Name ____Rt12: #REF!
Name ____Rt12: #REF!
Name ____Rt12: #REF!
Name ___Rt12: #REF!
Name ___Rt12: #REF!
Name ___Rt12: #REF!
Name ___Rt12: #REF!
Name ___Rt12: #REF!
Name ___Rt12: #REF!
Name __Rt12: #REF!
Name __Rt12: #REF!
Name __Rt12: #REF!
Name __Rt12: #REF!
Name __Rt12: #REF!
Name __Rt12: #REF!
Name __xlfn_SUMIFS: NA()
Name _Rt12: #REF!
Name _Rt12: #REF!
Name _Rt12: #REF!
Name _Rt12: #REF!
Name _Rt12: #REF!
Name _Rt12: #REF!
Name AJUSTES: #REF!
Name AJUSTES: #REF!
Name AJUSTES: #REF!
Name AJUSTES: #REF!
Name AJUSTES: #REF!
Name AJUSTES: #REF!
Name AJUSTES: #REF!
Name Assumptions: #REF!
Name Assumptions: #REF!
Name Assumptions: #REF!
Name Assumptions: #REF!
Name Assumptions: #REF!
Name Assumptions: #REF!
Name BuiltIn_Print_Area: #REF!
Name BuiltIn_Print_Area: #REF!
Name BuiltIn_Print_Area: #REF!
Name BuiltIn_Print_Area: #REF!
Name BuiltIn_Print_Area: #REF!
Name BuiltIn_Print_Area: #REF!
Name BuiltIn_Print_Area___0: #REF!
Name BuiltIn_Print_Area___0: #REF!
Name BuiltIn_Print_Area___0: #REF!
Name BuiltIn_Print_Area___0: #REF!
Name BuiltIn_Print_Area___0: #REF!
Name BuiltIn_Print_Area___0: #REF!
Name BuiltIn_Print_Titles: #REF!
Name BuiltIn_Print_Titles: #REF!
Name BuiltIn_Print_Titles: #REF!
Name BuiltIn_Print_Titles: #REF!

Sheet Mov_Analizados_Sept25 - Nov 25
G2: Ver Telefonos
G3: Ver Gastos devengados | I3: $ | J3: USD | K3: TC
G4: Ver Luz Devengada | H4: Food & Wine | I4: =+SUMIF($E$10:$E$371,H4,$I$10:$I$371) -> 13187448 | J4: =+SUMIF($E$10:$E$371,H4,$J$10:$J$371) -> 9389.8586 | K4: =+I4/J4 -> 1404.4352
G7: =+IF(I7+J7=0,"Ok","Check") -> Ok | I7: =ROUND(SUM(I10:I1080),0) -> 0 | J7: =ROUND(SUM(J10:J1080),0) -> 0
E8: Rubro | G8: =+Resumen_Base!C1 -> Ok
B9: =+F9&G9 | D9: DEL | E9: =+VLOOKUP(F9,Resumen_Base!$B$6:$F$69,5,0) -> #N/A | H9: =+D9&F9 -> DEL | I9: =SUM(I10:I371) -> 97836924 | J9: =SUM(J10:J371) -> 69488.431
A10: AJUSTES | B10: Cuenta Anterior | D10: Lodge | E10: Concepto | F10: Codigo Cuenta | G10: Cuenta Contable | I10: Saldo - $ | J10: Saldo - u$s | K10: Tipo cambio | L10: Fecha | M10: Modulo | N10: Cod Centro Costo | O10: gestionid | P10: Detalle | Q10: Observaciones | R10: Observación Adicional | S10: Número | T10: Ejercicio | AA10: tc | AC10: Fecha | AD10: Subdiario | AE10: Div | AF10: Datos del comprobante | AG10: Sujeto | AH10: CUIT | AI10: Observación asiento | AJ10: Clase de Asiento | AK10: Origen del comprobante | AL10: Observación del comprobante | AM10: Comentario renglón asiento | AN10: Asiento
A12: 12020103 | B12: 5226 | D12: DEL | E12: =+VLOOKUP(F12,Resumen_Base!$B$6:$F$69,5,0) -> Fixed Asset's Payments (Investments) Mejoras/equipamiento Lodge | F12: 12020103 | G12: Mejoras de Inmueb y Terrenos | H12: =+D12&F12 -> DEL12020103 | I12: 100000 | J12: 66.666667 | K12: 1500 | L12: 26/10/2025 | M12: CAJA | N12: 0141 | O12: TE001500000062 | P12: Asiento de CAJA (01/09/2025 - 31/08/2026) | Q12: Extracción de Caja 001500000062 Obs: 26-10-2025 Mov Lodge | R12: DT - Adicional padre de rolando por labores en la laguna | S12: 000000000061 | T12: Ejercicio 2025/2026
A13: 12020103 | B13: 5226 | D13: DEL | E13: =+VLOOKUP(F13,Resumen_Base!$B$6:$F$69,5,0) -> Fixed Asset's Payments (Investments) Mejoras/equipamiento Lodge | F13: 12020103 | G13: Mejoras de Inmueb y Terrenos | H13: =+D13&F13 -> DEL12020103 | I13: 15000 | J13: 10.791367 | K13: 1390 | L13: 30/09/2025 | M13: CAJA | N13: 0141 | O13: TE001500000030 | P13: Asiento de CAJA (01/09/2025 - 31/08/2026) | Q13: Extracción de Caja 001500000030 Obs: 30-09-2025 Mov Lodge | R13: DT - Noel le paga a constructor de lancha Laffranchi por ir a buscar el mismo los parlantes de la la | S13: 000000000036 | T13: Ejercicio 2025/2026
A14: 12020103 | B14: 5226 | D14: DEL | E14: =+VLOOKUP(F14,Resumen_Base!$B$6:$F$69,5,0) -> Fixed Asset's Payments (Investments) Mejoras/equipamiento Lodge | F14: 12020103 | G14: Mejoras de Inmueb y Terrenos | H14: =+D14&F14 -> DEL12020103 | I14: 300000 | J14: 200 | K14: 1500 | L14: 26/10/2025 | M14: CAJA | N14: 0141 | O14: TE001500000060 | P14: Asiento de CAJA (01/09/2025 - 31/08/2026) | Q14: Extracción de Caja 001500000060 Obs: 26-10-2025 INCOME OF MONEY | R14: DT - Noel paga adicional al padre de rolando por detalles en obra de laguna | S14: 000000000059 | T14: Ejercicio 2025/2026
D15: DEL | E15: =+VLOOKUP(F15,Resumen_Base!$B$6:$F$69,5,0) -> Fixed Asset's Payments (Investments) Mejoras/equipamiento Lodge | F15: 12020103 | G15: Mejoras de Inmueb y Terrenos | H15: =+D15&F15 -> DEL12020103 | I15: 7800000 | J15: 6000 | K15: 1300 | L15: 03/09/2025 | M15: CAJA | N15: 0141 | O15: TE001500000018 | P15: Asiento de CAJA | Q15: Extracción de Caja 001500000018 Obs: 14-09-2025 Mov Lodge | R15: DEL - Noel le paga adelantó a constructor rolando por obra de la Laguna | S15: 000000000016 | T15: Ejercicio 2025/2026
D16: DEL | E16: =+VLOOKUP(F16,Resumen_Base!$B$6:$F$69,5,0) -> Fixed Asset's Payments (Investments) Mejoras/equipamiento Lodge | F16: 12020103 | G16: Mejoras de Inmueb y Terrenos | H16: =+D16&F16 -> DEL12020103 | I16: 100000 | J16: 70.921986 | K16: 1410 | L16: 05/10/2025 | M16: CAJA | N16: 0141 | O16: TE001500000037 | P16: Asiento de CAJA (01/09/2025 - 31/08/2026) | Q16: Extracción de Caja 001500000037 Obs: 05-10-2025 Mov Lodge | R16: DT - Árboles para la Laguna | S16: 000000000039 | T16: Ejercicio 2025/2026
D17: DEL | E17: =+VLOOKUP(F17,Resumen_Base!$B$6:$F$69,5,0) -> Fixed Asset's Payments (Investments) Mejoras/equipamiento Lodge | F17: 12020103 | G17: Mejoras de Inmueb y Terrenos | H17: =+D17&F17 -> DEL12020103 | I17: 2860000 | J17: 2000 | K17: 1430 | L17: 12/10/2025 | M17: CAJA | N17: 0141 | O17: TE001500000047 | P17: Asiento de CAJA (01/09/2025 - 31/08/2026) | Q17: Extracción de Caja 001500000047 Obs: 12-10-2025 Mov Lodge | R17: DT - Noel le paga a Rolando constructor en concepto de adelanto por obra de Laguna | S17: 000000000044 | T17: Ejercicio 2025/2026
D18: DEL | E18: =+VLOOKUP(F18,Resumen_Base!$B$6:$F$69,5,0) -> Fixed Asset's Payments (Investments) Mejoras/equipamiento Lodge | F18: 12020103 | G18: Mejoras de Inmueb y Terrenos | H18: =+D18&F18 -> DEL12020103 | I18: 300000 | J18: 215.82734 | K18: 1390 | L18: 30/09/2025 | M18: CAJA | N18: 0141 | O18: TE001500000030 | P18: Asiento de CAJA (01/09/2025 - 31/08/2026) | Q18: Extracción de Caja 001500000030 Obs: 30-09-2025 Mov Lodge | R18: DT - Noel le paga adicional al padre de constructor rolando por agravar un canal en la obra de la La | S18: 000000000036 | T18: Ejercicio 2025/2026
D19: DEL | E19: =+VLOOKUP(F19,Resumen_Base!$B$6:$F$69,5,0) -> Fixed Asset's Payments (Investments) Mejoras/equipamiento Lodge | F19: 12020103 | G19: Mejoras de Inmueb y Terrenos | H19: =+D19&F19 -> DEL12020103 | I19: 450000 | J19: 316.90141 | K19: 1420 | L19: 30/11/2025 | M19: CAJA | N19: 0141 | O19: TE001500000085 | P19: Asiento de CAJA (01/09/2025 - 31/08/2026) | Q19: Extracción de Caja 001500000085 Obs: 30-11-2025 Mov Lodge | R19: DT - Noel paga al padre de rolando por agrandar un sector de la laguna | S19: 000000000083 | T19: Ejercicio 2025/2026
D20: DEL | E20: =+VLOOKUP(F20,Resumen_Base!$B$6:$F$69,5,0) -> Fixed Asset's Payments (Investments) Mejoras/equipamiento Lodge | F20: 12020103 | G20: Mejoras de Inmueb y Terrenos | H20: =+D20&F20 -> DEL12020103 | I20: 1050000 | J20: 700 | K20: 1500 | L20: 26/10/2025 | M20: CAJA | N20: 0141 | O20: TE001500000060 | P20: Asiento de CAJA (01/09/2025 - 31/08/2026) | Q20: Extracción de Caja 001500000060 Obs: 26-10-2025 INCOME OF MONEY | R20: DT - Obra de la escalera detrás de casa Noel | S20: 000000000059 | T20: Ejercicio 2025/2026
D21: DEL | E21: =+VLOOKUP(F21,Resumen_Base!$B$6:$F$69,5,0) -> Fixed Asset's Payments (Investments) Mejoras/equipamiento Lodge | F21: 12020103 | G21: Mejoras de Inmueb y Terrenos | H21: =+D21&F21 -> DEL12020103 | I21: 620000 | J21: 446.04317 | K21: 1390 | L21: 30/09/2025 | M21: CAJA | N21: 0141 | O21: TE001500000030 | P21: Asiento de CAJA (01/09/2025 - 31/08/2026) | Q21: Extracción de Caja 001500000030 Obs: 30-09-2025 Mov Lodge | R21: DT - Pago a Rolando por cañería para la Laguna | S21: 000000000036 | T21: Ejercicio 2025/2026
D22: DEL | E22: =+VLOOKUP(F22,Resumen_Base!$B$6:$F$69,5,0) -> Fixed Asset's Payments (Investments) Mejoras/equipamiento Lodge | F22: 12020103 | G22: Mejoras de Inmueb y Terrenos | H22: =+D22&F22 -> DEL12020103 | I22: 150000 | J22: 107.91367 | K22: 1390 | L22: 30/09/2025 | M22: CAJA | N22: 0141 | O22: TE001500000030 | P22: Asiento de CAJA (01/09/2025 - 31/08/2026) | Q22: Extracción de Caja 001500000030 Obs: 30-09-2025 Mov Lodge | R22: DT - Pago por tarea adicional en obre de Laguna, el padre del constructor de rolando le agrego un pe | S22: 000000000036 | T22: Ejercicio 2025/2026
D23: DEL | E23: =+VLOOKUP(F23,Resumen_Base!$B$6:$F$69,5,0) -> Fixed Asset's Payments (Investments) Mejoras/equipamiento Lodge | F23: 12020103 | G23: Mejoras de Inmueb y Terrenos | H23: =+D23&F23 -> DEL12020103 | I23: 9000 | J23: 6.2937063 | K23: 1430 | L23: 12/10/2025 | M23: CAJA | N23: 0141 | O23: TE001500000046 | P23: Asiento de CAJA (01/09/2025 - 31/08/2026) | Q23: Extracción de Caja 001500000046 Obs: 12-10-2025 Mov Lodge | R23: DT - Plantas agramaticas | S23: 000000000043 | T23: Ejercicio 2025/2026
D24: DEL | E24: =+VLOOKUP(F24,Resumen_Base!$B$6:$F$69,5,0) -> Fixed Asset's Payments (Investments) Mejoras/equipamiento Lodge | F24: 12020103 | G24: Mejoras de Inmueb y Terrenos | H24: =+D24&F24 -> DEL12020103 | I24: 76600 | J24: 51.066667 | K24: 1500 | L24: 26/10/2025 | M24: CAJA | N24: 0141 | O24: TE001500000062 | P24: Asiento de CAJA (01/09/2025 - 31/08/2026) | Q24: Extracción de Caja 001500000062 Obs: 26-10-2025 Mov Lodge | R24: DT - Plantas aromáticas | S24: 000000000061 | T24: Ejercicio 2025/2026
D25: DEL | E25: =+VLOOKUP(F25,Resumen_Base!$B$6:$F$69,5,0) -> Fixed Asset's Payments (Investments) Mejoras/equipamiento Lodge | F25: 12020103 | G25: Mejoras de Inmueb y Terrenos | H25: =+D25&F25 -> DEL12020103 | I25: 42000 | J25: 29.370629 | K25: 1430 | L25: 12/10/2025 | M25: CAJA | N25: 0141 | O25: TE001500000046 | P25: Asiento de CAJA (01/09/2025 - 31/08/2026) | Q25: Extracción de Caja 001500000046 Obs: 12-10-2025 Mov Lodge | R25: DT - Vivero plantas varias para el lodge | S25: 000000000043 | T25: Ejercicio 2025/2026
D26: DEL | E26: =+VLOOKUP(F26,Resumen_Base!$B$6:$F$69,5,0) -> Fixed Asset's Payments (Investments) Mejoras/equipamiento Lodge | F26: 12020103 | G26: Mejoras de Inmueb y Terrenos | H26: =+D26&F26 -> DEL12020103 | I26: 150000 | J26: 102.73973 | K26: 1460 | L26: 31/10/2025 | M26: CAJA | N26: 0141 | O26: TE001500000066 | P26: Asiento de CAJA (01/09/2025 - 31/08/2026) | Q26: Extracción de Caja 001500000066 Obs: Movimiento_Cajas_Bancos_Semana 25-26 al 31-10-2025 | R26: DT-Embalsado de madera para agregar a la laguna F.Fijo Oper. Al 31-10-2025 | S26: 000000000067 | T26: Ejercicio 2025/2026
... D30: DEL | E30: =+VLOOKUP(F30,Resumen_Base!$B$6:$F$69,5,0) -> Fixed Asset's Payments (Investments) Mejoras/equipamiento Lodge | F30: 12020103 | G30: Mejoras de Inmueb y Terrenos | H30: =+D30&F30 -> DEL12020103 | I30: 150000 | J30: 102.73973 | K30: 1460 | L30: 31/10/2025 | M30: CAJA | N30: 0141 | O30: TE001500000066 | P30: Asiento de CAJA (01/09/2025 - 31/08/2026) | Q30: Extracción de Caja 001500000066 Obs: Movimiento_Cajas_Bancos_Semana 25-26 al 31-10-2025 | R30: DT-Instalacion electrica en galpon nuevo detrás de casa staff F.Fijo Oper. Al 31-10-2025 | S30: 000000000067 | T30: Ejercicio 2025/2026
A31: 12020201 | B31: 5252 | D31: DEL | E31: =+VLOOKUP(F31,Resumen_Base!$B$6:$F$69,5,0) -> Fixed Asset's Payments (Investments) Mejoras/equipamiento Lodge | F31: 12020201 | G31: Instalaciones | H31: =+D31&F31 -> DEL12020201 | I31: 556000 | J31: 400 | K31: 1390 | L31: 30/09/2025 | M31: CAJA | N31: 0141 | O31: TE001500000033 | P31: Asiento de CAJA (01/09/2025 - 31/08/2026) | Q31: Extracción de Caja 001500000033 Obs: 30-09-2025 Mov Lodge | R31: DT - Pago a constructor rolando por instalar bomba presurizadora nueva debajo de calefon cocina nuev | S31: 000000000037 | T31: Ejercicio 2025/2026
D32: DEL | E32: =+VLOOKUP(F32,Resumen_Base!$B$6:$F$69,5,0) -> Fixed Asset's Payments (Investments) Mejoras/equipamiento Lodge | F32: 12020201 | G32: Instalaciones | H32: =+D32&F32 -> DEL12020201 | I32: 3748970.4 | J32: 2640.12 | K32: 1420 | L32: 14/11/2025 | M32: CAJA | N32: 0141 | O32: TE001500000077 | P32: Asiento de CAJA (01/09/2025 - 31/08/2026) | Q32: Extracción de Caja 001500000077 Obs: Movimiento_Cajas_Bancos_Semana 25-26 al 14-11-2025 | R32: DEL- Saldo Proyecto Salores Nexo 25/26 | S32: 000000000078 | T32: Ejercicio 2025/2026
D33: DEL | E33: =+VLOOKUP(F33,Resumen_Base!$B$6:$F$69,5,0) -> Fixed Asset's Payments (Investments) Mejoras/equipamiento Lodge | F33: 12020301 | G33: Movilidad y Viáticos - Locales | H33: =+D33&F33 -> DEL12020301 | I33: 240000 | J33: 160 | K33: 1500 | L33: 26/10/2025 | M33: CAJA | N33: 0141 | O33: TE001500000062 | P33: Asiento de CAJA (01/09/2025 - 31/08/2026) | Q33: Extracción de Caja 001500000062 Obs: 26-10-2025 Mov Lodge | R33: DT - Sillón nuevo para muelle de atrás | S33: 000000000061 | T33: Ejercicio 2025/2026
A34: 12020301 | B34: 5218 | D34: DEL | E34: =+VLOOKUP(F34,Resumen_Base!$B$6:$F$69,5,0) -> Fixed Asset's Payments (Investments) Mejoras/equipamiento Lodge | F34: 12020301 | G34: Muebles y útiles | H34: =+D34&F34 -> DEL12020301 | I34: 15000 | J34: 10 | K34: 1500 | L34: 26/10/2025 | M34: CAJA | N34: 0141 | O34: TE001500000062 | P34: Asiento de CAJA (01/09/2025 - 31/08/2026) | Q34: Extracción de Caja 001500000062 Obs: 26-10-2025 Mov Lodge | R34: DT - Flete para sillón del muelle de atrás | S34: 000000000061 | T34: Ejercicio 2025/2026
A35: 12020301 | B35: 5218 | D35: DEL | E35: =+VLOOKUP(F35,Resumen_Base!$B$6:$F$69,5,0) -> Fixed Asset's Payments (Investments) Mejoras/equipamiento Lodge | F35: 12020301 | G35: Muebles y útiles | H35: =+D35&F35 -> DEL12020301 | I35: 42000 | J35: 30 | K35: 1400 | L35: 17/10/2025 | M35: CAJA | N35: 0141 | O35: TE001500000052 | P35: Asiento de CAJA (01/09/2025 - 31/08/2026) | Q35: Extracción de Caja 001500000052 Obs: Movimiento_Cajas_Bancos_Semana 25-26 al 17-10-2025 | R35: DT-Flete envío Heladera Vertical - San Cristobal - Guarderia La Baie F.Fijo Oper. Al 17-10-2025 | S35: 000000000052 | T35: Ejercicio 2025/2026
D36: DEL | E36: =+VLOOKUP(F36,Resumen_Base!$B$6:$F$69,5,0) -> Fixed Asset's Payments (Investments) Mejoras/equipamiento Lodge | F36: 12020301 | G36: Muebles y útiles | H36: =+D36&F36 -> DEL12020301 | I36: 58000 | J36: 38.666667 | K36: 1500 | L36: 26/10/2025 | M36: CAJA | N36: 0141 | O36: TE001500000062 | P36: Asiento de CAJA (01/09/2025 - 31/08/2026) | Q36: Extracción de Caja 001500000062 Obs: 26-10-2025 Mov Lodge | R36: DT - Corderitos para sillón nuevo en muelle de atrás | S36: 000000000061 | T36: Ejercicio 2025/2026
D37: DEL | E37: =+VLOOKUP(F37,Resumen_Base!$B$6:$F$69,5,0) -> Fixed Asset's Payments (Investments) Mejoras/equipamiento Lodge | F37: 12020301 | G37: Muebles y útiles | H37: =+D37&F37 -> DEL12020301 | I37: 380000 | J37: 267.60563 | K37: 1420 | L37: 30/11/2025 | M37: CAJA | N37: 0141 | O37: TE001500000085 | P37: Asiento de CAJA (01/09/2025 - 31/08/2026) | Q37: Extracción de Caja 001500000085 Obs: 30-11-2025 Mov Lodge | R37: DT - Mesa ratona para muelle de atrás | S37: 000000000083 | T37: Ejercicio 2025/2026
D38: DEL | E38: =+VLOOKUP(F38,Resumen_Base!$B$6:$F$69,5,0) -> Fixed Asset's Payments (Investments) Mejoras/equipamiento Lodge | F38: 12020301 | G38: Muebles y útiles | H38: =+D38&F38 -> DEL12020301 | I38: 72700 | J38: 51.197183 | K38: 1420 | L38: 30/11/2025 | M38: CAJA | N38: 0141 | O38: TE001500000085 | P38: Asiento de CAJA (01/09/2025 - 31/08/2026) | Q38: Extracción de Caja 001500000085 Obs: 30-11-2025 Mov Lodge | R38: DT - Mueble mesa de apoyo hab 3 y 4 + 1 canasto mimbre | S38: 000000000083 | T38: Ejercicio 2025/2026
D39: DEL | E39: =+VLOOKUP(F39,Resumen_Base!$B$6:$F$69,5,0) -> Fixed Asset's Payments (Investments) Mejoras/equipamiento Lodge | F39: 12020301 | G39: Muebles y útiles | H39: =+D39&F39 -> DEL12020301 | I39: 900 | J39: 0.62937063 | K39: 1430 | L39: 12/10/2025 | M39: CAJA | N39: 0141 | O39: TE001500000046 | P39: Asiento de CAJA (01/09/2025 - 31/08/2026) | Q39: Extracción de Caja 001500000046 Obs: 12-10-2025 Mov Lodge | R39: DT - Peaje auto Noel | S39: 000000000043 | T39: Ejercicio 2025/2026
D40: DEL | E40: =+VLOOKUP(F40,Resumen_Base!$B$6:$F$69,5,0) -> Fixed Asset's Payments (Investments) Mejoras/equipamiento Lodge | F40: 12020301 | G40: Muebles y útiles | H40: =+D40&F40 -> DEL12020301 | I40: 90000 | J40: 62.937063 | K40: 1430 | L40: 12/10/2025 | M40: CAJA | N40: 0141 | O40: TE001500000046 | P40: Asiento de CAJA (01/09/2025 - 31/08/2026) | Q40: Extracción de Caja 001500000046 Obs: 12-10-2025 Mov Lodge | R40: DT - Tablón para superficie de apoyo cuarto de huéspedes | S40: 000000000043 | T40: Ejercicio 2025/2026
D41: DEL | E41: =+VLOOKUP(F41,Resumen_Base!$B$6:$F$69,5,0) -> Fixed Asset's Payments (Investments) Mejoras/equipamiento Lodge | F41: 12020301 | G41: Muebles y útiles | H41: =+D41&F41 -> DEL12020301 | I41: 77987 | J41: 59.99 | K41: 1300 | L41: 05/09/2025 | M41: CAJA | N41: 0141 | O41: TE001500000016 | P41: Asiento de CAJA | Q41: Extracción de Caja 001500000016 Obs: Movimiento_Cajas_Bancos_Semana 25-26 al 05-09-2025 | R41: DT- Reel - ValleySW- DEBIT PURCHASE MERCHANT PURCHASE TERMINAL 420429 eBay O 12 13467 06 671 San | S41: 000000000015 | T41: Ejercicio 2025/2026
D42: DEL | E42: =+VLOOKUP(F42,Resumen_Base!$B$6:$F$69,5,0) -> Fixed Asset's Payments (Investments) Mejoras/equipamiento Lodge | F42: 12020301 | G42: Muebles y útiles | H42: =+D42&F42 -> DEL12020301 | I42: 68822 | J42: 52.94 | K42: 1300 | L42: 05/09/2025 | M42: CAJA | N42: 0141 | O42: TE001500000016 | P42: Asiento de CAJA | Q42: Extracción de Caja 001500000016 Obs: Movimiento_Cajas_Bancos_Semana 25-26 al 05-09-2025 | R42: DT- Reel - ValleySW- DEBIT PURCHASE MERCHANT PURCHASE TERMINAL 420429 eBay O 12 13467 06 672 San | S42: 000000000015 | T42: Ejercicio 2025/2026
D43: DEL | E43: =+VLOOKUP(F43,Resumen_Base!$B$6:$F$69,5,0) -> Fixed Asset's Payments (Investments) Mejoras/equipamiento Lodge | F43: 12020301 | G43: Muebles y útiles | H43: =+D43&F43 -> DEL12020301 | I43: 92586 | J43: 71.22 | K43: 1300 | L43: 05/09/2025 | M43: CAJA | N43: 0141 | O43: TE001500000016 | P43: Asiento de CAJA | Q43: Extracción de Caja 001500000016 Obs: Movimiento_Cajas_Bancos_Semana 25-26 al 05-09-2025 | R43: DT- Reel - ValleySW- DEBIT PURCHASE MERCHANT PURCHASE TERMINAL 420429 eBay O 12 13467 06 673 San | S43: 000000000015 | T43: Ejercicio 2025/2026
D44: DEL | E44: =+VLOOKUP(F44,Resumen_Base!$B$6:$F$69,5,0) -> Fixed Asset's Payments (Investments) Mejoras/equipamiento Lodge | F44: 12020301 | G44: Muebles y útiles | H44: =+D44&F44 -> DEL12020301 | I44: 87685 | J44: 67.45 | K44: 1300 | L44: 05/09/2025 | M44: CAJA | N44: 0141 | O44: TE001500000016 | P44: Asiento de CAJA | Q44: Extracción de Caja 001500000016 Obs: Movimiento_Cajas_Bancos_Semana 25-26 al 05-09-2025 | R44: DT- Reel - ValleySW- DEBIT PURCHASE MERCHANT PURCHASE TERMINAL 420429 eBay O 12 13467 06 674 San | S44: 000000000015 | T44: Ejercicio 2025/2026
D45: DEL | E45: =+VLOOKUP(F45,Resumen_Base!$B$6:$F$69,5,0) -> Fixed Asset's Payments (Investments) Mejoras/equipamiento Lodge | F45: 12020301 | G45: Muebles y útiles | H45: =+D45&F45 -> DEL12020301 | I45: 800000 | J45: 533.33333 | K45: 1500 | L45: 24/10/2025 | M45: CAJA | N45: 0141 | O45: TE001500000061 | P45: Asiento de CAJA (01/09/2025 - 31/08/2026) | Q45: Extracción de Caja 001500000061 Obs: Movimiento_Cajas_Bancos_Semana 25-26 al 24-10-2025 | R45: DT-Compra 2 bancos hierro para Hab 1 y 2 F.Fijo Oper. Al 24-10-2025 | S45: 000000000060 | T45: Ejercicio 2025/2026
D46: DEL | E46: =+VLOOKUP(F46,Resumen_Base!$B$6:$F$69,5,0) -> Fixed Asset's Payments (Investments) Mejoras/equipamiento Lodge | F46: 12020301 | G46: Muebles y útiles | H46: =+D46&F46 -> DEL12020301 | I46: 159600 | J46: 109.31507 | K46: 1460 | L46: 14/11/2025 | M46: CAJA | N46: 0141 | O46: TE001500000078 | P46: Asiento de CAJA (01/09/2025 - 31/08/2026) | Q46: Extracción de Caja 001500000078 Obs: Movimiento_Cajas_Bancos_Semana 25-26 al 14-11-2025 | R46: DT-Compra de 2 cañas (compra realizada el 5/11) Pagos Depsa Valores. Al 14-11-2025 | S46: 000000000079 | T46: Ejercicio 2025/2026
D47: DEL | E47: =+VLOOKUP(F47,Resumen_Base!$B$6:$F$69,5,0) -> Fixed Asset's Payments (Investments) Mejoras/equipamiento Lodge | F47: 12020301 | G47: Muebles y útiles | H47: =+D47&F47 -> DEL12020301 | I47: 964079 | J47: 688.62786 | K47: 1400 | L47: 17/10/2025 | M47: CAJA | N47: 0141 | O47: TE001500000052 | P47: Asiento de CAJA (01/09/2025 - 31/08/2026) | Q47: Extracción de Caja 001500000052 Obs: Movimiento_Cajas_Bancos_Semana 25-26 al 17-10-2025 | R47: DT-Compra Heladera Exhibidora Vertical Inelro Mt - 450 437 Lts 1 Puerta - Gastro Hogar F.Fijo Oper. | S47: 000000000052 | T47: Ejercicio 2025/2026
...

Sheet Mov_Analizados_Dic25
G2: Ver Telefonos
G3: Ver Gastos devengados | I3: $ | J3: USD | K3: TC
G4: Ver Luz Devengada | H4: Food & Wine | I4: =+SUMIF($E$10:$E$371,H4,$I$10:$I$371) -> 3013697 | J4: =+SUMIF($E$10:$E$371,H4,$J$10:$J$371) -> 2105.2849 | K4: =+I4/J4 -> 1431.4913
G7: =+IF(I7+J7=0,"Ok","Check") -> Ok | I7: =ROUND(SUM(I10:I364),0) -> 0 | J7: =ROUND(SUM(J10:J364),0) -> 0
E8: Rubro | G8: =+Resumen_Base!C1 -> Ok
B9: =+F9&G9 | D9: DEL | E9: =+VLOOKUP(F9,Resumen_Base!$B$6:$F$69,5,0) -> #N/A | H9: =+D9&F9 -> DEL | I9: =SUM(I10:I130) -> 25550567 | J9: =SUM(J10:J130) -> 17678.519
B10: Cuenta Anterior | D10: Lodge | E10: Concepto | F10: Cuenta | G10: Nombre | I10: monto $ | J10: monto USD | K10: TC | L10: Fecha | M10: Subdiario | N10: Div | O10: Datos del comprobante | P10: Sujeto | Q10: CUIT | R10: Observación asiento | S10: Clase de Asiento | T10: Origen del comprobante | U10: Observación del comprobante | V10: Comentario renglón asiento | W10: Asiento | X10: Control | Z10: monto USD | AA10: tc | AC10: Fecha | AD10: Subdiario | AE10: Div | AF10: Datos del comprobante | AG10: Sujeto | AH10: CUIT | AI10: Observación asiento | AJ10: Clase de Asiento | AK10: Origen del comprobante | AL10: Observación del comprobante | AM10: Comentario renglón asiento | AN10: Asiento
D12: DEL | E12: =+VLOOKUP(F12,Resumen_Base!$B$6:$F$69,5,0) -> Fixed Asset's Payments (Investments) Mejoras/equipamiento Lodge | F12: 12020301 | G12: Muebles y útiles | H12: =+D12&F12 -> DEL12020301 | I12: 53450 | J12: 37.640845 | K12: 1420 | L12: 14/12/2025 | M12: CAJA | N12: 0141 | O12: TE001500000101 | P12: Asiento de CAJA (01/09/2025 - 31/08/2026) | Q12: Extracción de Caja 001500000101 Obs: 14-12-2025 Mov Lodge | R12: DT - 2 mesas de apoyo para los baños de habitaciones huéspedes | S12: 000000000112 | T12: Ejercicio 2025/2026
D13: DEL | E13: =+VLOOKUP(F13,Resumen_Base!$B$6:$F$69,5,0) -> Fixed Asset's Payments (Investments) Mejoras/equipamiento Lodge | F13: 12020301 | G13: Muebles y útiles | H13: =+D13&F13 -> DEL12020301 | I13: 70000 | J13: 49.295775 | K13: 1420 | L13: 14/12/2025 | M13: CAJA | N13: 0141 | O13: TE001500000101 | P13: Asiento de CAJA (01/09/2025 - 31/08/2026) | Q13: Extracción de Caja 001500000101 Obs: 14-12-2025 Mov Lodge | R13: DT - Noel compra mesa de apoyo para living principal huéspedes | S13: 000000000112 | T13: Ejercicio 2025/2026
D14: DEL | E14: =+VLOOKUP(F14,Resumen_Base!$B$6:$F$69,5,0) -> Fixed Asset's Payments (Investments) Mejoras/equipamiento Lodge | F14: 12020301 | G14: Muebles y útiles | H14: =+D14&F14 -> DEL12020301 | I14: 142000 | J14: 100 | K14: 1420 | L14: 14/12/2025 | M14: CAJA | N14: 0141 | O14: TE001500000100 | P14: Asiento de CAJA (01/09/2025 - 31/08/2026) | Q14: Extracción de Caja 001500000100 Obs: 14-12-2025 Mov Lodge | R14: DT - Noel compra mueble mesa de apoyo para living de huéspedes | S14: 000000000111 | T14: Ejercicio 2025/2026
D15: DEL | E15: =+VLOOKUP(F15,Resumen_Base!$B$6:$F$69,5,0) -> Fixed Asset's Payments (Investments) Rodados/Lanchas | F15: 12020701 | G15: Lanchas y Botes | H15: =+D15&F15 -> DEL12020701 | I15: 1374000 | J15: 967.60563 | K15: 1420 | L15: 19/12/2025 | M15: CAJA | N15: 0141 | O15: TE001500000111 | P15: Asiento de CAJA (01/09/2025 - 31/08/2026) | Q15: Extracción de Caja 001500000111 Obs: Movimiento_Cajas_Bancos_Semana 25-26 al 19-12-2025 | R15: DT-Flete Pira Jagua (itati - Bella vista - Bs As) 930km Pagos Frank Garrahan-. Al 19-12-2025 | S15: 000000000116 | T15: Ejercicio 2025/2026
D16: DEL | E16: =+VLOOKUP(F16,Resumen_Base!$B$6:$F$69,5,0) -> Shop | F16: 4104 | G16: Ventas Shop | H16: =+D16&F16 -> DEL4104 | I16: -85200 | J16: -60 | K16: 1420 | L16: 07/12/2025 | M16: VENTAS | N16: 0141 | O16: VF000000002775B | P16: Asiento de VENTAS (01/09/2025 - 31/08/2026) | Q16: F B 000000002775 | R16: Ref. nota de Venta: DEL20 Obs.:07-12-2025_CLIENTES | S16: 000000000100 | T16: Ejercicio 2025/2026
D17: DEL | E17: =+VLOOKUP(F17,Resumen_Base!$B$6:$F$69,5,0) -> Shop | F17: 4104 | G17: Ventas Shop | H17: =+D17&F17 -> DEL4104 | I17: -85200 | J17: -60 | K17: 1420 | L17: 07/12/2025 | M17: VENTAS | N17: 0141 | O17: VF000000002776B | P17: Asiento de VENTAS (01/09/2025 - 31/08/2026) | Q17: F B 000000002776 | R17: Ref. nota de Venta: DEL42 Obs.:07-12-2025_CLIENTES | S17: 000000000101 | T17: Ejercicio 2025/2026
D18: DEL | E18: =+VLOOKUP(F18,Resumen_Base!$B$6:$F$69,5,0) -> Shop | F18: 4104 | G18: Ventas Shop | H18: =+D18&F18 -> DEL4104 | I18: -56800 | J18: -40 | K18: 1420 | L18: 07/12/2025 | M18: VENTAS | N18: 0141 | O18: VF000000002777B | P18: Asiento de VENTAS (01/09/2025 - 31/08/2026) | Q18: F B 000000002777 | R18: Ref. nota de Venta: DEL50 Obs.:07-12-2025_CLIENTES | S18: 000000000102 | T18: Ejercicio 2025/2026
D19: DEL | E19: =+VLOOKUP(F19,Resumen_Base!$B$6:$F$69,5,0) -> Shop | F19: 4104 | G19: Ventas Shop | H19: =+D19&F19 -> DEL4104 | I19: -42600 | J19: -30 | K19: 1420 | L19: 07/12/2025 | M19: VENTAS | N19: 0141 | O19: VF000000002778B | P19: Asiento de VENTAS (01/09/2025 - 31/08/2026) | Q19: F B 000000002778 | R19: Ref. nota de Venta: DEL50 Obs.:07-12-2025_CLIENTES | S19: 000000000103 | T19: Ejercicio 2025/2026
D20: DEL | E20: =+VLOOKUP(F20,Resumen_Base!$B$6:$F$69,5,0) -> Shop | F20: 4104 | G20: Ventas Shop | H20: =+D20&F20 -> DEL4104 | I20: -42600 | J20: -30 | K20: 1420 | L20: 07/12/2025 | M20: VENTAS | N20: 0141 | O20: VF000000002778B | P20: Asiento de VENTAS (01/09/2025 - 31/08/2026) | Q20: F B 000000002778 | R20: Ref. nota de Venta: DEL50 Obs.:07-12-2025_CLIENTES | S20: 000000000103 | T20: Ejercicio 2025/2026
D21: DEL | E21: =+VLOOKUP(F21,Resumen_Base!$B$6:$F$69,5,0) -> Shop | F21: 4104 | G21: Ventas Shop | H21: =+D21&F21 -> DEL4104 | I21: -176400 | J21: -120 | K21: 1470 | L21: 31/12/2025 | M21: VENTAS | N21: 0141 | O21: VF000000003173B | P21: Asiento de VENTAS (01/09/2025 - 31/08/2026) | Q21: F B 000000003173 | R21: Ref. nota de Venta: DEL6 Obs.:31-12-2025_CLIENTES | S21: 000000000147 | T21: Ejercicio 2025/2026
D22: DEL | E22: =+VLOOKUP(F22,Resumen_Base!$B$6:$F$69,5,0) -> Canon Lodge/Labor Permits: | F22: 5208 | G22: Alquileres y Canon | H22: =+D22&F22 -> DEL5208 | I22: 17000 | J22: 11.564626 | K22: 1470 | L22: 31/12/2025 | M22: CAJA | N22: 0141 | O22: TE001500000137 | P22: Asiento de CAJA (01/09/2025 - 31/08/2026) | Q22: Extracción de Caja 001500000137 Obs: Movimiento_Cajas_Bancos_Semana 25-26 al 02-01-2026 | R22: DT-Saldo pendiente por aumento de cuota Diciembre - guarderia La Baie F.Fijo Oper. Al 02-02-2026 | S22: 000000000130 | T22: Ejercicio 2025/2026
D23: DEL | E23: =+VLOOKUP(F23,Resumen_Base!$B$6:$F$69,5,0) -> Work uniforms for personnel (employees) | F23: 5220 | G23: Uniformes | H23: =+D23&F23 -> DEL5220 | I23: 50402.05 | J23: 34.287109 | K23: 1470 | L23: 26/12/2025 | M23: CAJA | N23: 0141 | O23: TE001500000115 | P23: Asiento de CAJA (01/09/2025 - 31/08/2026) | Q23: Extracción de Caja 001500000115 Obs: Movimiento_Cajas_Bancos_Semana 25-26 al 26-12-2025 | R23: DT-Compra 1 par de zuecos gastronomicos - Andres F.Fijo Oper. Al 26-12-2025 | S23: 000000000120 | T23: Ejercicio 2025/2026
A24: 5210 | B24: 5226 | D24: DEL | E24: =+VLOOKUP(F24,Resumen_Base!$B$6:$F$69,5,0) -> Services/House | F24: 5226 | G24: Remuneraciones Servicios | H24: =+D24&F24 -> DEL5226 | I24: 80000 | J24: 54.421769 | K24: 1470 | L24: 31/12/2025 | M24: CAJA | N24: 0141 | O24: TE001500000120 | P24: Asiento de CAJA (01/09/2025 - 31/08/2026) | Q24: Extracción de Caja 001500000120 Obs: 31-12-2025 Mov Lodge | R24: DT - Noel le paga a Alexis por 1 Transfer realizado | S24: 000000000122 | T24: Ejercicio 2025/2026
A25: 5253 | B25: 5226 | D25: DEL | E25: =+VLOOKUP(F25,Resumen_Base!$B$6:$F$69,5,0) -> Services/House | F25: 5226 | G25: Remuneraciones Servicios | H25: =+D25&F25 -> DEL5226 | I25: 100000 | J25: 68.027211 | K25: 1470 | L25: 31/12/2025 | M25: CAJA | N25: 0141 | O25: TE001500000120 | P25: Asiento de CAJA (01/09/2025 - 31/08/2026) | Q25: Extracción de Caja 001500000120 Obs: 31-12-2025 Mov Lodge | R25: DT - Noel paga a Alexis casero por remolcar lancha del Lodge hasta la guardería náutica | S25: 000000000122 | T25: Ejercicio 2025/2026
D26: DEL | E26: =+VLOOKUP(F26,Resumen_Base!$B$6:$F$69,5,0) -> Services/House | F26: 5226 | G26: Remuneraciones Servicios | H26: =+D26&F26 -> DEL5226 | I26: 499800 | J26: 340 | K26: 1470 | L26: 31/12/2025 | M26: CAJA | N26: 0141 | O26: TE001500000119 | P26: Asiento de CAJA (01/09/2025 - 31/08/2026) | Q26: Extracción de Caja 001500000119 Obs: 31-12-2025 Mov Lodge | R26: DT - Pago a Karina por 6 full day (le incluyo 10 usd que le debia de la vez anterior) | S26: 000000000121 | T26: Ejercicio 2025/2026
D27: DEL | E27: =+VLOOKUP(F27,Resumen_Base!$B$6:$F$69,5,0) -> Services/House | F27: 5226 | G27: Remuneraciones Servicios | H27: =+D27&F27 -> DEL5226 | I27: 588000 | J27: 400 | K27: 1470 | L27: 31/12/2025 | M27: CAJA | N27: 0141 | O27: TE001500000119 | P27: Asiento de CAJA (01/09/2025 - 31/08/2026) | Q27: Extracción de Caja 001500000119 Obs: 31-12-2025 Mov Lodge | R27: DT - Pago a Lucia por ayuda en cocina | S27: 000000000121 | T27: Ejercicio 2025/2026
D28: DEL | E28: =+VLOOKUP(F28,Resumen_Base!$B$6:$F$69,5,0) -> Services/House | F28: 5226 | G28: Remuneraciones Servicios | H28: =+D28&F28 -> DEL5226 | I28: 20000 | J28: 13.605442 | K28: 1470 | L28: 31/12/2025 | M28: CAJA | N28: 0141 | O28: TE001500000120 | P28: Asiento de CAJA (01/09/2025 - 31/08/2026) | Q28: Extracción de Caja 001500000120 Obs: 31-12-2025 Mov Lodge | R28: DT - Pago adicional a Alexis por hacer compras | S28: 000000000122 | T28: Ejercicio 2025/2026
D29: DEL | E29: =+VLOOKUP(F29,Resumen_Base!$B$6:$F$69,5,0) -> Services/House | F29: 5226 | G29: Remuneraciones Servicios | H29: =+D29&F29 -> DEL5226 | I29: 40000 | J29: 27.210884 | K29: 1470 | L29: 31/12/2025 | M29: CAJA | N29: 0141 | O29: TE001500000120 | P29: Asiento de CAJA (01/09/2025 - 31/08/2026) | Q29: Extracción de Caja 001500000120 Obs: 31-12-2025 Mov Lodge | R29: DT - Pago complementario lucia ayuda cocina | S29: 000000000122 | T29: Ejercicio 2025/2026
D30: DEL | E30: =+VLOOKUP(F30,Resumen_Base!$B$6:$F$69,5,0) -> Services/House | F30: 5226 | G30: Remuneraciones Servicios | H30: =+D30&F30 -> DEL5226 | I30: 1136000 | J30: 800 | K30: 1420 | L30: 14/12/2025 | M30: CAJA | N30: 0141 | O30: TE001500000100 | P30: Asiento de CAJA (01/09/2025 - 31/08/2026) | Q30: Extracción de Caja 001500000100 Obs: 14-12-2025 Mov Lodge | R30: DT - Pago salario Andrés del 26/11 al 13/12 | S30: 000000000111 | T30: Ejercicio 2025/2026
D31: DEL | E31: =+VLOOKUP(F31,Resumen_Base!$B$6:$F$69,5,0) -> Services/House | F31: 5226 | G31: Remuneraciones Servicios | H31: =+D31&F31 -> DEL5226 | I31: 573300 | J31: 390 | K31: 1470 | L31: 31/12/2025 | M31: CAJA | N31: 0141 | O31: TE001500000119 | P31: Asiento de CAJA (01/09/2025 - 31/08/2026) | Q31: Extracción de Caja 001500000119 Obs: 31-12-2025 Mov Lodge | R31: DT - Pago salario Andrés por 6 full day | S31: 000000000121 | T31: Ejercicio 2025/2026
D32: DEL | E32: =+VLOOKUP(F32,Resumen_Base!$B$6:$F$69,5,0) -> Services/House | F32: 5226 | G32: Remuneraciones Servicios | H32: =+D32&F32 -> DEL5226 | I32: 1022400 | J32: 720 | K32: 1420 | L32: 14/12/2025 | M32: CAJA | N32: 0141 | O32: TE001500000100 | P32: Asiento de CAJA (01/09/2025 - 31/08/2026) | Q32: Extracción de Caja 001500000100 Obs: 14-12-2025 Mov Lodge | R32: DT - Pago salario Karina del 26/11 al 13/12 | S32: 000000000111 | T32: Ejercicio 2025/2026
D33: DEL | E33: =+VLOOKUP(F33,Resumen_Base!$B$6:$F$69,5,0) -> Services/House | F33: 5226 | G33: Remuneraciones Servicios | H33: =+D33&F33 -> DEL5226 | I33: 161998 | J33: 114.0831 | K33: 1420 | L33: 19/12/2025 | M33: CAJA | N33: 0141 | O33: TE001500000111 | P33: Asiento de CAJA (01/09/2025 - 31/08/2026) | Q33: Extracción de Caja 001500000111 Obs: Movimiento_Cajas_Bancos_Semana 25-26 al 19-12-2025 | R33: DT-Alexis Carra - SAC DIC 25 - mantenimiento Pagos Frank Garrahan-. Al 19-12-2025 | S33: 000000000116 | T33: Ejercicio 2025/2026
D34: DEL | E34: =+VLOOKUP(F34,Resumen_Base!$B$6:$F$69,5,0) -> Services/House | F34: 5226 | G34: Remuneraciones Servicios | H34: =+D34&F34 -> DEL5226 | I34: 1176000 | J34: 800 | K34: 1470 | L34: 31/12/2025 | M34: CAJA | N34: 0141 | O34: TE001500000135 | P34: Asiento de CAJA (01/09/2025 - 31/08/2026) | Q34: Extracción de Caja 001500000135 Obs: Movimiento_Cajas_Bancos_Semana 25-26 al 02-01-2026 | R34: DT-Supervisión Luis Chua - 26/11 al 5/12 F.Fijo Oper. Al 02-02-2026 | S34: 000000000128 | T34: Ejercicio 2025/2026
D35: DEL | E35: =+VLOOKUP(F35,Resumen_Base!$B$6:$F$69,5,0) -> Services/House | F35: 5226 | G35: Remuneraciones Servicios | H35: =+D35&F35 -> DEL5226 | I35: 1136000 | J35: 800 | K35: 1420 | L35: 26/12/2025 | M35: CAJA | N35: 0141 | O35: TE001500000114 | P35: Asiento de CAJA (01/09/2025 - 31/08/2026) | Q35: Extracción de Caja 001500000114 Obs: Movimiento_Cajas_Bancos_Semana 25-26 al 26-12-2025 | R35: DT-Supervisión Luis Chua 26/11 al 5/12 - 10 dias a 80 usd F.Fijo Oper. Al 26-12-2025 | S35: 000000000119 | T35: Ejercicio 2025/2026
D36: DEL | E36: =+VLOOKUP(F36,Resumen_Base!$B$6:$F$69,5,0) -> Guides | F36: 5227 | G36: Remuneraciones Guías | H36: =+D36&F36 -> DEL5227 | I36: 2425500 | J36: 1650 | K36: 1470 | L36: 31/12/2025 | M36: CAJA | N36: 0141 | O36: TE001500000119 | P36: Asiento de CAJA (01/09/2025 - 31/08/2026) | Q36: Extracción de Caja 001500000119 Obs: 31-12-2025 Mov Lodge | R36: DT - Pago a Pablo guía | S36: 000000000121 | T36: Ejercicio 2025/2026
D37: DEL | E37: =+VLOOKUP(F37,Resumen_Base!$B$6:$F$69,5,0) -> Guides | F37: 5227 | G37: Remuneraciones Guías | H37: =+D37&F37 -> DEL5227 | I37: 30000 | J37: 21.126761 | K37: 1420 | L37: 14/12/2025 | M37: CAJA | N37: 0141 | O37: TE001500000101 | P37: Asiento de CAJA (01/09/2025 - 31/08/2026) | Q37: Extracción de Caja 001500000101 Obs: 14-12-2025 Mov Lodge | R37: DT - Pago complemento a Matías guía en pesos por falta de cambio en usd | S37: 000000000112 | T37: Ejercicio 2025/2026
... D80: DEL | E80: =+VLOOKUP(F80,Resumen_Base!$B$6:$F$69,5,0) -> Maintenance Lodge | F80: 5252 | G80: Mantenimiento Rep-Lodge | H80: =+D80&F80 -> DEL5252 | I80: 263966 | J80: 179.56871 | K80: 1470 | L80: 31/12/2025 | M80: CAJA | N80: 0141 | O80: TE001500000120 | P80: Asiento de CAJA (01/09/2025 - 31/08/2026) | Q80: Extracción de Caja 001500000120 Obs: 31-12-2025 Mov Lodge | R80: DT - Compras supermercado coto | S80: 000000000122 | T80: Ejercicio 2025/2026
A81: 5252 | B81: 5220 | D81: DEL | E81: =+VLOOKUP(F81,Resumen_Base!$B$6:$F$69,5,0) -> Maintenance Lodge | F81: 5252 | G81: Mantenimiento Rep-Lodge | H81: =+D81&F81 -> DEL5252 | I81: 139000 | J81: 94.557823 | K81: 1470 | L81: 31/12/2025 | M81: CAJA | N81: 0141 | O81: TE001500000120 | P81: Asiento de CAJA (01/09/2025 - 31/08/2026) | Q81: Extracción de Caja 001500000120 Obs: 31-12-2025 Mov Lodge | R81: DT - Indumentaria de trabajo para Alexis | S81: 000000000122 | T81: Ejercicio 2025/2026
D82: DEL | E82: =+VLOOKUP(F82,Resumen_Base!$B$6:$F$69,5,0) -> Maintenance Lodge | F82: 5252 | G82: Mantenimiento Rep-Lodge | H82: =+D82&F82 -> DEL5252 | I82: 28000 | J82: 19.71831 | K82: 1420 | L82: 07/12/2025 | M82: CAJA | N82: 0141 | O82: TE001500000091 | P82: Asiento de CAJA (01/09/2025 - 31/08/2026) | Q82: Extracción de Caja 001500000091 Obs: 07-12-2025 Mov Lodge | R82: DT - Lavadero las marias | S82: 000000000087 | T82: Ejercicio 2025/2026
D83: DEL | E83: =+VLOOKUP(F83,Resumen_Base!$B$6:$F$69,5,0) -> Maintenance Lodge | F83: 5252 | G83: Mantenimiento Rep-Lodge | H83: =+D83&F83 -> DEL5252 | I83: 131400 | J83: 89.387755 | K83: 1470 | L83: 31/12/2025 | M83: CAJA | N83: 0141 | O83: TE001500000120 | P83: Asiento de CAJA (01/09/2025 - 31/08/2026) | Q83: Extracción de Caja 001500000120 Obs: 31-12-2025 Mov Lodge | R83: DT - Pago a Ecosec por servicio de lavado de blanqueria | S83: 000000000122 | T83: Ejercicio 2025/2026
D84: DEL | E84: =+VLOOKUP(F84,Resumen_Base!$B$6:$F$69,5,0) -> Maintenance Lodge | F84: 5252 | G84: Mantenimiento Rep-Lodge | H84: =+D84&F84 -> DEL5252 | I84: 40000 | J84: 28.169014 | K84: 1420 | L84: 07/12/2025 | M84: CAJA | N84: 0141 | O84: TE001500000091 | P84: Asiento de CAJA (01/09/2025 - 31/08/2026) | Q84: Extracción de Caja 001500000091 Obs: 07-12-2025 Mov Lodge | R84: DT - Pago a gasista | S84: 000000000087 | T84: Ejercicio 2025/2026
D85: DEL | E85: =+VLOOKUP(F85,Resumen_Base!$B$6:$F$69,5,0) -> Maintenance Lodge | F85: 5252 | G85: Mantenimiento Rep-Lodge | H85: =+D85&F85 -> DEL5252 | I85: 20000 | J85: 14.084507 | K85: 1420 | L85: 07/12/2025 | M85: CAJA | N85: 0141 | O85: TE001500000091 | P85: Asiento de CAJA (01/09/2025 - 31/08/2026) | Q85: Extracción de Caja 001500000091 Obs: 07-12-2025 Mov Lodge | R85: DT - Pago a rolando por llevarse basura del Lodge | S85: 000000000087 | T85: Ejercicio 2025/2026
D86: DEL | E86: =+VLOOKUP(F86,Resumen_Base!$B$6:$F$69,5,0) -> Maintenance Lodge | F86: 5252 | G86: Mantenimiento Rep-Lodge | H86: =+D86&F86 -> DEL5252 | I86: 6000 | J86: 4.2253521 | K86: 1420 | L86: 14/12/2025 | M86: CAJA | N86: 0141 | O86: TE001500000101 | P86: Asiento de CAJA (01/09/2025 - 31/08/2026) | Q86: Extracción de Caja 001500000101 Obs: 14-12-2025 Mov Lodge | R86: DT - Pico manguera para riego | S86: 000000000112 | T86: Ejercicio 2025/2026
...

Sheet Mov_Analizados_Ene26
G2: Ver Telefonos
G3: Ver Gastos devengados | I3: $ | J3: USD | K3: TC
G4: Ver Luz Devengada | H4: Food & Wine | I4: =+SUMIF($E$10:$E$243,H4,$I$10:$I$243) -> 11715963 | J4: =+SUMIF($E$10:$E$243,H4,$J$10:$J$243) -> 7935.0283 | K4: =+I4/J4 -> 1476.4866
G7: =+IF(I7+J7=0,"Ok","Check") -> Ok | I7: =ROUND(SUM(I10:I625),0) -> 0 | J7: =ROUND(SUM(J10:J625),0) -> 0
E8: Rubro | G8: =+Resumen_Base!C1 -> Ok
B9: =+F9&G9 | D9: DEL | E9: =+VLOOKUP(F9,Resumen_Base!$B$6:$F$69,5,0) -> #N/A | H9: =+D9&F9 -> DEL | I9: =SUM(I10:I243) -> 41028183 | J9: =SUM(J10:J243) -> 30923.554
B10: Cuenta Anterior | D10: Lodge | E10: Concepto | F10: Cuenta | G10: Nombre | I10: monto $ | J10: monto USD | K10: TC | L10: Fecha | M10: Subdiario | N10: Div | O10: Datos del comprobante | P10: Sujeto | Q10: CUIT | R10: Observación asiento | S10: Clase de Asiento | T10: Origen del comprobante | U10: Observación del comprobante | V10: Comentario renglón asiento | W10: Asiento | X10: Control | Z10: monto USD | AA10: tc | AC10: Fecha | AD10: Subdiario | AE10: Div | AF10: Datos del comprobante | AG10: Sujeto | AH10: CUIT | AI10: Observación asiento | AJ10: Clase de Asiento | AK10: Origen del comprobante | AL10: Observación del comprobante | AM10: Comentario renglón asiento | AN10: Asiento
C12: =+VLOOKUP(F12,Resumen_Base!$B$7:$F$69,5,0) -> Fixed Asset's Payments (Investments) Mejoras/equipamiento Lodge | D12: DEL | E12: =+VLOOKUP(F12,Resumen_Base!$B$6:$F$69,5,0) -> Fixed Asset's Payments (Investments) Mejoras/equipamiento Lodge | F12: 12020301 | G12: Muebles y útiles | H12: =+D12&F12 -> DEL12020301 | I12: 179000 | J12: 120.94595 | K12: 1480 | L12: 23/01/2026 | M12: CAJA | N12: 0141 | O12: TE001500000148 | P12: Asiento de CAJA (01/09/2025 - 310126) | Q12: Extracción de Caja 001500000148 Obs: Movimiento_Cajas_Bancos_Semana 25-26 al 23-01-2026 | R12: DT-Compra 1 termo Stanley 1.5 litros F.Fijo Oper. Al 23-01-2026 | S12: 000000000163 | T12: Ejercicio 2025/2026
A13: 5252 | B13: 12020301 | C13: =+VLOOKUP(F13,Resumen_Base!$B$7:$F$69,5,0) -> Maintenance Lodge | D13: DEL | E13: =+VLOOKUP(F13,Resumen_Base!$B$6:$F$69,5,0) -> Maintenance Lodge | F13: 5252 | G13: Mantenimiento Rep-Lodge | H13: =+D13&F13 -> DEL5252 | I13: 49999 | J13: 34.012925 | K13: 1470 | L13: 09/01/2026 | M13: CAJA | N13: 0141 | O13: TE001500000123 | P13: Asiento de CAJA (01/09/2025 - 31/08/2026) | Q13: Extracción de Caja 001500000123 Obs: Movimiento_Cajas_Bancos_Semana 25-26 al 09-01-2026 | R13: DT-Compra licuadora de vaso 1.5 litros F.Fijo Oper. Al 09-01-2026 | S13: 000000000125 | T13: Ejercicio 2025/2026
C14: =+VLOOKUP(F14,Resumen_Base!$B$7:$F$69,5,0) -> Fixed Asset's Payments (Investments) Mejoras/equipamiento Lodge | D14: DEL | E14: =+VLOOKUP(F14,Resumen_Base!$B$6:$F$69,5,0) -> Fixed Asset's Payments (Investments) Mejoras/equipamiento Lodge | F14: 12020301 | G14: Muebles y útiles | H14: =+D14&F14 -> DEL12020301 | I14: 158175 | J14: 107.60204 | K14: 1470 | L14: 09/01/2026 | M14: CAJA | N14: 0141 | O14: TE001500000123 | P14: Asiento de CAJA (01/09/2025 - 31/08/2026) | Q14: Extracción de Caja 001500000123 Obs: Movimiento_Cajas_Bancos_Semana 25-26 al 09-01-2026 | R14: DT-Compra microondas Rca para staff F.Fijo Oper. Al 09-01-2026 | S14: 000000000125 | T14: Ejercicio 2025/2026
A15: 5252 | B15: 12020301 | C15: =+VLOOKUP(F15,Resumen_Base!$B$7:$F$69,5,0) -> Maintenance Lodge | D15: DEL | E15: =+VLOOKUP(F15,Resumen_Base!$B$6:$F$69,5,0) -> Maintenance Lodge | F15: 5252 | G15: Mantenimiento Rep-Lodge | H15: =+D15&F15 -> DEL5252 | I15: 55057.6 | J15: 37.201081 | K15: 1480 | L15: 23/01/2026 | M15: CAJA | N15: 0141 | O15: TE001500000148 | P15: Asiento de CAJA (01/09/2025 - 310126) | Q15: Extracción de Caja 001500000148 Obs: Movimiento_Cajas_Bancos_Semana 25-26 al 23-01-2026 | R15: DT-Compra tabla lazy susan marmol acacia F.Fijo Oper. Al 23-01-2026 | S15: 000000000163 | T15: Ejercicio 2025/2026
C16: =+VLOOKUP(F16,Resumen_Base!$B$7:$F$69,5,0) -> Fixed Asset's Payments (Investments) Mejoras/equipamiento Lodge | D16: DEL | E16: =+VLOOKUP(F16,Resumen_Base!$B$6:$F$69,5,0) -> Fixed Asset's Payments (Investments) Mejoras/equipamiento Lodge | F16: 12020601 | G16: Ropa Blanca | H16: =+D16&F16 -> DEL12020601 | I16: 2760000 | J16: 1877.551 | K16: 1470 | L16: 09/01/2026 | M16: CAJA | N16: 0141 | O16: TE001500000123 | P16: Asiento de CAJA (01/09/2025 - 31/08/2026) | Q16: Extracción de Caja 001500000123 Obs: Movimiento_Cajas_Bancos_Semana 25-26 al 09-01-2026 | R16: DT-16 paños para 4 habitación - cortiñas black out - Flopy Ganly F.Fijo Oper. Al 09-01-2026 | S16: 000000000125 | T16: Ejercicio 2025/2026
C17: =+VLOOKUP(F17,Resumen_Base!$B$7:$F$69,5,0) -> Fixed Asset's Payments (Investments) Rodados/Lanchas | D17: DEL | E17: =+VLOOKUP(F17,Resumen_Base!$B$6:$F$69,5,0) -> Fixed Asset's Payments (Investments) Rodados/Lanchas | F17: 12020701 | G17: Lanchas y Botes | H17: =+D17&F17 -> DEL12020701 | I17: 2960000 | J17: 2000 | K17: 1480 | L17: 16/01/2026 | M17: CAJA | N17: 0141 | O17: TE001500000141 | P17: Asiento de CAJA (01/09/2025 - 310126) | Q17: Extracción de Caja 001500000141 Obs: Movimiento_Cajas_Bancos_Semana 25-26 al 16-01-2026 | R17: DT-GPS / Ecosonda + Carta Nautica de Lancha Salminus -retiró Noel F.Fijo Oper. Al 16-01-2026 | S17: 000000000159 | T17: Ejercicio 2025/2026
C18: =+VLOOKUP(F18,Resumen_Base!$B$7:$F$69,5,0) -> Shop | D18: DEL | E18: =+VLOOKUP(F18,Resumen_Base!$B$6:$F$69,5,0) -> Shop | F18: 4104 | G18: Ventas Shop | H18: =+D18&F18 -> DEL4104 | I18: -88800 | J18: -60 | K18: 1480 | L18: 14/01/2026 | M18: VENTAS | N18: 0141 | O18: VF000000003704B | P18: Asiento de VENTAS (01/09/2025 - 31/1/2026) | Q18: F B 000000003704 | R18: Ref. nota de Venta: DEL10 Obs.:26-01-2026_CLIENTES | S18: 000000000196 | T18: Ejercicio 2025/2026
C19: =+VLOOKUP(F19,Resumen_Base!$B$7:$F$69,5,0) -> Shop | D19: DEL | E19: =+VLOOKUP(F19,Resumen_Base!$B$6:$F$69,5,0) -> Shop | F19: 4104 | G19: Ventas Shop | H19: =+D19&F19 -> DEL4104 | I19: -88800 | J19: -60 | K19: 1480 | L19: 15/01/2026 | M19: VENTAS | N19: 0141 | O19: VF000000003708B | P19: Asiento de VENTAS (01/09/2025 - 31/1/2026) | Q19: F B 000000003708 | R19: Ref. nota de Venta: DEL37 Obs.:26-01-2026_CLIENTES | S19: 000000000200 | T19: Ejercicio 2025/2026
C20: =+VLOOKUP(F20,Resumen_Base!$B$7:$F$69,5,0) -> Canon Lodge/Labor Permits: | D20: DEL | E20: =+VLOOKUP(F20,Resumen_Base!$B$6:$F$69,5,0) -> Canon Lodge/Labor Permits: | F20: 5208 | G20: Alquileres y Canon | H20: =+D20&F20 -> DEL5208 | I20: 352000 | J20: 239.45578 | K20: 1470 | L20: 09/01/2026 | M20: CAJA | N20: 0141 | O20: TE001500000123 | P20: Asiento de CAJA (01/09/2025 - 31/08/2026) | Q20: Extracción de Caja 001500000123 Obs: Movimiento_Cajas_Bancos_Semana 25-26 al 09-01-2026 | R20: DT-Guarderia La Baie - cuota Enero Pagos Frank Garrahan Al 09-01-2026 | S20: 000000000125 | T20: Ejercicio 2025/2026
C21: =+VLOOKUP(F21,Resumen_Base!$B$7:$F$69,5,0) -> Canon Lodge/Labor Permits: | D21: DEL | E21: =+VLOOKUP(F21,Resumen_Base!$B$6:$F$69,5,0) -> Canon Lodge/Labor Permits: | F21: 5208 | G21: Alquileres y Canon | H21: =+D21&F21 -> DEL5208 | I21: 352000 | J21: 237.83784 | K21: 1480 | L21: 31/01/2026 | M21: CAJA | N21: 0141 | O21: TE001500000170 | P21: Asiento de CAJA (01/09/2025 - 310126) | Q21: Extracción de Caja 001500000170 Obs: Movimiento_Cajas_Bancos_Semana 25-26 al 06-02-2026 | R21: DT-Guarderia La Baie - cuota Febrero 2026 Pagos Depsa Valores. Al 06-02-2026 | S21: 000000000173 | T21: Ejercicio 2025/2026
C22: =+VLOOKUP(F22,Resumen_Base!$B$7:$F$69,5,0) -> Food & Wine | D22: DEL | E22: =+VLOOKUP(F22,Resumen_Base!$B$6:$F$69,5,0) -> Food & Wine | F22: 5213 | G22: Vinos | H22: =+D22&F22 -> DEL5213 | I22: 66500 | J22: 45.238095 | K22: 1470 | L22: 12/01/2026 | M22: CAJA | N22: 0141 | O22: TE001500000125 | P22: Asiento de CAJA (01/09/2025 - 31/08/2026) | Q22: Extracción de Caja 001500000125 Obs: 12-01-2026 Mov Lodge | R22: DT - Súper chino vinos | S22: 000000000126 | T22: Ejercicio 2025/2026
C23: =+VLOOKUP(F23,Resumen_Base!$B$7:$F$69,5,0) -> Food & Wine | D23: DEL | E23: =+VLOOKUP(F23,Resumen_Base!$B$6:$F$69,5,0) -> Food & Wine | F23: 5213 | G23: Vinos | H23: =+D23&F23 -> DEL5213 | I23: 1304896.5 | J23: 881.6868 | K23: 1480 | L23: 31/01/2026 | M23: CAJA | N23: 0141 | O23: TE001500000170 | P23: Asiento de CAJA (01/09/2025 - 310126) | Q23: Extracción de Caja 001500000170 Obs: Movimiento_Cajas_Bancos_Semana 25-26 al 06-02-2026 | R23: DT-Mix de Vinos - Pago Bressia Wines F.Fijo Oper. Al 06-02-2026 | S23: 000000000173 | T23: Ejercicio 2025/2026
C24: =+VLOOKUP(F24,Resumen_Base!$B$7:$F$69,5,0) -> Food & Wine | D24: DEL | E24: =+VLOOKUP(F24,Resumen_Base!$B$6:$F$69,5,0) -> Food & Wine | F24: 5213 | G24: Vinos | H24: =+D24&F24 -> DEL5213 | I24: 881000 | J24: 595.27027 | K24: 1480 | L24: 23/01/2026 | M24: CAJA | N24: 0141 | O24: TE001500000148 | P24: Asiento de CAJA (01/09/2025 - 310126) | Q24: Extracción de Caja 001500000148 Obs: Movimiento_Cajas_Bancos_Semana 25-26 al 23-01-2026 | R24: DT-Pedido Catena - 18 cajas de vino F.Fijo Oper. Al 23-01-2026 | S24: 000000000163 | T24: Ejercicio 2025/2026
C25: =+VLOOKUP(F25,Resumen_Base!$B$7:$F$69,5,0) -> Miscellaneous & Shipping | D25: DEL | E25: =+VLOOKUP(F25,Resumen_Base!$B$6:$F$69,5,0) -> Miscellaneous & Shipping | F25: 5219 | G25: Gastos Varios | H25: =+D25&F25 -> DEL5219 | I25: 91340 | J25: 61.716216 | K25: 1480 | L25: 16/01/2026 | M25: CAJA | N25: 0141 | O25: TE001500000142 | P25: Asiento de CAJA (01/09/2025 - 310126) | Q25: Extracción de Caja 001500000142 Obs: Movimiento_Cajas_Bancos_Semana 25-26 al 16-01-2026 | R25: DT-Saldo 50 % - Latin Gráfica - impresión brochures x 20 unidades F.Fijo Oper. Al 16-01-2026 | S25: 000000000160 | T25: Ejercicio 2025/2026
C26: =+VLOOKUP(F26,Resumen_Base!$B$7:$F$69,5,0) -> Services/House | D26: DEL | E26: =+VLOOKUP(F26,Resumen_Base!$B$6:$F$69,5,0) -> Services/House | F26: 5226 | G26: Remuneraciones Servicios | H26: =+D26&F26 -> DEL5226 | I26: 1915120 | J26: 1294 | K26: 1480 | L26: 30/01/2026 | M26: CAJA | N26: 0141 | O26: TE001500000161 | P26: Asiento de CAJA (01/09/2025 - 310126) | Q26: Extracción de Caja 001500000161 Obs: Reversión de documento | R26: DEL- Reintegro Sueldos TA 01-2026 - Servicios | S26: 000000000168 | T26: Ejercicio 2025/2026
C27: =+VLOOKUP(F27,Resumen_Base!$B$7:$F$69,5,0) -> Services/House | D27: DEL | E27: =+VLOOKUP(F27,Resumen_Base!$B$6:$F$69,5,0) -> Services/House | F27: 5226 | G27: Remuneraciones Servicios | H27: =+D27&F27 -> DEL5226 | I27: 1915120 | J27: 1294 | K27: 1480 | L27: 30/01/2026 | M27: CAJA | N27: 0141 | O27: TE001500000165 | P27: Asiento de CAJA (01/09/2025 - 310126) | Q27: Extracción de Caja 001500000165 Obs: Movimiento_Cajas_Bancos_Semana 25-26 al 30-01-2026 | R27: DEL- Reintegro Sueldos TA 01-2026 - Servicios | S27: 000000000172 | T27: Ejercicio 2025/2026
... C29: =+VLOOKUP(F29,Resumen_Base!$B$7:$F$69,5,0) -> Services/House | D29: DEL | E29: =+VLOOKUP(F29,Resumen_Base!$B$6:$F$69,5,0) -> Services/House | F29: 5226 | G29: Remuneraciones Servicios | H29: =+D29&F29 -> DEL5226 | I29: 280000 | J29: 189.18919 | K29: 1480 | L29: 26/01/2026 | M29: CAJA | N29: 0141 | O29: TE001500000145 | P29: Asiento de CAJA (01/09/2025 - 310126) | Q29: Extracción de Caja 001500000145 Obs: 26-01-2026 Mov Lodge | R29: DT - Adicional a Alexis por cubrir 4 días a Noel | S29: 000000000161 | T29: Ejercicio 2025/2026
A30: 5252 | B30: 5226 | C30: =+VLOOKUP(F30,Resumen_Base!$B$7:$F$69,5,0) -> Maintenance Lodge | D30: DEL | E30: =+VLOOKUP(F30,Resumen_Base!$B$6:$F$69,5,0) -> Maintenance Lodge | F30: 5252 | G30: Mantenimiento Rep-Lodge | H30: =+D30&F30 -> DEL5252 | I30: 80000 | J30: 54.054054 | K30: 1480 | L30: 26/01/2026 | M30: CAJA | N30: 0141 | O30: TE001500000145 | P30: Asiento de CAJA (01/09/2025 - 310126) | Q30: Extracción de Caja 001500000145 Obs: 26-01-2026 Mov Lodge | R30: DT - Alexis corte de pasto y poda con su tío en días de descanso | S30: 000000000161 | T30: Ejercicio 2025/2026
A31: 5252 | B31: 5226 | C31: =+VLOOKUP(F31,Resumen_Base!$B$7:$F$69,5,0) -> Maintenance Lodge | D31: DEL | E31: =+VLOOKUP(F31,Resumen_Base!$B$6:$F$69,5,0) -> Maintenance Lodge | F31: 5252 | G31: Mantenimiento Rep-Lodge | H31: =+D31&F31 -> DEL5252 | I31: 20000 | J31: 13.513514 | K31: 1480 | L31: 26/01/2026 | M31: CAJA | N31: 0141 | O31: TE001500000145 | P31: Asiento de CAJA (01/09/2025 - 310126) | Q31: Extracción de Caja 001500000145 Obs: 26-01-2026 Mov Lodge | R31: DT - Alexis de hachero durante 1 servicio de 9 pax | S31: 000000000161 | T31: Ejercicio 2025/2026
C32: =+VLOOKUP(F32,Resumen_Base!$B$7:$F$69,5,0) -> Services/House | D32: DEL | E32: =+VLOOKUP(F32,Resumen_Base!$B$6:$F$69,5,0) -> Services/House | F32: 5226 | G32: Remuneraciones Servicios | H32: =+D32&F32 -> DEL5226 | I32: 444000 | J32: 300 | K32: 1480 | L32: 26/01/2026 | M32: CAJA | N32: 0141 | O32: TE001500000146 | P32: Asiento de CAJA (01/09/2025 - 310126) | Q32: Extracción de Caja 001500000146 Obs: 26-01-2026 Mov Lodge | R32: DT - Lucia ayudante de cocina 6fd | S32: 000000000162 | T32: Ejercicio 2025/2026
A33: 5291 | B33: 5226 | C33: =+VLOOKUP(F33,Resumen_Base!$B$7:$F$69,5,0) -> Food & Wine | D33: DEL | E33: =+VLOOKUP(F33,Resumen_Base!$B$6:$F$69,5,0) -> Food & Wine | F33: 5291 | G33: Comida / Fletes | H33: =+D33&F33 -> DEL5291 | I33: 20000 | J33: 13.605442 | K33: 1470 | L33: 12/01/2026 | M33: CAJA | N33: 0141 | O33: TE001500000125 | P33: Asiento de CAJA (01/09/2025 - 31/08/2026) | Q33: Extracción de Caja 001500000125 Obs: 12-01-2026 Mov Lodge | R33: DT - Pago a Alexis por 2 viajes añde compras que realizó | S33: 000000000126 | T33: Ejercicio 2025/2026
C34: =+VLOOKUP(F34,Resumen_Base!$B$7:$F$69,5,0) -> Services/House | D34: DEL | E34: =+VLOOKUP(F34,Resumen_Base!$B$6:$F$69,5,0) -> Services/House | F34: 5226 | G34: Remuneraciones Servicios | H34: =+D34&F34 -> DEL5226 | I34: 296000 | J34: 200 | K34: 1480 | L34: 31/01/2026 | M34: CAJA | N34: 0141 | O34: TE001500000153 | P34: Asiento de CAJA (01/09/2025 - 310126) | Q34: Extracción de Caja 001500000153 Obs: 31-01-2026 Mov Lodge | R34: DT - Pago a lucia por 4 full day | S34: 000000000166 | T34: Ejercicio 2025/2026
A35: 5291 | B35: 5226 | C35: =+VLOOKUP(F35,Resumen_Base!$B$7:$F$69,5,0) -> Food & Wine | D35: DEL | E35: =+VLOOKUP(F35,Resumen_Base!$B$6:$F$69,5,0) -> Food & Wine | F35: 5291 | G35: Comida / Fletes | H35: =+D35&F35 -> DEL5291 | I35: 20000 | J35: 13.605442 | K35: 1470 | L35: 12/01/2026 | M35: CAJA | N35: 0141 | O35: TE001500000125 | P35: Asiento de CAJA (01/09/2025 - 31/08/2026) | Q35: Extracción de Caja 001500000125 Obs: 12-01-2026 Mov Lodge | R35: DT - Pago a Rolando por ayudarnos con la carga y descarga día de compras | S35: 000000000126 | T35: Ejercicio 2025/2026
C36: =+VLOOKUP(F36,Resumen_Base!$B$7:$F$69,5,0) -> Services/House | D36: DEL | E36: =+VLOOKUP(F36,Resumen_Base!$B$6:$F$69,5,0) -> Services/House | F36: 5226 | G36: Remuneraciones Servicios | H36: =+D36&F36 -> DEL5226 | I36: 44850 | J36: 30.304054 | K36: 1480 | L36: 26/01/2026 | M36: CAJA | N36: 0141 | O36: TE001500000145 | P36: Asiento de CAJA (01/09/2025 - 310126) | Q36: Extracción de Caja 001500000145 Obs: 26-01-2026 Mov Lodge | R36: DT - Pago complementario a lucia por ayuda en cocina | S36: 000000000161 | T36: Ejercicio 2025/2026
C37: =+VLOOKUP(F37,Resumen_Base!$B$7:$F$69,5,0) -> Services/House | D37: DEL | E37: =+VLOOKUP(F37,Resumen_Base!$B$6:$F$69,5,0) -> Services/House | F37: 5226 | G37: Remuneraciones Servicios | H37: =+D37&F37 -> DEL5226 | I37: 29500 | J37: 19.932432 | K37: 1480 | L37: 31/01/2026 | M37: CAJA | N37: 0141 | O37: TE001500000152 | P37: Asiento de CAJA (01/09/2025 - 310126) | Q37: Extracción de Caja 001500000152 Obs: 31-01-2026 Mov Lodge | R37: DT - Pago complementario lucia por 4 full day 20-usd pago $ a cotización 1475 | S37: 000000000165 | T37: Ejercicio 2025/2026
C38: =+VLOOKUP(F38,Resumen_Base!$B$7:$F$69,5,0) -> Services/House | D38: DEL | E38: =+VLOOKUP(F38,Resumen_Base!$B$6:$F$69,5,0) -> Services/House | F38: 5226 | G38: Remuneraciones Servicios | H38: =+D38&F38 -> DEL5226 | I38: 317667 | J38: 216.1 | K38: 1470 | L38: 09/01/2026 | M38: CAJA | N38: 0141 | O38: TE001500000123 | P38: Asiento de CAJA (01/09/2025 - 31/08/2026) | Q38: Extracción de Caja 001500000123 Obs: Movimiento_Cajas_Bancos_Semana 25-26 al 09-01-2026 | R38: DT-Alexis Carra - Honorarios mantenimiento diciembre Pagos Frank Garrahan Al 09-01-2026 | S38: 000000000125 | T38: Ejercicio 2025/2026
C39: =+VLOOKUP(F39,Resumen_Base!$B$7:$F$69,5,0) -> Services/House | D39: DEL | E39: =+VLOOKUP(F39,Resumen_Base!$B$6:$F$69,5,0) -> Services/House | F39: 5226 | G39: Remuneraciones Servicios | H39: =+D39&F39 -> DEL5226 | I39: 309481 | J39: 209.10878 | K39: 1480 | L39: 31/01/2026 | M39: CAJA | N39: 0141 | O39: TE001500000170 | P39: Asiento de CAJA (01/09/2025 - 310126) | Q39: Extracción de Caja 001500000170 Obs: Movimiento_Cajas_Bancos_Semana 25-26 al 06-02-2026 | R39: DT-Alexis Carra - Honorarios mantenimiento Enero 2026 Pagos Depsa Valores. Al 06-02-2026 | S39: 000000000173 | T39: Ejercicio 2025/2026
C40: =+VLOOKUP(F40,Resumen_Base!$B$7:$F$69,5,0) -> Guides | D40: DEL | E40: =+VLOOKUP(F40,Resumen_Base!$B$6:$F$69,5,0) -> Guides | F40: 5227 | G40: Remuneraciones Guías | H40: =+D40&F40 -> DEL5227 | I40: 1184000 | J40: 800 | K40: 1480 | L40: 26/01/2026 | M40: CAJA | N40: 0141 | O40: TE001500000146 | P40: Asiento de CAJA (01/09/2025 - 310126) | Q40: Extracción de Caja 001500000146 Obs: 26-01-2026 Mov Lodge | R40: DT - Matías guía por 2 full day y 3 half day | S40: 000000000162 | T40: Ejercicio 2025/2026
C41: =+VLOOKUP(F41,Resumen_Base!$B$7:$F$69,5,0) -> Guides | D41: DEL | E41: =+VLOOKUP(F41,Resumen_Base!$B$6:$F$69,5,0) -> Guides | F41: 5227 | G41: Remuneraciones Guías | H41: =+D41&F41 -> DEL5227 | I41: 1332000 | J41: 900 | K41: 1480 | L41: 26/01/2026 | M41: CAJA | N41: 0141 | O41: TE001500000146 | P41: Asiento de CAJA (01/09/2025 - 310126) | Q41: Extracción de Caja 001500000146 Obs: 26-01-2026 Mov Lodge | R41: DT - Pablo guía 3 fd | S41: 000000000162 | T41: Ejercicio 2025/2026
C42: =+VLOOKUP(F42,Resumen_Base!$B$7:$F$69,5,0) -> Guides | D42: DEL | E42: =+VLOOKUP(F42,Resumen_Base!$B$6:$F$69,5,0) -> Guides | F42: 5227 | G42: Remuneraciones Guías | H42: =+D42&F42 -> DEL5227 | I42: 3848000 | J42: 2600 | K42: 1480 | L42: 26/01/2026 | M42: CAJA | N42: 0141 | O42: TE001500000146 | P42: Asiento de CAJA (01/09/2025 - 310126) | Q42: Extracción de Caja 001500000146 Obs: 26-01-2026 Mov Lodge | R42: DT - Pablo guía por 7 full day | S42: 000000000162 | T42: Ejercicio 2025/2026
C43: =+VLOOKUP(F43,Resumen_Base!$B$7:$F$69,5,0) -> Guides | D43: DEL | E43: =+VLOOKUP(F43,Resumen_Base!$B$6:$F$69,5,0) -> Guides | F43: 5227 | G43: Remuneraciones Guías | H43: =+D43&F43 -> DEL5227 | I43: 2960000 | J43: 2000 | K43: 1480 | L43: 30/01/2026 | M43: CAJA | N43: 0141 | O43: TE001500000161 | P43: Asiento de CAJA (01/09/2025 - 310126) | Q43: Extracción de Caja 001500000161 Obs: Reversión de documento | R43: DT- Fee Noel 01-2026 | S43: 000000000168 | T43: Ejercicio 2025/2026
C44: =+VLOOKUP(F44,Resumen_Base!$B$7:$F$69,5,0) -> Guides | D44: DEL | E44: =+VLOOKUP(F44,Resumen_Base!$B$6:$F$69,5,0) -> Guides | F44: 5227 | G44: Remuneraciones Guías | H44: =+D44&F44 -> DEL5227 | I44: 2960000 | J44: 2000 | K44: 1480 | L44: 30/01/2026 | M44: CAJA | N44: 0141 | O44: TE001500000165 | P44: Asiento de CAJA (01/09/2025 - 310126) | Q44: Extracción de Caja 001500000165 Obs: Movimiento_Cajas_Bancos_Semana 25-26 al 30-01-2026 | R44: DT- Fee Noel 01-2026 | S44: 000000000172 | T44: Ejercicio 2025/2026
C45: =+VLOOKUP(F45,Resumen_Base!$B$7:$F$69,5,0) -> Guides | D45: DEL | E45: =+VLOOKUP(F45,Resumen_Base!$B$6:$F$69,5,0) -> Guides | F45: 5227 | G45: Remuneraciones Guías | H45: =+D45&F45 -> DEL5227 | I45: -2960000 | J45: -2000 | K45: 1480 | L45: 30/01/2026 | M45: CAJA | N45: 0141 | O45: TI001500000158 | P45: Asiento de CAJA (01/09/2025 - 310126) | Q45: Ingreso a Caja 001500000158 Obs: Movimiento_Cajas_Bancos_Semana 25-26 al 30-01-2026 | R45: DT- Fee Noel 01-2026 | S45: 000000000180 | T45: Ejercicio 2025/2026
...

Sheet Mov_Analizados_Feb26
G2: Ver Telefonos
G3: Ver Gastos devengados | I3: $ | J3: USD | K3: TC
G4: Ver Luz Devengada | H4: Food & Wine | I4: =+SUMIF($E$10:$E$259,H4,$I$10:$I$259) -> 5481342.5 | J4: =+SUMIF($E$10:$E$259,H4,$J$10:$J$259) -> 3853.3284 | K4: =+I4/J4 -> 1422.4955
G7: =+IF(I7+J7=0,"Ok","Check") -> Ok | I7: =ROUND(SUM(I10:I612),0) -> 0 | J7: =ROUND(SUM(J10:J612),0) -> 0
E8: Rubro | G8: =+Resumen_Base!C1 -> Ok
B9: =+F9&G9 | D9: DEL | E9: =+VLOOKUP(F9,Resumen_Base!$B$6:$F$69,5,0) -> #N/A | H9: =+D9&F9 -> DEL | I9: =SUM(I10:I259) -> 30528432 | J9: =SUM(J10:J259) -> 20615.661
B10: Cuenta Anterior | D10: Lodge | E10: Concepto | F10: Cuenta | G10: Nombre | I10: monto $ | J10: monto USD | K10: TC | L10: Fecha | M10: Subdiario | N10: Div | O10: Datos del comprobante | P10: Sujeto | Q10: CUIT | R10: Observación asiento | S10: Clase de Asiento | T10: Origen del comprobante | U10: Observación del comprobante | V10: Comentario renglón asiento | W10: Asiento | X10: Control | Z10: monto USD | AA10: tc | AC10: Fecha | AD10: Subdiario | AE10: Div | AF10: Datos del comprobante | AG10: Sujeto | AH10: CUIT | AI10: Observación asiento | AJ10: Clase de Asiento | AK10: Origen del comprobante | AL10: Observación del comprobante | AM10: Comentario renglón asiento | AN10: Asiento
C12: Delta | D12: DEL | E12: =+VLOOKUP(F12,Resumen_Base!$B$6:$F$69,5,0) -> Fixed Asset's Payments (Investments) Mejoras/equipamiento Lodge | F12: 12020103 | G12: Mejoras de Inmueb y Terrenos | H12: =+D12&F12 -> DEL12020103 | I12: 424500 | J12: 300 | K12: 1415 | L12: 28/02/2026 | M12: CAJA | N12: 0141 | O12: TE001500000199 | P12: Asiento de CAJA (01/09/2025 - 280226) | Q12: Extracción de Caja 001500000199 Obs: Movimiento_Cajas_Bancos_Semana 25-26 al 06-03-2026 | R12: DT-Honorarios Hector Natera por visita Lodges - monitoreo deinversores F.Fijo Oper. Al 06-03-2026 | S12: 000000000222 | T12: Ejercicio 2025/2026
