Workbook
Name _____Rt12: #REF!
Name _____Rt12: #REF!
Name _____Rt12: #REF!
Name _____Rt12: #REF!
Name ____Rt12: #REF!
Name ____Rt12: #REF!
Name ____Rt12: #REF!
Name ____Rt12: #REF!
Name ___Rt12: #REF!
Name ___Rt12: #REF!
Name ___Rt12: #REF!
Name ___Rt12: #REF!
Name __Rt12: #REF!
Name __Rt12: #REF!
Name __Rt12: #REF!
Name __Rt12: #REF!
Name _Rt12: #REF!
Name _Rt12: #REF!
Name _Rt12: #REF!
Name _Rt12: #REF!
Name A: #REF!
Name A: #REF!
Name AJUSTES: #REF!
Name AJUSTES: #REF!
Name AJUSTES: #REF!
Name AJUSTES: #REF!
Name AJUSTES: #REF!
Name AJUSTES: #REF!
Name AJUSTES: #REF!
Name AJUSTES: #REF!
Name AJUSTES: #REF!
Name AJUSTES: #REF!
Name Assumptions: #REF!
Name Assumptions: #REF!
Name Assumptions: #REF!
Name Assumptions: #REF!
Name BuiltIn_Print_Area: #REF!
Name BuiltIn_Print_Area: #REF!
Name BuiltIn_Print_Area: #REF!
Name BuiltIn_Print_Area: #REF!
Name BuiltIn_Print_Area___0: #REF!
Name BuiltIn_Print_Area___0: #REF!
Name BuiltIn_Print_Area___0: #REF!
Name BuiltIn_Print_Area___0: #REF!
Name BuiltIn_Print_Titles: #REF!
Name BuiltIn_Print_Titles: #REF!
Name BuiltIn_Print_Titles: #REF!
Name BuiltIn_Print_Titles: #REF!
Name BuiltIn_Print_Titles___0: #REF!
Name BuiltIn_Print_Titles___0: #REF!
Name BuiltIn_Print_Titles___0: #REF!
Name BuiltIn_Print_Titles___0: #REF!
Name CASH_FLOW: #N/A
Name CodigoLodge: #REF!
Name CodigoLodge: #REF!
Name CodigoLodge: #REF!
Name CodigoLodge: #REF!
Name Costo: #REF!
Name Costo: #REF!
Name Costo: #REF!

Sheet Ajustes y Comentarios

Sheet Mov_Analizados_Sept25 - Dic25
J1: =SUM(J2:J5) -> 200020.27 | K1: =+J1-J9 -> 0
G2: Ver Telefonos | I2: CAR | J2: =+SUMIF($D$10:$D$1038,I2,$J$10:$J$1038) -> 148947.6 | K2: =+J2-Resumen_Base!J220 -> 0
G3: Ver Gastos devengados | I3: SJ | J3: =+SUMIF($D$10:$D$1038,I3,$J$10:$J$1038) -> 23309.96 | K3: =+J3-Resumen_Base!J28 -> 0
G4: Ver Luz Devengada | I4: UL | J4: =+SUMIF($D$10:$D$1038,I4,$J$10:$J$1038) -> 27762.716 | K4: =+J4-Resumen_Base!J93 -> 0
G7: =+IF(I7+J7=0,"Ok","Check") -> Ok | I7: =ROUND(SUM(I10:I3108),0) -> 0 | J7: =ROUND(SUM(J10:J3108),0) -> 0
D8: FL | E8: Rubro | G8: =+Resumen_Base!D1 -> Ok
B9: =+F9&G9 | D9: =+VLOOKUP(F9,Resumen_Base!$C$8:$F$26,4,0) -> #N/A | E9: =+VLOOKUP(F9,Resumen_Base!$C$8:$G$287,5,0) -> #N/A | H9: =+D9&F9 -> #N/A | I9: =SUM(I10:I1038) -> 3.1037681e+08 | J9: =SUM(J10:J1038) -> 200020.27
A10: Ajustes | B10: Cuenta Anterior | D10: Lodge | E10: Concepto | F10: Codigo Cuenta | G10: Cuenta Contable | I10: Saldo - $ | J10: Saldo - u$s | K10: Tipo cambio | L10: Fecha | M10: Modulo | N10: Cod Centro Costo | O10: gestionid | P10: Detalle | Q10: Observaciones | R10: Observación Adicional | S10: Número | T10: Ejercicio | U10: Observación del comprobante | V10: Comentario renglón asiento | W10: Asiento | X10: Control | Z10: monto USD | AA10: tc | AC10: Fecha | AD10: Subdiario | AE10: Div | AF10: Datos del comprobante | AG10: Sujeto | AH10: CUIT | AI10: Observación asiento | AJ10: Clase de Asiento | AK10: Origen del comprobante | AL10: Observación del comprobante | AM10: Comentario renglón asiento | AN10: Asiento
D12: SJ | E12: =+VLOOKUP(F12,Resumen_Base!$C$8:$G$287,5,0) -> Fixed Asset's Payments (Investments) Mejoras/equipamiento Lodge | F12: 12020103 | G12: Mejoras de Inmueb y Terrenos | H12: =+D12&F12 -> SJ12020103 | I12: 903319.3 | J12: 649.87 | K12: 1390 | L12: 30/09/2025 | M12: CAJA | N12: 0121 | O12: TH001400000043 | P12: Asiento de CAJA (01/09/2025 - 31/08/2026) | Q12: Extracción de Banco 001400000043 Obs: 30-09-2025 Mov Lodge | R12: SJ - inversion inmuebles SJ | S12: 000000000072 | T12: Ejercicio 2025/2026
A13: ESTO ES TODO URUGUAY LODGE | D13: UL | E13: =+VLOOKUP(F13,Resumen_Base!$C$8:$G$287,5,0) -> Fixed Asset's Payments (Investments) Mejoras/equipamiento Lodge | F13: 12020103 | G13: Mejoras de Inmueb y Terrenos | H13: =+D13&F13 -> UL12020103 | I13: 9230000 | J13: 6500 | K13: 1420 | L13: 23/11/2025 | M13: CAJA | N13: 0121 | O13: TE001400000144 | P13: Asiento de CAJA (01/09/2025 - 31/08/2026) | Q13: Extracción de Caja 001400000144 Obs: 23-11-2025 Mov Lodge | R13: SJ - fachada valle de soba constructor | S13: 000000000222 | T13: Ejercicio 2025/2026
D14: UL | E14: =+VLOOKUP(F14,Resumen_Base!$C$8:$G$287,5,0) -> Fixed Asset's Payments (Investments) Mejoras/equipamiento Lodge | F14: 12020103 | G14: Mejoras de Inmueb y Terrenos | H14: =+D14&F14 -> UL12020103 | I14: 1420 | J14: 1 | K14: 1420 | L14: 16/11/2025 | M14: CAJA | N14: 0121 | O14: TH001400000125 | P14: Asiento de CAJA (01/09/2025 - 31/08/2026) | Q14: Extracción de Banco 001400000125 Obs: 16-11-2025 Mov Lodge | R14: SJ - deb comi | S14: 000000000230 | T14: Ejercicio 2025/2026
D15: UL | E15: =+VLOOKUP(F15,Resumen_Base!$C$8:$G$287,5,0) -> Fixed Asset's Payments (Investments) Mejoras/equipamiento Lodge | F15: 12020103 | G15: Mejoras de Inmueb y Terrenos | H15: =+D15&F15 -> UL12020103 | I15: 284000 | J15: 200 | K15: 1420 | L15: 16/11/2025 | M15: CAJA | N15: 0121 | O15: TH001400000125 | P15: Asiento de CAJA (01/09/2025 - 31/08/2026) | Q15: Extracción de Banco 001400000125 Obs: 16-11-2025 Mov Lodge | R15: SJ - obra valle ruben perez | S15: 000000000230 | T15: Ejercicio 2025/2026
D16: UL | E16: =+VLOOKUP(F16,Resumen_Base!$C$8:$G$287,5,0) -> Fixed Asset's Payments (Investments) Mejoras/equipamiento Lodge | F16: 12020103 | G16: Mejoras de Inmueb y Terrenos | H16: =+D16&F16 -> UL12020103 | I16: 710000 | J16: 500 | K16: 1420 | L16: 16/11/2025 | M16: CAJA | N16: 0121 | O16: TH001400000125 | P16: Asiento de CAJA (01/09/2025 - 31/08/2026) | Q16: Extracción de Banco 001400000125 Obs: 16-11-2025 Mov Lodge | R16: SJ - obra valle ruben perez | S16: 000000000230 | T16: Ejercicio 2025/2026
D17: UL | E17: =+VLOOKUP(F17,Resumen_Base!$C$8:$G$287,5,0) -> Fixed Asset's Payments (Investments) Mejoras/equipamiento Lodge | F17: 12020103 | G17: Mejoras de Inmueb y Terrenos | H17: =+D17&F17 -> UL12020103 | I17: 1420 | J17: 1 | K17: 1420 | L17: 16/11/2025 | M17: CAJA | N17: 0121 | O17: TH001400000125 | P17: Asiento de CAJA (01/09/2025 - 31/08/2026) | Q17: Extracción de Banco 001400000125 Obs: 16-11-2025 Mov Lodge | R17: SJ - deb comi | S17: 000000000230 | T17: Ejercicio 2025/2026
D18: UL | E18: =+VLOOKUP(F18,Resumen_Base!$C$8:$G$287,5,0) -> Fixed Asset's Payments (Investments) Mejoras/equipamiento Lodge | F18: 12020103 | G18: Mejoras de Inmueb y Terrenos | H18: =+D18&F18 -> UL12020103 | I18: 710000 | J18: 500 | K18: 1420 | L18: 07/12/2025 | M18: CAJA | N18: 0121 | O18: TH001400000168 | P18: Asiento de CAJA (01/09/2025 - 31/08/2026) | Q18: Extracción de Banco 001400000168 Obs: 07-12-2025 Mov Lodge | R18: SJ - obra Valle de Soba Ruben Perez | S18: 000000000242 | T18: Ejercicio 2025/2026
D19: UL | E19: =+VLOOKUP(F19,Resumen_Base!$C$8:$G$287,5,0) -> Fixed Asset's Payments (Investments) Mejoras/equipamiento Lodge | F19: 12020103 | G19: Mejoras de Inmueb y Terrenos | H19: =+D19&F19 -> UL12020103 | I19: 710000 | J19: 500 | K19: 1420 | L19: 07/12/2025 | M19: CAJA | N19: 0121 | O19: TH001400000168 | P19: Asiento de CAJA (01/09/2025 - 31/08/2026) | Q19: Extracción de Banco 001400000168 Obs: 07-12-2025 Mov Lodge | R19: SJ - obra Valle de Soba Ruben Perez | S19: 000000000242 | T19: Ejercicio 2025/2026
D20: UL | E20: =+VLOOKUP(F20,Resumen_Base!$C$8:$G$287,5,0) -> Fixed Asset's Payments (Investments) Mejoras/equipamiento Lodge | F20: 12020103 | G20: Mejoras de Inmueb y Terrenos | H20: =+D20&F20 -> UL12020103 | I20: 710000 | J20: 500 | K20: 1420 | L20: 07/12/2025 | M20: CAJA | N20: 0121 | O20: TH001400000168 | P20: Asiento de CAJA (01/09/2025 - 31/08/2026) | Q20: Extracción de Banco 001400000168 Obs: 07-12-2025 Mov Lodge | R20: SJ - obra Valle de Soba Ruben Perez | S20: 000000000242 | T20: Ejercicio 2025/2026
D21: UL | E21: =+VLOOKUP(F21,Resumen_Base!$C$8:$G$287,5,0) -> Fixed Asset's Payments (Investments) Mejoras/equipamiento Lodge | F21: 12020103 | G21: Mejoras de Inmueb y Terrenos | H21: =+D21&F21 -> UL12020103 | I21: 1420 | J21: 1 | K21: 1420 | L21: 07/12/2025 | M21: CAJA | N21: 0121 | O21: TH001400000168 | P21: Asiento de CAJA (01/09/2025 - 31/08/2026) | Q21: Extracción de Banco 001400000168 Obs: 07-12-2025 Mov Lodge | R21: SJ - obra Valle de Soba Ruben Perez | S21: 000000000242 | T21: Ejercicio 2025/2026
D22: UL | E22: =+VLOOKUP(F22,Resumen_Base!$C$8:$G$287,5,0) -> Fixed Asset's Payments (Investments) Mejoras/equipamiento Lodge | F22: 12020103 | G22: Mejoras de Inmueb y Terrenos | H22: =+D22&F22 -> UL12020103 | I22: 710000 | J22: 500 | K22: 1420 | L22: 07/12/2025 | M22: CAJA | N22: 0121 | O22: TH001400000168 | P22: Asiento de CAJA (01/09/2025 - 31/08/2026) | Q22: Extracción de Banco 001400000168 Obs: 07-12-2025 Mov Lodge | R22: SJ - obra Valle de Soba Ruben Perez | S22: 000000000242 | T22: Ejercicio 2025/2026
D23: UL | E23: =+VLOOKUP(F23,Resumen_Base!$C$8:$G$287,5,0) -> Fixed Asset's Payments (Investments) Mejoras/equipamiento Lodge | F23: 12020103 | G23: Mejoras de Inmueb y Terrenos | H23: =+D23&F23 -> UL12020103 | I23: 1420 | J23: 1 | K23: 1420 | L23: 07/12/2025 | M23: CAJA | N23: 0121 | O23: TH001400000168 | P23: Asiento de CAJA (01/09/2025 - 31/08/2026) | Q23: Extracción de Banco 001400000168 Obs: 07-12-2025 Mov Lodge | R23: SJ - obra Valle de Soba Ruben Perez | S23: 000000000242 | T23: Ejercicio 2025/2026
D24: UL | E24: =+VLOOKUP(F24,Resumen_Base!$C$8:$G$287,5,0) -> Fixed Asset's Payments (Investments) Mejoras/equipamiento Lodge | F24: 12020103 | G24: Mejoras de Inmueb y Terrenos | H24: =+D24&F24 -> UL12020103 | I24: 7395360 | J24: 5208 | K24: 1420 | L24: 21/12/2025 | M24: CAJA | N24: 0121 | O24: TE001400000186 | P24: Asiento de CAJA (01/09/2025 - 31/08/2026) | Q24: Extracción de Caja 001400000186 Obs: 21-12-2025 Mov Lodge | R24: SJ - devolucion a sofi barran que presto para empezar obra en valle de soba | S24: 000000000283 | T24: Ejercicio 2025/2026
D25: UL | E25: =+VLOOKUP(F25,Resumen_Base!$C$8:$G$287,5,0) -> Fixed Asset's Payments (Investments) Mejoras/equipamiento Lodge | F25: 12020103 | G25: Mejoras de Inmueb y Terrenos | H25: =+D25&F25 -> UL12020103 | I25: 2130000 | J25: 1500 | K25: 1420 | L25: 21/12/2025 | M25: CAJA | N25: 0121 | O25: TE001400000186 | P25: Asiento de CAJA (01/09/2025 - 31/08/2026) | Q25: Extracción de Caja 001400000186 Obs: 21-12-2025 Mov Lodge | R25: SJ - a favor obra valle de soba | S25: 000000000283 | T25: Ejercicio 2025/2026
... D39: CAR | E39: =+VLOOKUP(F39,Resumen_Base!$C$8:$G$287,5,0) -> Fixed Asset's Payments (Investments) Mejoras/equipamiento Lodge | F39: 12020103 | G39: Mejoras de Inmueb y Terrenos | H39: =+D39&F39 -> CAR12020103 | I39: 9165000 | J39: 6500 | K39: 1410 | L39: 12/10/2025 | M39: CAJA | N39: 0123 | O39: TH001400000056 | P39: Asiento de CAJA (01/09/2025 - 31/08/2026) | Q39: Extracción de Banco 001400000056 Obs: 12-10-2025 Mov Lodge | R39: CAR - mejoras inmuebles | S39: 000000000075 | T39: Ejercicio 2025/2026
D40: CAR | E40: =+VLOOKUP(F40,Resumen_Base!$C$8:$G$287,5,0) -> Fixed Asset's Payments (Investments) Mejoras/equipamiento Lodge | F40: 12020103 | G40: Mejoras de Inmueb y Terrenos | H40: =+D40&F40 -> CAR12020103 | I40: -9750000 | J40: -6500 | K40: 1500 | L40: 27/10/2025 | M40: CAJA | N40: 0123 | O40: TD001400000097 | P40: Asiento de CAJA (01/09/2025 - 31/08/2026) | Q40: Depósito a Banco 001400000097 Obs: CAR - Recupero Mejoras inmuebles y terrenos | S40: 000000000158 | T40: Ejercicio 2025/2026
A41: PAGAN LOS DUEÑOS DE LA PROPIEDAD | D41: CAR | E41: =+VLOOKUP(F41,Resumen_Base!$C$8:$G$287,5,0) -> Fixed Asset's Payments (Investments) Mejoras/equipamiento Lodge | F41: 12020103 | G41: Mejoras de Inmueb y Terrenos | H41: =+D41&F41 -> CAR12020103 | I41: 101941.8 | J41: 71.79 | K41: 1420 | L41: 23/11/2025 | M41: CAJA | N41: 0123 | O41: TE001400000144 | P41: Asiento de CAJA (01/09/2025 - 31/08/2026) | Q41: Extracción de Caja 001400000144 Obs: 23-11-2025 Mov Lodge | R41: CAR - OBRA COCINA: barraca | S41: 000000000222 | T41: Ejercicio 2025/2026
A42: PAGAN LOS DUEÑOS DE LA PROPIEDAD | D42: CAR | E42: =+VLOOKUP(F42,Resumen_Base!$C$8:$G$287,5,0) -> Fixed Asset's Payments (Investments) Mejoras/equipamiento Lodge | F42: 12020103 | G42: Mejoras de Inmueb y Terrenos | H42: =+D42&F42 -> CAR12020103 | I42: 4260000 | J42: 3000 | K42: 1420 | L42: 23/11/2025 | M42: CAJA | N42: 0123 | O42: TE001400000144 | P42: Asiento de CAJA (01/09/2025 - 31/08/2026) | Q42: Extracción de Caja 001400000144 Obs: 23-11-2025 Mov Lodge | R42: CAR - OBRA COCINA: honorarios albanil | S42: 000000000222 | T42: Ejercicio 2025/2026
A43: PAGAN LOS DUEÑOS DE LA PROPIEDAD | D43: CAR | E43: =+VLOOKUP(F43,Resumen_Base!$C$8:$G$287,5,0) -> Fixed Asset's Payments (Investments) Mejoras/equipamiento Lodge | F43: 12020103 | G43: Mejoras de Inmueb y Terrenos | H43: =+D43&F43 -> CAR12020103 | I43: 5212820 | J43: 3671 | K43: 1420 | L43: 23/11/2025 | M43: CAJA | N43: 0123 | O43: TE001400000144 | P43: Asiento de CAJA (01/09/2025 - 31/08/2026) | Q43: Extracción de Caja 001400000144 Obs: 23-11-2025 Mov Lodge | R43: CAR - materiales barraca | S43: 000000000222 | T43: Ejercicio 2025/2026
A44: PAGAN LOS DUEÑOS DE LA PROPIEDAD | D44: CAR | E44: =+VLOOKUP(F44,Resumen_Base!$C$8:$G$287,5,0) -> Fixed Asset's Payments (Investments) Mejoras/equipamiento Lodge | F44: 12020103 | G44: Mejoras de Inmueb y Terrenos | H44: =+D44&F44 -> CAR12020103 | I44: 291284.6 | J44: 205.13 | K44: 1420 | L44: 23/11/2025 | M44: CAJA | N44: 0123 | O44: TE001400000144 | P44: Asiento de CAJA (01/09/2025 - 31/08/2026) | Q44: Extracción de Caja 001400000144 Obs: 23-11-2025 Mov Lodge | R44: CAR - OBRA COCINA: babetas | S44: 000000000222 | T44: Ejercicio 2025/2026
A45: PAGAN LOS DUEÑOS DE LA PROPIEDAD | D45: CAR | E45: =+VLOOKUP(F45,Resumen_Base!$C$8:$G$287,5,0) -> Fixed Asset's Payments (Investments) Mejoras/equipamiento Lodge | F45: 12020103 | G45: Mejoras de Inmueb y Terrenos | H45: =+D45&F45 -> CAR12020103 | I45: 889104.6 | J45: 626.13 | K45: 1420 | L45: 23/11/2025 | M45: CAJA | N45: 0123 | O45: TE001400000144 | P45: Asiento de CAJA (01/09/2025 - 31/08/2026) | Q45: Extracción de Caja 001400000144 Obs: 23-11-2025 Mov Lodge | R45: CAR - OBRA COCINA: materiales | S45: 000000000222 | T45: Ejercicio 2025/2026
A46: PAGAN LOS DUEÑOS DE LA PROPIEDAD | D46: CAR | E46: =+VLOOKUP(F46,Resumen_Base!$C$8:$G$287,5,0) -> Fixed Asset's Payments (Investments) Mejoras/equipamiento Lodge | F46: 12020103 | G46: Mejoras de Inmueb y Terrenos | H46: =+D46&F46 -> CAR12020103 | I46: 586417.4 | J46: 412.97 | K46: 1420 | L46: 23/11/2025 | M46: CAJA | N46: 0123 | O46: TE001400000144 | P46: Asiento de CAJA (01/09/2025 - 31/08/2026) | Q46: Extracción de Caja 001400000144 Obs: 23-11-2025 Mov Lodge | R46: CAR - OBRA COCINA: materiales | S46: 000000000222 | T46: Ejercicio 2025/2026
D47: CAR | E47: =+VLOOKUP(F47,Resumen_Base!$C$8:$G$287,5,0) -> Fixed Asset's Payments (Investments) Mejoras/equipamiento Lodge | F47: 12020103 | G47: Mejoras de Inmueb y Terrenos | H47: =+D47&F47 -> CAR12020103 | I47: 555915.8 | J47: 391.49 | K47: 1420 | L47: 23/11/2025 | M47: CAJA | N47: 0123 | O47: TE001400000144 | P47: Asiento de CAJA (01/09/2025 - 31/08/2026) | Q47: Extracción de Caja 001400000144 Obs: 23-11-2025 Mov Lodge | R47: CAR - ferreteria varios para cambio de luces en jardin y pintura muebles exterior | S47: 000000000222 | T47: Ejercicio 2025/2026
D48: CAR | E48: =+VLOOKUP(F48,Resumen_Base!$C$8:$G$287,5,0) -> Fixed Asset's Payments (Investments) Mejoras/equipamiento Lodge | F48: 12020103 | G48: Mejoras de Inmueb y Terrenos | H48: =+D48&F48 -> CAR12020103 | I48: 801760.4 | J48: 564.62 | K48: 1420 | L48: 23/11/2025 | M48: CAJA | N48: 0123 | O48: TE001400000144 | P48: Asiento de CAJA (01/09/2025 - 31/08/2026) | Q48: Extracción de Caja 001400000144 Obs: 23-11-2025 Mov Lodge | R48: CAR - Pintura pileta | S48: 000000000222 | T48: Ejercicio 2025/2026
A49: PAGAN LOS DUEÑOS DE LA PROPIEDAD | D49: CAR | E49: =+VLOOKUP(F49,Resumen_Base!$C$8:$G$287,5,0) -> Fixed Asset's Payments (Investments) Mejoras/equipamiento Lodge | F49: 12020103 | G49: Mejoras de Inmueb y Terrenos | H49: =+D49&F49 -> CAR12020103 | I49: 138364.8 | J49: 97.44 | K49: 1420 | L49: 23/11/2025 | M49: CAJA | N49: 0123 | O49: TE001400000144 | P49: Asiento de CAJA (01/09/2025 - 31/08/2026) | Q49: Extracción de Caja 001400000144 Obs: 23-11-2025 Mov Lodge | R49: CAR - OBRA COCINA: retiro de escombros | S49: 000000000222 | T49: Ejercicio 2025/2026
A50: PAGAN LOS DUEÑOS DE LA PROPIEDAD | D50: CAR | E50: =+VLOOKUP(F50,Resumen_Base!$C$8:$G$287,5,0) -> Fixed Asset's Payments (Investments) Mejoras/equipamiento Lodge | F50: 12020103 | G50: Mejoras de Inmueb y Terrenos | H50: =+D50&F50 -> CAR12020103 | I50: 673591.2 | J50: 474.36 | K50: 1420 | L50: 30/11/2025 | M50: CAJA | N50: 0123 | O50: TE001400000157 | P50: Asiento de CAJA (01/09/2025 - 31/08/2026) | Q50: Extracción de Caja 001400000157 Obs: 30-11-2025 Mov Lodge | R50: CAR - OBRA COCINA: ferreteria | S50: 000000000225 | T50: Ejercicio 2025/2026
A51: PAGAN LOS DUEÑOS DE LA PROPIEDAD | D51: CAR | E51: =+VLOOKUP(F51,Resumen_Base!$C$8:$G$287,5,0) -> Fixed Asset's Payments (Investments) Mejoras/equipamiento Lodge | F51: 12020103 | G51: Mejoras de Inmueb y Terrenos | H51: =+D51&F51 -> CAR12020103 | I51: 695800 | J51: 490 | K51: 1420 | L51: 30/11/2025 | M51: CAJA | N51: 0123 | O51: TE001400000157 | P51: Asiento de CAJA (01/09/2025 - 31/08/2026) | Q51: Extracción de Caja 001400000157 Obs: 30-11-2025 Mov Lodge | R51: CAR - OBRA COCINA: puerta nueva | S51: 000000000225 | T51: Ejercicio 2025/2026
A52: PAGAN LOS DUEÑOS DE LA PROPIEDAD | D52: CAR | E52: =+VLOOKUP(F52,Resumen_Base!$C$8:$G$287,5,0) -> Fixed Asset's Payments (Investments) Mejoras/equipamiento Lodge | F52: 12020103 | G52: Mejoras de Inmueb y Terrenos | H52: =+D52&F52 -> CAR12020103 | I52: 1136000 | J52: 800 | K52: 1420 | L52: 21/12/2025 | M52: CAJA | N52: 0123 | O52: TE001400000186 | P52: Asiento de CAJA (01/09/2025 - 31/08/2026) | Q52: Extracción de Caja 001400000186 Obs: 21-12-2025 Mov Lodge | R52: CAR - OBRA COCINA: albanil | S52: 000000000283 | T52: Ejercicio 2025/2026
A53: PAGAN LOS DUEÑOS DE LA PROPIEDAD | D53: CAR | E53: =+VLOOKUP(F53,Resumen_Base!$C$8:$G$287,5,0) -> Fixed Asset's Payments (Investments) Mejoras/equipamiento Lodge | F53: 12020103 | G53: Mejoras de Inmueb y Terrenos | H53: =+D53&F53 -> CAR12020103 | I53: 984060 | J53: 693 | K53: 1420 | L53: 21/12/2025 | M53: CAJA | N53: 0123 | O53: TE001400000186 | P53: Asiento de CAJA (01/09/2025 - 31/08/2026) | Q53: Extracción de Caja 001400000186 Obs: 21-12-2025 Mov Lodge | R53: CAR - OBRA COCINA: ferreteria | S53: 000000000283 | T53: Ejercicio 2025/2026
A54: PAGAN LOS DUEÑOS DE LA PROPIEDAD | D54: CAR | E54: =+VLOOKUP(F54,Resumen_Base!$C$8:$G$287,5,0) -> Fixed Asset's Payments (Investments) Mejoras/equipamiento Lodge | F54: 12020103 | G54: Mejoras de Inmueb y Terrenos | H54: =+D54&F54 -> CAR12020103 | I54: 1136000 | J54: 800 | K54: 1420 | L54: 21/12/2025 | M54: CAJA | N54: 0123 | O54: TE001400000186 | P54: Asiento de CAJA (01/09/2025 - 31/08/2026) | Q54: Extracción de Caja 001400000186 Obs: 21-12-2025 Mov Lodge | R54: CAR - OBRA COCINA: albanil | S54: 000000000283 | T54: Ejercicio 2025/2026
D55: CAR | E55: =+VLOOKUP(F55,Resumen_Base!$C$8:$G$287,5,0) -> Fixed Asset's Payments (Investments) Mejoras/equipamiento Lodge | F55: 12020103 | G55: Mejoras de Inmueb y Terrenos | H55: =+D55&F55 -> CAR12020103 | I55: 1491000 | J55: 1050 | K55: 1420 | L55: 21/12/2025 | M55: CAJA | N55: 0123 | O55: TE001400000186 | P55: Asiento de CAJA (01/09/2025 - 31/08/2026) | Q55: Extracción de Caja 001400000186 Obs: 21-12-2025 Mov Lodge | R55: CAR - PERGOLA NUEVA ESTACIONAMIENTO: balasto y maquinas | S55: 000000000283 | T55: Ejercicio 2025/2026
A56: PAGAN LOS DUEÑOS DE LA PROPIEDAD | D56: CAR | E56: =+VLOOKUP(F56,Resumen_Base!$C$8:$G$287,5,0) -> Fixed Asset's Payments (Investments) Mejoras/equipamiento Lodge | F56: 12020103 | G56: Mejoras de Inmueb y Terrenos | H56: =+D56&F56 -> CAR12020103 | I56: 1420000 | J56: 1000 | K56: 1420 | L56: 21/12/2025 | M56: CAJA | N56: 0123 | O56: TE001400000186 | P56: Asiento de CAJA (01/09/2025 - 31/08/2026) | Q56: Extracción de Caja 001400000186 Obs: 21-12-2025 Mov Lodge | R56: CAR - OBRA COCINA: albanil | S56: 000000000283 | T56: Ejercicio 2025/2026
...

Sheet Mov_Analizados_Nov_21
G2: Ver Telefonos
G3: Ver Gastos devengados
G4: Ver Luz Devengada
G5: Ver REVERSAS VINOS
G7: =+IF(I7+J7=0,"Ok","Check") -> Ok | I7: =ROUND(SUM(I10:I166),0) -> 0 | J7: =ROUND(SUM(J10:J166),0) -> 0
D8: FL | E8: Rubro | G8: =+Resumen_Base!D1 -> Ok
B9: =+F9&$C$9&G9 | D9: =+VLOOKUP(F9,Resumen_Base!$C$8:$F$26,4,0) -> #N/A | E9: =+VLOOKUP(F9,Resumen_Base!$C$8:$G$156,5,0) -> #N/A | H9: =+D9&F9 -> #N/A | I9: =SUM(I10:I14) -> 0 | J9: =SUM(J10:J14) -> 0
B10: Cuenta Anterior | D10: Lodge | E10: Concepto | F10: Cuenta | G10: Nombre | I10: monto $ | J10: monto USD | K10: TC | L10: Fecha | M10: Subdiario | N10: Div | O10: Datos del comprobante | P10: Sujeto | Q10: CUIT | R10: Observación asiento | S10: Clase de Asiento | T10: Origen del comprobante | U10: Observación del comprobante | V10: Comentario renglón asiento | W10: Asiento | X10: Control | Z10: monto USD | AA10: tc | AC10: Fecha | AD10: Subdiario | AE10: Div | AF10: Datos del comprobante | AG10: Sujeto | AH10: CUIT | AI10: Observación asiento | AJ10: Clase de Asiento | AK10: Origen del comprobante | AL10: Observación del comprobante | AM10: Comentario renglón asiento | AN10: Asiento
A14: INSERT | B14: INSERT | C14: INSERT | D14: INSERT | E14: INSERT | F14: INSERT | G14: INSERT | H14: INSERT | I14: INSERT | J14: INSERT | K14: INSERT | L14: INSERT | M14: INSERT | N14: INSERT | O14: INSERT | P14: INSERT | Q14: INSERT | R14: INSERT | S14: INSERT | T14: INSERT | U14: INSERT | V14: INSERT | W14: INSERT
A20: INSERT | B20: INSERT | C20: INSERT | D20: INSERT | E20: INSERT | F20: INSERT | G20: INSERT | H20: INSERT | I20: INSERT | J20: INSERT | K20: INSERT | L20: INSERT | M20: INSERT | N20: INSERT | O20: INSERT | P20: INSERT | Q20: INSERT | R20: INSERT | S20: INSERT | T20: INSERT | U20: INSERT | V20: INSERT | W20: INSERT

Sheet Mov_Analizados_Dic_21
G2: Ver Telefonos
G3: Ver Gastos devengados
G4: Ver Luz Devengada
G5: Ver REVERSAS VINOS
G7: =+IF(I7+J7=0,"Ok","Check") -> Ok | I7: =ROUND(SUM(I10:I22),0) -> 0 | J7: =ROUND(SUM(J10:J22),0) -> 0
D8: FL | E8: Rubro | G8: Ok
B9: =+F9&$C$9&G9 | D9: =+VLOOKUP(F9,Resumen_Base!$C$8:$F$26,4,0) -> #N/A | E9: =+VLOOKUP(F9,Resumen_Base!$C$8:$G$156,5,0) -> #N/A | H9: =+D9&F9 -> #N/A | I9: =SUM(I10:I13) -> 0 | J9: =SUM(J10:J13) -> 0
B10: Cuenta Anterior | D10: Lodge | E10: Concepto | F10: Cuenta | G10: Nombre | I10: monto $ | J10: monto USD | K10: TC | L10: Fecha | M10: Subdiario | N10: Div | O10: Datos del comprobante | P10: Sujeto | Q10: CUIT | R10: Observación asiento | S10: Clase de Asiento | T10: Origen del comprobante | U10: Observación del comprobante | V10: Comentario renglón asiento | W10: Asiento | X10: Control | Z10: monto USD | AA10: tc | AC10: Fecha | AD10: Subdiario | AE10: Div | AF10: Datos del comprobante | AG10: Sujeto | AH10: CUIT | AI10: Observación asiento | AJ10: Clase de Asiento | AK10: Origen del comprobante | AL10: Observación del comprobante | AM10: Comentario renglón asiento | AN10: Asiento
A13: INSERT | B13: INSERT | C13: INSERT | D13: INSERT | E13: INSERT | F13: INSERT | G13: INSERT | H13: INSERT | I13: INSERT | J13: INSERT | K13: INSERT | L13: INSERT | M13: INSERT | N13: INSERT | O13: INSERT | P13: INSERT | Q13: INSERT | R13: INSERT | S13: INSERT | T13: INSERT | U13: INSERT | V13: INSERT | W13: INSERT
A22: INSERT | B22: INSERT | C22: INSERT | D22: INSERT | E22: INSERT | F22: INSERT | G22: INSERT | H22: INSERT | I22: INSERT | J22: INSERT | K22: INSERT | L22: INSERT | M22: INSERT | N22: INSERT | O22: INSERT | P22: INSERT | Q22: INSERT | R22: INSERT | S22: INSERT | T22: INSERT | U22: INSERT | V22: INSERT | W22: INSERT

Sheet Mov_Analizados_Ene_Feb 23
G2: Ver Telefonos
G3: Ver Gastos devengados
G4: Ver Luz Devengada
G5: Ver REVERSAS VINOS
G7: =+IF(I7+J7=0,"Ok","Check") -> Ok | I7: =ROUND(SUM(I10:I86),0) -> 0 | J7: =ROUND(SUM(J10:J86),0) -> 0
D8: FL | E8: Rubro | G8: =+Resumen_Base!D1 -> Ok
B9: =+F9&$C$9&G9 | D9: =+VLOOKUP(F9,Resumen_Base!$C$8:$F$26,4,0) -> #N/A | E9: =+VLOOKUP(F9,Resumen_Base!$C$8:$G$156,5,0) -> #N/A | H9: =+D9&F9 -> #N/A | I9: =SUM(I10:I13) -> 0 | J9: =SUM(J10:J13) -> 0
B10: Cuenta Anterior | D10: Lodge | E10: Concepto | F10: Cuenta | G10: Nombre | I10: monto $ | J10: monto USD | K10: TC | L10: Fecha | M10: Subdiario | N10: Div | O10: Datos del comprobante | P10: Sujeto | Q10: CUIT | R10: Observación asiento | S10: Clase de Asiento | T10: Origen del comprobante | U10: Observación del comprobante | V10: Comentario renglón asiento | W10: Asiento | X10: Control | Z10: monto USD | AA10: tc | AC10: Fecha | AD10: Subdiario | AE10: Div | AF10: Datos del comprobante | AG10: Sujeto | AH10: CUIT | AI10: Observación asiento | AJ10: Clase de Asiento | AK10: Origen del comprobante | AL10: Observación del comprobante | AM10: Comentario renglón asiento | AN10: Asiento
A13: INSERT | B13: INSERT | C13: INSERT | D13: INSERT | E13: INSERT | F13: INSERT | G13: INSERT | H13: INSERT | I13: INSERT | J13: INSERT | K13: INSERT | L13: INSERT | M13: INSERT | N13: INSERT | O13: INSERT | P13: INSERT | Q13: INSERT | R13: INSERT | S13: INSERT | T13: INSERT | U13: INSERT | V13: INSERT | W13: INSERT
A20: INSERT | B20: INSERT | C20: INSERT | D20: INSERT | E20: INSERT | F20: INSERT | G20: INSERT | H20: INSERT | I20: INSERT | J20: INSERT | K20: INSERT | L20: INSERT | M20: INSERT | N20: INSERT | O20: INSERT | P20: INSERT | Q20: INSERT | R20: INSERT | S20: INSERT | T20: INSERT | U20: INSERT | V20: INSERT | W20: INSERT

Sheet Mov_Analizados_Feb_22
G2: Ver Telefonos
G3: Ver Gastos devengados
G4: Ver Luz Devengada
G5: Ver REVERSAS VINOS
G7: =+IF(I7+J7=0,"Ok","Check") -> Ok | I7: =ROUND(SUM(I10:I47),0) -> 0 | J7: =ROUND(SUM(J10:J47),0) -> 0
D8: FL | E8: Rubro | G8: =+Resumen_Base!D1 -> Ok
B9: =+F9&$C$9&G9 | D9: =+VLOOKUP(F9,Resumen_Base!$C$8:$F$26,4,0) -> #N/A | E9: =+VLOOKUP(F9,Resumen_Base!$C$8:$G$156,5,0) -> #N/A | H9: =+D9&F9 -> #N/A | I9: =SUM(I10:I13) -> 0 | J9: =SUM(J10:J13) -> 0 | K9: =+AVERAGE(K10:K13) -> #DIV/0!
B10: Cuenta Anterior | D10: Lodge | E10: Concepto | F10: Cuenta | G10: Nombre | I10: monto $ | J10: monto USD | K10: TC | L10: Fecha | M10: Subdiario | N10: Div | O10: Datos del comprobante | P10: Sujeto | Q10: CUIT | R10: Observación asiento | S10: Clase de Asiento | T10: Origen del comprobante | U10: Observación del comprobante | V10: Comentario renglón asiento | W10: Asiento | X10: Control | Z10: monto USD | AA10: tc | AC10: Fecha | AD10: Subdiario | AE10: Div | AF10: Datos del comprobante | AG10: Sujeto | AH10: CUIT | AI10: Observación asiento | AJ10: Clase de Asiento | AK10: Origen del comprobante | AL10: Observación del comprobante | AM10: Comentario renglón asiento | AN10: Asiento
A13: INSERT | B13: INSERT | C13: INSERT | D13: INSERT | E13: INSERT | F13: INSERT | G13: INSERT | H13: INSERT | I13: INSERT | J13: INSERT | K13: INSERT | L13: INSERT | M13: INSERT | N13: INSERT | O13: INSERT | P13: INSERT | Q13: INSERT | R13: INSERT | S13: INSERT | T13: INSERT | U13: INSERT | V13: INSERT | W13: INSERT
A19: INSERT | B19: INSERT | C19: INSERT | D19: INSERT | E19: INSERT | F19: INSERT | G19: INSERT | H19: INSERT | I19: INSERT | J19: INSERT | K19: INSERT | L19: INSERT | M19: INSERT | N19: INSERT | O19: INSERT | P19: INSERT | Q19: INSERT | R19: INSERT | S19: INSERT | T19: INSERT | U19: INSERT | V19: INSERT | W19: INSERT

Sheet Mov_Analizados_Mar_23
A1: Campos | C1: Mant. Vehiculo Scouting
A2: CL | B2: =+#REF! -> #REF! | C2: CL | D2: =+#REF! -> #REF! | G2: Ver Telefonos
A3: FL | B3: =+#REF! -> #REF! | C3: FL | D3: =+#REF! -> #REF! | G3: Ver Gastos devengados
A4: Combustible | G4: Ver Luz Devengada
A5: CL | B5: =+#REF! -> #REF! | G5: Ver REVERSAS VINOS
A6: FL | B6: =+#REF! -> #REF!
A7: Permisos | G7: =+IF(I7+J7=0,"Ok","Check") -> Ok | I7: =ROUND(SUM(I10:I20),0) -> 0 | J7: =ROUND(SUM(J10:J20),0) -> 0
A8: CL | B8: =+#REF! -> #REF! | D8: FL | E8: Rubro | G8: =+Resumen_Base!D1 -> Ok
A9: FL | B9: =+#REF! -> #REF! | D9: =+VLOOKUP(F9,Resumen_Base!$C$8:$F$26,4,0) -> #N/A | E9: =+VLOOKUP(F9,Resumen_Base!$C$8:$G$156,5,0) -> #N/A | H9: =+D9&F9 -> #N/A | I9: =SUM(I10:I14) -> 0 | J9: =SUM(J10:J14) -> 0
B10: Cuenta Anterior | D10: Lodge | E10: Concepto | F10: Cuenta | G10: Nombre | I10: monto $ | J10: monto USD | K10: TC | L10: Fecha | M10: Subdiario | N10: Div | O10: Datos del comprobante | P10: Sujeto | Q10: CUIT | R10: Observación asiento | S10: Clase de Asiento | T10: Origen del comprobante | U10: Observación del comprobante | V10: Comentario renglón asiento | W10: Asiento | X10: Control | Z10: monto USD | AA10: tc | AC10: Fecha | AD10: Subdiario | AE10: Div | AF10: Datos del comprobante | AG10: Sujeto | AH10: CUIT | AI10: Observación asiento | AJ10: Clase de Asiento | AK10: Origen del comprobante | AL10: Observación del comprobante | AM10: Comentario renglón asiento | AN10: Asiento
A14: INSERT | B14: INSERT | C14: INSERT | D14: INSERT | E14: INSERT | F14: INSERT | G14: INSERT | H14: INSERT | I14: INSERT | J14: INSERT | K14: INSERT | L14: INSERT | M14: INSERT | N14: INSERT | O14: INSERT | P14: INSERT | Q14: INSERT | R14: INSERT | S14: INSERT | T14: INSERT | U14: INSERT | V14: INSERT | W14: INSERT
A20: INSERT | B20: INSERT | C20: INSERT | D20: INSERT | E20: INSERT | F20: INSERT | G20: INSERT | H20: INSERT | I20: INSERT | J20: INSERT | K20: INSERT | L20: INSERT | M20: INSERT | N20: INSERT | O20: INSERT | P20: INSERT | Q20: INSERT | R20: INSERT | S20: INSERT | T20: INSERT | U20: INSERT | V20: INSERT | W20: INSERT

Sheet Mov_Analizados_Abr_23
A1: Campos | C1: Mant. Vehiculo Scouting
A2: CL | B2: =+#REF! -> #REF! | C2: CL | D2: =+#REF! -> #REF! | G2: Ver Telefonos
A3: FL | B3: =+#REF! -> #REF! | C3: FL | D3: =+#REF! -> #REF! | G3: Ver Gastos devengados
A4: Combustible | G4: Ver Luz Devengada
A5: CL | B5: =+#REF! -> #REF! | G5: Ver REVERSAS VINOS
A6: FL | B6: =+#REF! -> #REF!
A7: Permisos | G7: =+IF(I7+J7=0,"Ok","Check") -> Ok | I7: =ROUND(SUM(I11:I33),0) -> 0 | J7: =ROUND(SUM(J11:J33),0) -> 0
A8: CL | B8: =+#REF! -> #REF! | D8: FL | E8: Rubro | G8: =+Resumen_Base!D1 -> Ok
A9: FL | B9: =+#REF! -> #REF! | D9: =+VLOOKUP(F9,Resumen_Base!$C$8:$F$26,4,0) -> #N/A | E9: =+VLOOKUP(F9,Resumen_Base!$C$8:$G$156,5,0) -> #N/A | H9: =+D9&F9 -> #N/A | I9: =SUM(I11:I14) -> 0 | J9: =SUM(J11:J14) -> 0
B10: =+F10&G10
B11: Cuenta Anterior | D11: Lodge | E11: Concepto | F11: Cuenta | G11: Nombre | I11: monto $ | J11: monto USD | K11: TC | L11: Fecha | M11: Subdiario | N11: Div | O11: Datos del comprobante | P11: Sujeto | Q11: CUIT | R11: Observación asiento | S11: Clase de Asiento | T11: Origen del comprobante | U11: Observación del comprobante | V11: Comentario renglón asiento | W11: Asiento | X11: Control | Z11: monto USD | AA11: tc | AC11: Fecha | AD11: Subdiario | AE11: Div | AF11: Datos del comprobante | AG11: Sujeto | AH11: CUIT | AI11: Observación asiento | AJ11: Clase de Asiento | AK11: Origen del comprobante | AL11: Observación del comprobante | AM11: Comentario renglón asiento | AN11: Asiento
A14: INSERT | B14: INSERT | C14: INSERT | D14: INSERT | E14: INSERT | F14: INSERT | G14: INSERT | H14: INSERT | I14: INSERT | J14: INSERT | K14: INSERT | L14: INSERT | M14: INSERT | N14: INSERT | O14: INSERT | P14: INSERT | Q14: INSERT | R14: INSERT | S14: INSERT | T14: INSERT | U14: INSERT | V14: INSERT | W14: INSERT
A20: INSERT | B20: INSERT | C20: INSERT | D20: INSERT | E20: INSERT | F20: INSERT | G20: INSERT | H20: INSERT | I20: INSERT | J20: INSERT | K20: INSERT | L20: INSERT | M20: INSERT | N20: INSERT | O20: INSERT | P20: INSERT | Q20: INSERT | R20: INSERT | S20: INSERT | T20: INSERT | U20: INSERT | V20: INSERT | W20: INSERT

Sheet Mov_Analizados_May_23
A1: Campos | C1: Mant. Vehiculo Scouting
A2: CL | B2: =+#REF! -> #REF! | C2: CL | D2: =+#REF! -> #REF! | G2: Ver Telefonos
A3: FL | B3: =+#REF! -> #REF! | C3: FL | D3: =+#REF! -> #REF! | G3: Ver Gastos devengados
A4: Combustible | G4: Ver Luz Devengada
A5: CL | B5: =+#REF! -> #REF! | G5: Ver REVERSAS VINOS
A6: FL | B6: =+#REF! -> #REF!
A7: Permisos | G7: =+IF(I7+J7=0,"Ok","Check") -> Ok | I7: =ROUND(SUM(I11:I18),0) -> 0 | J7: =ROUND(SUM(J11:J18),0) -> 0
A8: CL | B8: =+#REF! -> #REF! | D8: FL | E8: Rubro | G8: =+Resumen_Base!D1 -> Ok
A9: FL | B9: =+#REF! -> #REF! | D9: =+VLOOKUP(F9,Resumen_Base!$C$8:$F$26,4,0) -> #N/A | E9: =+VLOOKUP(F9,Resumen_Base!$C$8:$G$156,5,0) -> #N/A | H9: =+D9&F9 -> #N/A | I9: =SUM(I11:I14) -> 0 | J9: =SUM(J11:J14) -> 0
B11: Cuenta Anterior | D11: Lodge | E11: Concepto | F11: Cuenta | G11: Nombre | I11: monto $ | J11: monto USD | K11: TC | L11: Fecha | M11: Subdiario | N11: Div | O11: Datos del comprobante | P11: Sujeto | Q11: CUIT | R11: Observación asiento | S11: Clase de Asiento | T11: Origen del comprobante | U11: Observación del comprobante | V11: Comentario renglón asiento | W11: Asiento | X11: Control | Z11: monto USD | AA11: tc | AC11: Fecha | AD11: Subdiario | AE11: Div | AF11: Datos del comprobante | AG11: Sujeto | AH11: CUIT | AI11: Observación asiento | AJ11: Clase de Asiento | AK11: Origen del comprobante | AL11: Observación del comprobante | AM11: Comentario renglón asiento | AN11: Asiento
A14: INSERT | B14: INSERT | C14: INSERT | D14: INSERT | E14: INSERT | F14: INSERT | G14: INSERT | H14: INSERT | I14: INSERT | J14: INSERT | K14: INSERT | L14: INSERT | M14: INSERT | N14: INSERT | O14: INSERT | P14: INSERT | Q14: INSERT | R14: INSERT | S14: INSERT | T14: INSERT | U14: INSERT | V14: INSERT | W14: INSERT
A18: INSERT | B18: INSERT | C18: INSERT | D18: INSERT | E18: INSERT | F18: INSERT | G18: INSERT | H18: INSERT | I18: INSERT | J18: INSERT | K18: INSERT | L18: INSERT | M18: INSERT | N18: INSERT | O18: INSERT | P18: INSERT | Q18: INSERT | R18: INSERT | S18: INSERT | T18: INSERT | U18: INSERT | V18: INSERT | W18: INSERT

Sheet Mov_Analizados_Jun_22
G2: Ver Telefonos
G3: Ver Gastos devengados
G4: Ver Luz Devengada
G5: Ver REVERSAS VINOS
G7: =+IF(I7+J7=0,"Ok","Check") -> Ok | I7: =ROUND(SUM(I10:I17),0) -> 0 | J7: =ROUND(SUM(J10:J17),0) -> 0
D8: FL | E8: Rubro | G8: =+Resumen_Base!D1 -> Ok | K8: TC PROM
B9: =+F9&$C$9&G9 | D9: =+VLOOKUP(F9,Resumen_Base!$C$8:$F$26,4,0) -> #N/A | E9: =+VLOOKUP(F9,Resumen_Base!$C$8:$G$156,5,0) -> #N/A | H9: =+D9&F9 -> #N/A | I9: =SUM(I10:I14) -> 0 | J9: =SUM(J10:J14) -> 0 | K9: =+AVERAGE(K10:K17) -> #DIV/0!
B10: Cuenta Anterior | D10: Lodge | E10: Concepto | F10: Cuenta | G10: Nombre | I10: monto $ | J10: monto USD | K10: TC | L10: Fecha | M10: Subdiario | N10: Div | O10: Datos del comprobante | P10: Sujeto | Q10: CUIT | R10: Observación asiento | S10: Clase de Asiento | T10: Origen del comprobante | U10: Observación del comprobante | V10: Comentario renglón asiento | W10: Asiento | X10: Control | Z10: monto USD | AA10: tc | AC10: Fecha | AD10: Subdiario | AE10: Div | AF10: Datos del comprobante | AG10: Sujeto | AH10: CUIT | AI10: Observación asiento | AJ10: Clase de Asiento | AK10: Origen del comprobante | AL10: Observación del comprobante | AM10: Comentario renglón asiento | AN10: Asiento
A14: INSERT | B14: INSERT | C14: INSERT | D14: INSERT | E14: INSERT | F14: INSERT | G14: INSERT | H14: INSERT | I14: INSERT | J14: INSERT | K14: INSERT | L14: INSERT | M14: INSERT | N14: INSERT | O14: INSERT | P14: INSERT | Q14: INSERT | R14: INSERT | S14: INSERT | T14: INSERT | U14: INSERT | V14: INSERT | W14: INSERT
A17: INSERT | B17: INSERT | C17: INSERT | D17: INSERT | E17: INSERT | F17: INSERT | G17: INSERT | H17: INSERT | I17: INSERT | J17: INSERT | K17: INSERT | L17: INSERT | M17: INSERT | N17: INSERT | O17: INSERT | P17: INSERT | Q17: INSERT | R17: INSERT | S17: INSERT | T17: INSERT | U17: INSERT | V17: INSERT | W17: INSERT

Sheet Mov_Analizados_Jul_22
G2: Ver Telefonos
G3: Ver Gastos devengados
G4: Ver Luz Devengada
G5: Ver REVERSAS VINOS
G7: =+IF(I7+J7=0,"Ok","Check") -> Ok | I7: =ROUND(SUM(I10:I16),0) -> 0 | J7: =ROUND(SUM(J10:J16),0) -> 0
D8: FL | E8: Rubro | G8: =+Resumen_Base!D1 -> Ok
B9: =+F9&$C$9&G9 | D9: =+VLOOKUP(F9,Resumen_Base!$C$8:$F$26,4,0) -> #N/A | E9: =+VLOOKUP(F9,Resumen_Base!$C$8:$G$156,5,0) -> #N/A | H9: =+D9&F9 -> #N/A | I9: =SUM(I10:I13) -> 0 | J9: =SUM(J10:J13) -> 0
B10: Cuenta Anterior | D10: Lodge | E10: Concepto | F10: Cuenta | G10: Nombre | I10: monto $ | J10: monto USD | K10: TC | L10: Fecha | M10: Subdiario | N10: Div | O10: Datos del comprobante | P10: Sujeto | Q10: CUIT | R10: Observación asiento | S10: Clase de Asiento | T10: Origen del comprobante | U10: Observación del comprobante | V10: Comentario renglón asiento | W10: Asiento | X10: Control | Z10: monto USD | AA10: tc | AC10: Fecha | AD10: Subdiario | AE10: Div | AF10: Datos del comprobante | AG10: Sujeto | AH10: CUIT | AI10: Observación asiento | AJ10: Clase de Asiento | AK10: Origen del comprobante | AL10: Observación del comprobante | AM10: Comentario renglón asiento | AN10: Asiento
A13: INSERT | B13: INSERT | C13: INSERT | D13: INSERT | E13: INSERT | F13: INSERT | G13: INSERT | H13: INSERT | I13: INSERT | J13: INSERT | K13: INSERT | L13: INSERT | M13: INSERT | N13: INSERT | O13: INSERT | P13: INSERT | Q13: INSERT | R13: INSERT | S13: INSERT | T13: INSERT | U13: INSERT | V13: INSERT | W13: INSERT
A16: INSERT | B16: INSERT | C16: INSERT | D16: INSERT | E16: INSERT | F16: INSERT | G16: INSERT | H16: INSERT | I16: INSERT | J16: INSERT | K16: INSERT | L16: INSERT | M16: INSERT | N16: INSERT | O16: INSERT | P16: INSERT | Q16: INSERT | R16: INSERT | S16: INSERT | T16: INSERT | U16: INSERT | V16: INSERT | W16: INSERT

Sheet Mov_Analizados_Ago_22
G2: Ver Telefonos
G3: Ver Gastos devengados
G4: Ver Luz Devengada
G5: Ver REVERSAS VINOS
G7: =+IF(I7+J7=0,"Ok","Check") -> Ok | I7: =ROUND(SUM(I10:I16),0) -> 0 | J7: =ROUND(SUM(J10:J16),0) -> 0
D8: FL | E8: Rubro | G8: =+Resumen_Base!D1 -> Ok
B9: =+F9&$C$9&G9 | D9: =+VLOOKUP(F9,Resumen_Base!$C$8:$F$26,4,0) -> #N/A | E9: =+VLOOKUP(F9,Resumen_Base!$C$8:$G$156,5,0) -> #N/A | H9: =+D9&F9 -> #N/A | I9: =SUM(I10:I13) -> 0 | J9: =SUM(J10:J13) -> 0
B10: Cuenta Anterior | D10: Lodge | E10: Concepto | F10: Cuenta | G10: Nombre | I10: monto $ | J10: monto USD | K10: TC | L10: Fecha | M10: Subdiario | N10: Div | O10: Datos del comprobante | P10: Sujeto | Q10: CUIT | R10: Observación asiento | S10: Clase de Asiento | T10: Origen del comprobante | U10: Observación del comprobante | V10: Comentario renglón asiento | W10: Asiento | X10: Control | Z10: monto USD | AA10: tc | AC10: Fecha | AD10: Subdiario | AE10: Div | AF10: Datos del comprobante | AG10: Sujeto | AH10: CUIT | AI10: Observación asiento | AJ10: Clase de Asiento | AK10: Origen del comprobante | AL10: Observación del comprobante | AM10: Comentario renglón asiento | AN10: Asiento
A13: INSERT | B13: INSERT | C13: INSERT | D13: INSERT | E13: INSERT | F13: INSERT | G13: INSERT | H13: INSERT | I13: INSERT | J13: INSERT | K13: INSERT | L13: INSERT | M13: INSERT | N13: INSERT | O13: INSERT | P13: INSERT | Q13: INSERT | R13: INSERT | S13: INSERT | T13: INSERT | U13: INSERT | V13: INSERT | W13: INSERT
A16: INSERT | B16: INSERT | C16: INSERT | D16: INSERT | E16: INSERT | F16: INSERT | G16: INSERT | H16: INSERT | I16: INSERT | J16: INSERT | K16: INSERT | L16: INSERT | M16: INSERT | N16: INSERT | O16: INSERT | P16: INSERT | Q16: INSERT | R16: INSERT | S16: INSERT | T16: INSERT | U16: INSERT | V16: INSERT | W16: INSERT

Sheet Mov_Analizados_Ene 26
G2: Ver Telefonos
G3: Ver Gastos devengados
G4: Ver Luz Devengada
G5: Ver REVERSAS
G7: =+IF(I7+J7=0,"Ok","Check") -> Ok | I7: =ROUND(SUM(I10:I829),0) -> 0 | J7: =ROUND(SUM(J10:J829),0) -> 0
D8: FL | E8: Rubro | G8: =+Resumen_Base!D1 -> Ok
B9: =+F9&$C$9&G9 | D9: =+VLOOKUP(F9,Resumen_Base!$C$8:$F$26,4,0) -> #N/A | E9: =+VLOOKUP(F9,Resumen_Base!$C$8:$G$156,5,0) -> #N/A | H9: =+D9&F9 -> #N/A | I9: =SUM(I10:I330) -> 91745932 | J9: =SUM(J10:J330) -> 76869.01
B10: Cuenta Anterior | D10: Lodge | E10: Concepto | F10: Cuenta | G10: Nombre | I10: monto $ | J10: monto USD | K10: TC | L10: Fecha | M10: Subdiario | N10: Div | O10: Datos del comprobante | P10: Sujeto | Q10: CUIT | R10: Observación asiento | S10: Clase de Asiento | T10: Origen del comprobante | U10: Observación del comprobante | V10: Comentario renglón asiento | W10: Asiento | X10: Control | Z10: monto USD | AA10: tc | AC10: Fecha | AD10: Subdiario | AE10: Div | AF10: Datos del comprobante | AG10: Sujeto | AH10: CUIT | AI10: Observación asiento | AJ10: Clase de Asiento | AK10: Origen del comprobante | AL10: Observación del comprobante | AM10: Comentario renglón asiento | AN10: Asiento
C12: Uruguay | D12: CAR | E12: =+VLOOKUP(F12,Resumen_Base!$C$8:$G$287,5,0) -> Fixed Asset's Payments (Investments) Mejoras/equipamiento Lodge | F12: 12020301 | G12: Muebles y útiles | H12: =+D12&F12 -> CAR12020301 | I12: 1905648 | J12: 1287.6 | K12: 1480 | L12: 31/01/2026 | M12: CAJA | N12: 0123 | O12: TH001400000254 | P12: Asiento de CAJA (01/09/2025 - 31/08/2026) | Q12: Extracción de Banco 001400000254 Obs: 31-01-2026 Mov Lodge | R12: CAR - bastones magneticos para cartuchos usados | S12: 000000000341 | T12: Ejercicio 2025/2026
C13: Uruguay | D13: CAR | E13: =+VLOOKUP(F13,Resumen_Base!$C$8:$G$287,5,0) -> Fixed Asset's Payments (Investments) Mejoras/equipamiento Lodge | F13: 12020301 | G13: Muebles y útiles | H13: =+D13&F13 -> CAR12020301 | I13: 373404 | J13: 252.3 | K13: 1480 | L13: 26/01/2026 | M13: CAJA | N13: 0123 | O13: TE001400000225 | P13: Asiento de CAJA (01/09/2025 - 31/08/2026) | Q13: Extracción de Caja 001400000225 Obs: 26-01-2026 Mov Lodge | R13: CAR - Estanterías metálicas para depósito cocina | S13: 000000000327 | T13: Ejercicio 2025/2026
C14: Uruguay | D14: CAR | E14: =+VLOOKUP(F14,Resumen_Base!$C$8:$G$287,5,0) -> Fixed Asset's Payments (Investments) Mejoras/equipamiento Lodge | F14: 12020301 | G14: Muebles y útiles | H14: =+D14&F14 -> CAR12020301 | I14: 33735.99 | J14: 22.794588 | K14: 1480 | L14: 23/01/2026 | M14: CAJA | N14: 0123 | O14: TE001400000243 | P14: Asiento de CAJA (01/09/2025 - 31/08/2026) | Q14: Extracción de Caja 001400000243 Obs: Movimiento_Cajas_Bancos_Semana 25-26 al 23-01-2026 | R14: CAR-Compra perforadora 3 agujeros F.Fijo Oper. Al 23-01-2026 | S14: 000000000330 | T14: Ejercicio 2025/2026
C15: Uruguay | D15: CAR | E15: =+VLOOKUP(F15,Resumen_Base!$C$8:$G$287,5,0) -> Fixed Asset's Payments (Investments) Mejoras/equipamiento Lodge | F15: 12020601 | G15: Ropa Blanca | H15: =+D15&F15 -> CAR12020601 | I15: 78543.6 | J15: 53.07 | K15: 1480 | L15: 26/01/2026 | M15: CAJA | N15: 0123 | O15: TE001400000225 | P15: Asiento de CAJA (01/09/2025 - 31/08/2026) | Q15: Extracción de Caja 001400000225 Obs: 26-01-2026 Mov Lodge | R15: CAR - Envío ropa blanca surtex | S15: 000000000327 | T15: Ejercicio 2025/2026
C16: Uruguay | D16: CAR | E16: =+VLOOKUP(F16,Resumen_Base!$C$8:$G$287,5,0) -> Fixed Asset's Payments (Investments) Mejoras/equipamiento Lodge | F16: 12020901 | G16: Vajillas | H16: =+D16&F16 -> CAR12020901 | I16: 331520 | J16: 224 | K16: 1480 | L16: 31/01/2026 | M16: CAJA | N16: 0123 | O16: TE001400000248 | P16: Asiento de CAJA (01/09/2025 - 31/08/2026) | Q16: Extracción de Caja 001400000248 Obs: 31-01-2026 Mov Lodge | R16: CAR - 12 vasos trago largo + 12 vasos whiskey | S16: 000000000333 | T16: Ejercicio 2025/2026
C17: Uruguay | D17: CAR | E17: =+VLOOKUP(F17,Resumen_Base!$C$8:$G$287,5,0) -> Fixed Asset's Payments (Investments) Armas | F17: 120211 | G17: Armas- Escopetas - Equip Field | H17: =+D17&F17 -> CAR120211 | I17: 2812 | J17: 1.9 | K17: 1480 | L17: 26/01/2026 | M17: CAJA | N17: 0123 | O17: TH001400000236 | P17: Asiento de CAJA (01/09/2025 - 31/08/2026) | Q17: Extracción de Banco 001400000236 Obs: 26-01-2026 Mov Lodge | R17: CAR - deb comi | S17: 000000000337 | T17: Ejercicio 2025/2026
C18: Uruguay | D18: CAR | E18: =+VLOOKUP(F18,Resumen_Base!$C$8:$G$287,5,0) -> Fixed Asset's Payments (Investments) Armas | F18: 120211 | G18: Armas- Escopetas - Equip Field | H18: =+D18&F18 -> CAR120211 | I18: 289813.6 | J18: 195.82 | K18: 1480 | L18: 26/01/2026 | M18: CAJA | N18: 0123 | O18: TH001400000236 | P18: Asiento de CAJA (01/09/2025 - 31/08/2026) | Q18: Extracción de Banco 001400000236 Obs: 26-01-2026 Mov Lodge | R18: CAR - flete cartuchos Pablo Segovia | S18: 000000000337 | T18: Ejercicio 2025/2026
C19: Uruguay | D19: CAR | E19: =+VLOOKUP(F19,Resumen_Base!$C$8:$G$287,5,0) -> Fixed Asset's Payments (Investments) Armas | F19: 120211 | G19: Armas- Escopetas - Equip Field | H19: =+D19&F19 -> CAR120211 | I19: 999991.6 | J19: 675.67 | K19: 1480 | L19: 31/01/2026 | M19: CAJA | N19: 0123 | O19: TH001400000255 | P19: Asiento de CAJA (01/09/2025 - 31/08/2026) | Q19: Extracción de Banco 001400000255 Obs: 31-01-2026 Mov Lodge | R19: CAR - fundas escopetas carmelo | S19: 000000000342 | T19: Ejercicio 2025/2026
C20: Uruguay | D20: CAR | E20: =+VLOOKUP(F20,Resumen_Base!$C$8:$G$287,5,0) -> Tips | F20: 210609 | G20: Propinas a pagar | H20: =+D20&F20 -> CAR210609 | I20: -740000 | J20: -500 | K20: 1480 | L20: 29/01/2026 | M20: VENTAS | N20: 0123 | O20: VF000000004067B | P20: Asiento de VENTAS (01/09/2025 - 31/08/2026) | Q20: F B 000000004067 | R20: Ref. nota de Venta: CA.DU18 Obs.:31-01-2026_CLIENTES | S20: 000000000355 | T20: Ejercicio 2025/2026
C21: Uruguay | D21: CAR | E21: =+VLOOKUP(F21,Resumen_Base!$C$8:$G$287,5,0) -> Tips | F21: 210609 | G21: Propinas a pagar | H21: =+D21&F21 -> CAR210609 | I21: -1184000 | J21: -800 | K21: 1480 | L21: 29/01/2026 | M21: VENTAS | N21: 0123 | O21: VF000000004067B | P21: Asiento de VENTAS (01/09/2025 - 31/08/2026) | Q21: F B 000000004067 | R21: Ref. nota de Venta: CA.DU18 Obs.:31-01-2026_CLIENTES | S21: 000000000355 | T21: Ejercicio 2025/2026
C22: Uruguay | D22: CAR | E22: =+VLOOKUP(F22,Resumen_Base!$C$8:$G$287,5,0) -> Tips | F22: 210609 | G22: Propinas a pagar | H22: =+D22&F22 -> CAR210609 | I22: -532800 | J22: -360 | K22: 1480 | L22: 30/01/2026 | M22: VENTAS | N22: 0123 | O22: VF000000004068B | P22: Asiento de VENTAS (01/09/2025 - 31/08/2026) | Q22: F B 000000004068 | R22: Ref. nota de Venta: CA.DU18 Obs.:31-01-2026_CLIENTES | S22: 000000000356 | T22: Ejercicio 2025/2026
C23: Uruguay | D23: CAR | E23: =+VLOOKUP(F23,Resumen_Base!$C$8:$G$287,5,0) -> Tips | F23: 210609 | G23: Propinas a pagar | H23: =+D23&F23 -> CAR210609 | I23: -266400 | J23: -180 | K23: 1480 | L23: 30/01/2026 | M23: VENTAS | N23: 0123 | O23: VF000000004068B | P23: Asiento de VENTAS (01/09/2025 - 31/08/2026) | Q23: F B 000000004068 | R23: Ref. nota de Venta: CA.DU18 Obs.:31-01-2026_CLIENTES | S23: 000000000356 | T23: Ejercicio 2025/2026
... C121: Uruguay | D121: CAR | E121: =+VLOOKUP(F121,Resumen_Base!$C$8:$G$287,5,0) -> Guides | F121: 5227 | G121: Remuneraciones Guías | H121: =+D121&F121 -> CAR5227 | I121: 2368000 | J121: 1600 | K121: 1480 | L121: 26/01/2026 | M121: CAJA | N121: 0123 | O121: TH001400000236 | P121: Asiento de CAJA (01/09/2025 - 31/08/2026) | Q121: Extracción de Banco 001400000236 Obs: 26-01-2026 Mov Lodge | R121: CAR - Transaccion laboral Michel Cufre | S121: 000000000337 | T121: Ejercicio 2025/2026
A122: CAR | C122: Uruguay | D122: CAR | E122: =+VLOOKUP(F122,Resumen_Base!$C$8:$G$287,5,0) -> Manager | F122: 5228 | G122: Remuneraciones Managers | H122: =+D122&F122 -> CAR5228 | I122: 1171508.8 | J122: 791.56 | K122: 1480 | L122: 31/01/2026 | M122: CAJA | N122: 0121 | O122: TH001400000256 | P122: Asiento de CAJA (01/09/2025 - 31/08/2026) | Q122: Extracción de Banco 001400000256 Obs: 31-01-2026 Mov Lodge | R122: SJ - adelanto servicios personales enero Caro Horta | S122: 000000000343 | T122: Ejercicio 2025/2026
A123: CAR | C123: Uruguay | D123: CAR | E123: =+VLOOKUP(F123,Resumen_Base!$C$8:$G$287,5,0) -> Manager | F123: 5228 | G123: Remuneraciones Managers | H123: =+D123&F123 -> CAR5228 | I123: 2516000 | J123: 1700 | K123: 1480 | L123: 26/01/2026 | M123: CAJA | N123: 0121 | O123: TH001400000238 | P123: Asiento de CAJA (01/09/2025 - 31/08/2026) | Q123: Extracción de Banco 001400000238 Obs: 26-01-2026 Mov Lodge | R123: SJ - SP diciembre Sofia Barran | S123: 000000000339 | T123: Ejercicio 2025/2026
A124: CAR | C124: Uruguay | D124: CAR | E124: =+VLOOKUP(F124,Resumen_Base!$C$8:$G$287,5,0) -> Manager | F124: 5228 | G124: Remuneraciones Managers | H124: =+D124&F124 -> CAR5228 | I124: 444000 | J124: 300 | K124: 1480 | L124: 26/01/2026 | M124: CAJA | N124: 0121 | O124: TH001400000238 | P124: Asiento de CAJA (01/09/2025 - 31/08/2026) | Q124: Extracción de Banco 001400000238 Obs: 26-01-2026 Mov Lodge | R124: SJ - SP diciembre TAtiana Ribas | S124: 000000000339 | T124: Ejercicio 2025/2026
C125: Uruguay | D125: CAR | E125: =+VLOOKUP(F125,Resumen_Base!$C$8:$G$287,5,0) -> Manager | F125: 5228 | G125: Remuneraciones Managers | H125: =+D125&F125 -> CAR5228 | I125: 1480 | J125: 1 | K125: 1480 | L125: 26/01/2026 | M125: CAJA | N125: 0123 | O125: TH001400000236 | P125: Asiento de CAJA (01/09/2025 - 31/08/2026) | Q125: Extracción de Banco 001400000236 Obs: 26-01-2026 Mov Lodge | R125: CAR - deb comi | S125: 000000000337 | T125: Ejercicio 2025/2026
C126: Uruguay | D126: CAR | E126: =+VLOOKUP(F126,Resumen_Base!$C$8:$G$287,5,0) -> Manager | F126: 5228 | G126: Remuneraciones Managers | H126: =+D126&F126 -> CAR5228 | I126: 888000 | J126: 600 | K126: 1480 | L126: 26/01/2026 | M126: CAJA | N126: 0123 | O126: TH001400000236 | P126: Asiento de CAJA (01/09/2025 - 31/08/2026) | Q126: Extracción de Banco 001400000236 Obs: 26-01-2026 Mov Lodge | R126: CAR - medio aguimaldo Caro Horta | S126: 000000000337 | T126: Ejercicio 2025/2026
C127: Uruguay | D127: CAR | E127: =+VLOOKUP(F127,Resumen_Base!$C$8:$G$287,5,0) -> Manager | F127: 5228 | G127: Remuneraciones Managers | H127: =+D127&F127 -> CAR5228 | I127: 2029080 | J127: 1371 | K127: 1480 | L127: 26/01/2026 | M127: CAJA | N127: 0123 | O127: TH001400000236 | P127: Asiento de CAJA (01/09/2025 - 31/08/2026) | Q127: Extracción de Banco 001400000236 Obs: 26-01-2026 Mov Lodge | R127: CAR - sueldo diciembre Caro Horta | S127: 000000000337 | T127: Ejercicio 2025/2026
C128: Uruguay | D128: CAR | E128: =+VLOOKUP(F128,Resumen_Base!$C$8:$G$287,5,0) -> Gun Rental | F128: 5229 | G128: Alquiler Escopetas | H128: =+D128&F128 -> CAR5229 | I128: 2812 | J128: 1.9 | K128: 1480 | L128: 26/01/2026 | M128: CAJA | N128: 0123 | O128: TH001400000236 | P128: Asiento de CAJA (01/09/2025 - 31/08/2026) | Q128: Extracción de Banco 001400000236 Obs: 26-01-2026 Mov Lodge | R128: CAR - deb comi | S128: 000000000337 | T128: Ejercicio 2025/2026
C129: Uruguay | D129: CAR | E129: =+VLOOKUP(F129,Resumen_Base!$C$8:$G$287,5,0) -> Social Security Contributions | F129: 5235 | G129: Cargas Sociales Servicios | H129: =+D129&F129 -> CAR5235 | I129: 3504477.2 | J129: 2367.89 | K129: 1480 | L129: 26/01/2026 | M129: CAJA | N129: 0123 | O129: TH001400000236 | P129: Asiento de CAJA (01/09/2025 - 31/08/2026) | Q129: Extracción de Banco 001400000236 Obs: 26-01-2026 Mov Lodge | R129: CAR - Bps enero Carmelo | S129: 000000000337 | T129: Ejercicio 2025/2026
C130: Uruguay | D130: CAR | E130: =+VLOOKUP(F130,Resumen_Base!$C$8:$G$287,5,0) -> Social Security Contributions | F130: 5237 | G130: Cargas Sociales Managers | H130: =+D130&F130 -> CAR5237 | I130: 831686 | J130: 561.95 | K130: 1480 | L130: 26/01/2026 | M130: CAJA | N130: 0123 | O130: TH001400000236 | P130: Asiento de CAJA (01/09/2025 - 31/08/2026) | Q130: Extracción de Banco 001400000236 Obs: 26-01-2026 Mov Lodge | R130: CAR - bps , fonasa iva dic Caro Horta | S130: 000000000337 | T130: Ejercicio 2025/2026
C131: Uruguay | D131: CAR | E131: =+VLOOKUP(F131,Resumen_Base!$C$8:$G$287,5,0) -> Electricity | F131: 5247 | G131: Combustible y Lub- Elect-Gener | H131: =+D131&F131 -> CAR5247 | I131: 264698 | J131: 178.85 | K131: 1480 | L131: 26/01/2026 | M131: CAJA | N131: 0123 | O131: TH001400000236 | P131: Asiento de CAJA (01/09/2025 - 31/08/2026) | Q131: Extracción de Banco 001400000236 Obs: 26-01-2026 Mov Lodge | R131: CAR - Ute electricidad casa staff | S131: 000000000337 | T131: Ejercicio 2025/2026
C132: Uruguay | D132: CAR | E132: =+VLOOKUP(F132,Resumen_Base!$C$8:$G$287,5,0) -> Electricity | F132: 5247 | G132: Combustible y Lub- Elect-Gener | H132: =+D132&F132 -> CAR5247 | I132: 1019779.2 | J132: 689.04 | K132: 1480 | L132: 26/01/2026 | M132: CAJA | N132: 0123 | O132: TH001400000236 | P132: Asiento de CAJA (01/09/2025 - 31/08/2026) | Q132: Extracción de Banco 001400000236 Obs: 26-01-2026 Mov Lodge | R132: CAR - UTE electricidad Lodge Carmelo | S132: 000000000337 | T132: Ejercicio 2025/2026
C133: Uruguay | D133: CAR | E133: =+VLOOKUP(F133,Resumen_Base!$C$8:$G$287,5,0) -> Electricity - Gas for Boats & Vehicles | F133: 5248 | G133: Combustible y Lub-Vehiculo Bot | H133: =+D133&F133 -> CAR5248 | I133: 75381.6 | J133: 51.28 | K133: 1470 | L133: 12/01/2026 | M133: CAJA | N133: 0123 | O133: TE001400000213 | P133: Asiento de CAJA (01/09/2025 - 31/08/2026) | Q133: Extracción de Caja 001400000213 Obs: 12-01-2026 Mov Lodge | R133: CAR - Combustible | S133: 000000000290 | T133: Ejercicio 2025/2026
C134: Uruguay | D134: CAR | E134: =+VLOOKUP(F134,Resumen_Base!$C$8:$G$287,5,0) -> Electricity - Gas for Boats & Vehicles | F134: 5248 | G134: Combustible y Lub-Vehiculo Bot | H134: =+D134&F134 -> CAR5248 | I134: 2200360.4 | J134: 1486.73 | K134: 1480 | L134: 31/01/2026 | M134: CAJA | N134: 0123 | O134: TH001400000254 | P134: Asiento de CAJA (01/09/2025 - 31/08/2026) | Q134: Extracción de Banco 001400000254 Obs: 31-01-2026 Mov Lodge | R134: CAR - combustible vehiculos enero Servicios Carmelo | S134: 000000000341 | T134: Ejercicio 2025/2026
C135: Uruguay | D135: CAR | E135: =+VLOOKUP(F135,Resumen_Base!$C$8:$G$287,5,0) -> Electricity - Gas for Boats & Vehicles | F135: 5248 | G135: Combustible y Lub-Vehiculo Bot | H135: =+D135&F135 -> CAR5248 | I135: 1147000 | J135: 775 | K135: 1480 | L135: 31/01/2026 | M135: CAJA | N135: 0123 | O135: TH001400000255 | P135: Asiento de CAJA (01/09/2025 - 31/08/2026) | Q135: Extracción de Banco 001400000255 Obs: 31-01-2026 Mov Lodge | R135: CAR - combustible viajes varios Long | S135: 000000000342 | T135: Ejercicio 2025/2026
C136: Uruguay | D136: CAR | E136: =+VLOOKUP(F136,Resumen_Base!$C$8:$G$287,5,0) -> Electricity - Gas for Boats & Vehicles | F136: 5248 | G136: Combustible y Lub-Vehiculo Bot | H136: =+D136&F136 -> CAR5248 | I136: 2871.2 | J136: 1.94 | K136: 1480 | L136: 31/01/2026 | M136: CAJA | N136: 0123 | O136: TH001400000254 | P136: Asiento de CAJA (01/09/2025 - 31/08/2026) | Q136: Extracción de Banco 001400000254 Obs: 31-01-2026 Mov Lodge | R136: CAR - deb comi | S136: 000000000341 | T136: Ejercicio 2025/2026
... C270: Uruguay | D270: CAR | E270: =+VLOOKUP(F270,Resumen_Base!$C$8:$G$287,5,0) -> Food & Wine | F270: 5289 | G270: Comidas Fuera Temp / Empleados | H270: =+D270&F270 -> CAR5289 | I270: 52581.9 | J270: 35.77 | K270: 1470 | L270: 26/01/2026 | M270: CAJA | N270: 0123 | O270: TE001400000225 | P270: Asiento de CAJA (01/09/2025 - 31/08/2026) | Q270: Extracción de Caja 001400000225 Obs: 26-01-2026 Mov Lodge | R270: CAR - Comida santiago mantenimiento carmelo | S270: 000000000327 | T270: Ejercicio 2025/2026
A272: EXTRA CONTABLE REVERSAR EN ENERO 26 | D272: CAR | E272: =+VLOOKUP(F272,Resumen_Base!$C$8:$G$287,5,0) -> Transfer to and from the airport (local taxi) - Vehicle Rental | F272: 5225 | G272: Alquiler Camionetas/Lanchas | H272: =+D272&F272 -> CAR5225 | I272: 0 | J272: -991 | L272: 46013 | N272: 0123 | Q272: saldo nov Celmu Multcar
A273: EXTRA CONTABLE REVERSAR EN ENERO 26 | D273: CAR | E273: =+VLOOKUP(F273,Resumen_Base!$C$8:$G$287,5,0) -> Guides | F273: 5227 | G273: Remuneraciones Guías | H273: =+D273&F273 -> CAR5227 | I273: 0 | J273: -1600 | L273: 46013 | N273: 0123 | Q273: Transaccion laboral Michel Cufre
A274: EXTRA CONTABLE REVERSAR EN ENERO 26 | D274: CAR | E274: =+VLOOKUP(F274,Resumen_Base!$C$8:$G$287,5,0) -> Manager | F274: 5228 | G274: Remuneraciones Managers | H274: =+D274&F274 -> CAR5228 | I274: 0 | J274: -1371 | L274: 46013 | N274: 0123 | Q274: sueldo diciembre Caro Horta
...

Sheet Mov_Analizados_Feb - Mar 26
G2: Ver Telefonos
G3: Ver Gastos devengados
G4: Ver Luz Devengada
G5: Ver REVERSAS
G7: =+IF(I7+J7=0,"Ok","Check") -> Ok | I7: =ROUND(SUM(I10:I3520),0) -> 0 | J7: =ROUND(SUM(J10:J3520),0) -> 0
D8: FL | E8: Rubro | G8: =+Resumen_Base!D1 -> Ok
B9: =+F9&$C$9&G9 | D9: =+VLOOKUP(F9,Resumen_Base!$C$8:$F$26,4,0) -> #N/A | E9: =+VLOOKUP(F9,Resumen_Base!$C$8:$G$156,5,0) -> #N/A | H9: =+D9&F9 -> #N/A | I9: =SUM(I10:I1378) -> 1.0077694e+08 | J9: =SUM(J10:J1378) -> 103144.36
A10: AJUSTES | B10: Cuenta Anterior | D10: Lodge | E10: Concepto | F10: Cuenta | G10: Nombre | I10: monto $ | J10: monto USD | K10: TC | L10: Fecha | M10: Subdiario | N10: Div | O10: Datos del comprobante | P10: Sujeto | Q10: CUIT | R10: Observación asiento | S10: Clase de Asiento | T10: Origen del comprobante | U10: Observación del comprobante | V10: Comentario renglón asiento | W10: Asiento | X10: Control | Z10: monto USD | AA10: tc | AC10: Fecha | AD10: Subdiario | AE10: Div | AF10: Datos del comprobante | AG10: Sujeto | AH10: CUIT | AI10: Observación asiento | AJ10: Clase de Asiento | AK10: Origen del comprobante | AL10: Observación del comprobante | AM10: Comentario renglón asiento | AN10: Asiento
C13: Uruguay | D13: SJ | E13: =+VLOOKUP(F13,Resumen_Base!$C$8:$G$156,5,0) -> Fixed Asset's Payments (Investments) Mejoras/equipamiento Lodge | F13: 12020103 | G13: Mejoras de Inmueb y Terrenos | H13: =+D13&F13 -> SJ12020103 | I13: 2707.5 | J13: 1.9 | K13: 1425 | L13: 16/02/2026 | M13: CAJA | N13: 0121 | O13: TH001400000277 | P13: Asiento de CAJA (2025-09-01 - 2026-08-31) | Q13: Extracción de Banco 001400000277 Obs: 16-02-2026 Mov Lodge | R13: SJ - deb comi | S13: 000000000417 | T13: Ejercicio 2025/2026
C14: Uruguay | D14: SJ | E14: =+VLOOKUP(F14,Resumen_Base!$C$8:$G$156,5,0) -> Fixed Asset's Payments (Investments) Mejoras/equipamiento Lodge | F14: 12020103 | G14: Mejoras de Inmueb y Terrenos | H14: =+D14&F14 -> SJ12020103 | I14: 370614 | J14: 260.08 | K14: 1425 | L14: 16/02/2026 | M14: CAJA | N14: 0121 | O14: TH001400000277 | P14: Asiento de CAJA (2025-09-01 - 2026-08-31) | Q14: Extracción de Banco 001400000277 Obs: 16-02-2026 Mov Lodge | R14: SJ - pintura arreglos San Juan | S14: 000000000417 | T14: Ejercicio 2025/2026
A15: ESTO ES URU LODGE | C15: Uruguay | D15: UL | E15: =+VLOOKUP(F15,Resumen_Base!$C$8:$G$156,5,0) -> Fixed Asset's Payments (Investments) Mejoras/equipamiento Lodge | F15: 12020103 | G15: Mejoras de Inmueb y Terrenos | H15: =+D15&F15 -> UL12020103 | I15: 6300395.2 | J15: 4421.33 | K15: 1425 | L15: 16/02/2026 | M15: CAJA | N15: 0121 | O15: TH001400000277 | P15: Asiento de CAJA (2025-09-01 - 2026-08-31) | Q15: Extracción de Banco 001400000277 Obs: 16-02-2026 Mov Lodge | R15: SJ - pintura fachada Valle de soba Crisoles | S15: 000000000417 | T15: Ejercicio 2025/2026
C16: Uruguay | D16: CAR | E16: =+VLOOKUP(F16,Resumen_Base!$C$8:$G$156,5,0) -> Fixed Asset's Payments (Investments) Mejoras/equipamiento Lodge | F16: 12020103 | G16: Mejoras de Inmueb y Terrenos | H16: =+D16&F16 -> CAR12020103 | I16: 52725 | J16: 37 | K16: 1425 | L16: 23/02/2026 | M16: CAJA | N16: 0123 | O16: TE001400000296 | P16: Asiento de CAJA (01/09/2025 - 310326) | Q16: Extracción de Caja 001400000296 Obs: 23-02-2026 Mov Lodge | R16: "CAR - Compra de antialgas y tornillo madera (1430 uruguayos)Se abono con usd" | S16: 000000000484 | T16: Ejercicio 2025/2026
C17: Uruguay | D17: CAR | E17: =+VLOOKUP(F17,Resumen_Base!$C$8:$G$156,5,0) -> Fixed Asset's Payments (Investments) Mejoras/equipamiento Lodge | F17: 12020103 | G17: Mejoras de Inmueb y Terrenos | H17: =+D17&F17 -> CAR12020103 | I17: 81225 | J17: 57 | K17: 1425 | L17: 16/02/2026 | M17: CAJA | N17: 0123 | O17: TE001400000283 | P17: Asiento de CAJA (2025-09-01 - 2026-08-31) | Q17: Extracción de Caja 001400000283 Obs: 16-02-2026 Mov Lodge | R17: CAR - Cañería instalaciones lavadero nuevo en galpón | S17: 000000000414 | T17: Ejercicio 2025/2026
